Workbook

Sheet Tháng 1
C1: Tồn Đầu Kỳ | E1: Nhập | G1: Xuất | I1: Tồn cuối kỳ
A2: Tên Hàng | B2: Tháng | C2: Số Lượng | D2: T,Tiền | E2: Số Lượng | F2: T.Tiền | G2: Số Lượng | H2: T. Tiền | I2: Số Lượng | J2: T.Tiền
A3: Cá viên Funny 500g | B3: 1 | C3: 250 | D3: 6861365 | E3: 100 | F3: 2716600 | G3: 135 | H3: 3694358 | I3: 215 | J3: 5883607
A4: AL Anlene Concentrate Choco 4x125ml | B4: 1 | C4: 0 | D4: 0 | E4: 0 | F4: 0 | G4: 0 | H4: 0 | I4: 0 | J4: 0
A5: AL Anlene Concentrate Vanilla 4x125ml | B5: 1 | C5: 1221 | D5: 40068502 | E5: 0 | F5: 0 | G5: 94 | H5: 3084717 | I5: 1127 | J5: 36983785
A6: AL Anlene Gold Vanilla Movepro 1Kg | B6: 1 | C6: 125 | D6: 37241817 | E6: 0 | F6: 0 | G6: 0 | H6: 0 | I6: 125 | J6: 37241817
A7: AL Anlene Gold Vanilla Movepro 400g | B7: 1 | C7: 510 | D7: 69373706 | E7: 0 | F7: 0 | G7: 0 | H7: 0 | I7: 510 | J7: 69373706
A8: AL Anlene Gold Vanilla Movepro 440g | B8: 1 | C8: 354 | D8: 55405030 | E8: 0 | F8: 0 | G8: 0 | H8: 0 | I8: 354 | J8: 55405030
A9: AL Anlene Gold Vanilla Movepro 800g | B9: 1 | C9: 169 | D9: 40442640 | E9: 0 | F9: 0 | G9: 0 | H9: 0 | I9: 169 | J9: 40442640
A10: AL Anlene Movepro UHT 180ml - Có đường | B10: 1 | C10: 894 | D10: 19467870 | E10: 0 | F10: 0 | G10: 0 | H10: 0 | I10: 894 | J10: 19467870
A11: AL Anlene Movepro UHT 180ml - Không béo | B11: 1 | C11: 180 | D11: 3904035 | E11: 0 | F11: 0 | G11: 0 | H11: 0 | I11: 180 | J11: 3904035
A12: AL Anlene Vanilla Movepro 440g | B12: 1 | C12: 307 | D12: 32682234 | E12: 0 | F12: 0 | G12: 0 | H12: 0 | I12: 307 | J12: 32682234
A13: AL Anlene Vanilla Movepro 800g | B13: 1 | C13: 192 | D13: 45946668 | E13: 0 | F13: 0 | G13: 0 | H13: 0 | I13: 192 | J13: 45946668
A14: AL Anlene Vanilla Movepro Sachet 20gx3 | B14: 1 | C14: 18 | D14: 407934 | E14: 0 | F14: 0 | G14: 0 | H14: 0 | I14: 18 | J14: 407934
... A284: XXTT Heo 18g gói (T-3.6KG) | B284: 1 | C284: 0 | D284: 0 | E284: 216 | F284: 19220544 | G284: 0 | H284: 0 | I284: 216 | J284: 19220544
A285: Tổng Cộng | D285: 15447634554 | E285: 480934 | F285: 11706869809 | G285: 371957 | H285: 12007329223 | J285: 15147175140
H287: =H285+'Tháng 2'!H285+'Tháng 3'!H285+'Tháng 4'!H285+'Tháng 5'!H285+'Tháng 6'!H285+'Tháng 7'!H285+'Tháng 8'!H285+'Tháng 9'!H285+'Tháng 10'!H285+'Tháng 11'!H285+'Tháng 12'!H285 -> 112087384096

Sheet Tháng 2
C1: Tồn Đầu Kỳ | E1: Nhập | G1: Xuất | I1: Tồn cuối kỳ
A2: Tên Hàng | B2: Tháng | C2: Số Lượng | D2: T,Tiền | E2: Số Lượng | F2: T.Tiền | G2: Số Lượng | H2: T. Tiền | I2: Số Lượng | J2: T.Tiền
A3: Cá viên Funny 500g | B3: 2 | C3: 215 | D3: 5883607 | E3: 160 | F3: 4346560 | G3: 10 | H3: 272804 | I3: 365 | J3: 9957363
A4: AL Anlene Concentrate Choco 4x125ml | B4: 2 | C4: 0 | D4: 0 | E4: 0 | F4: 0 | G4: 0 | H4: 0 | I4: 0 | J4: 0
A5: AL Anlene Concentrate Vanilla 4x125ml | B5: 2 | C5: 1127 | D5: 36983785 | E5: 0 | F5: 0 | G5: 132 | H5: 4331730 | I5: 995 | J5: 32652055
A6: AL Anlene Gold Vanilla Movepro 1Kg | B6: 2 | C6: 125 | D6: 37241817 | E6: 0 | F6: 0 | G6: 5 | H6: 1489673 | I6: 120 | J6: 35752144
A7: AL Anlene Gold Vanilla Movepro 400g | B7: 2 | C7: 510 | D7: 69373706 | E7: 0 | F7: 0 | G7: 0 | H7: 0 | I7: 510 | J7: 69373706
A8: AL Anlene Gold Vanilla Movepro 440g | B8: 2 | C8: 354 | D8: 55405030 | E8: 0 | F8: 0 | G8: 10 | H8: 1565114 | I8: 344 | J8: 53839916
A9: AL Anlene Gold Vanilla Movepro 800g | B9: 2 | C9: 169 | D9: 40442640 | E9: 0 | F9: 0 | G9: 10 | H9: 2393056 | I9: 159 | J9: 38049584
A10: AL Anlene Movepro UHT 180ml - Có đường | B10: 2 | C10: 894 | D10: 19467870 | E10: 0 | F10: 0 | G10: 80 | H10: 1742091 | I10: 814 | J10: 17725779
A11: AL Anlene Movepro UHT 180ml - Không béo | B11: 2 | C11: 180 | D11: 3904035 | E11: 0 | F11: 0 | G11: 0 | H11: 0 | I11: 180 | J11: 3904035
A12: AL Anlene Vanilla Movepro 440g | B12: 2 | C12: 307 | D12: 32682234 | E12: 0 | F12: 0 | G12: 0 | H12: 0 | I12: 307 | J12: 32682234
A13: AL Anlene Vanilla Movepro 800g | B13: 2 | C13: 192 | D13: 45946668 | E13: 0 | F13: 0 | G13: 10 | H13: 2393056 | I13: 182 | J13: 43553612
A14: AL Anlene Vanilla Movepro Sachet 20gx3 | B14: 2 | C14: 18 | D14: 407934 | E14: 0 | F14: 0 | G14: 0 | H14: 0 | I14: 18 | J14: 407934
... A243: VS ĐL Ba rọi sốt tiêu đen gói 500g | B243: 2 | C243: 0 | D243: 0 | E243: 15 | F243: 1122000 | G243: 15 | H243: 1122000 | I243: 0 | J243: 0
A244: VS ĐL Ba rọi ướp gia vị gói 500g | B244: 2 | C244: 0 | D244: 0 | E244: 0 | F244: 0 | H244: 0 | I244: 0 | J244: 0
A245: VS ĐL Ba Rọi Xốt Mật Ong gói 500g | B245: 2 | C245: 0 | D245: 0 | E245: 42 | F245: 3141600 | G245: 42 | H245: 3141600 | I245: 0 | J245: 0
A246: VS ĐL Bò viên 3 ngon gói 500g | B246: 2 | C246: 125 | D246: 4196915 | E246: 170 | F246: 5720840 | G246: 50 | H246: 1680975 | I246: 245 | J246: 8236780
A247: VS ĐL Bò viên gói 200g | B247: 2 | C247: 0 | D247: 0 | E247: 0 | F247: 0 | H247: 0 | I247: 0 | J247: 0
A248: VS ĐL Cá viên 3 ngon gói 500g | B248: 2 | C248: 103 | D248: 2200478 | E248: 20 | F248: 854554 | G248: 0 | H248: 0 | I248: 123 | J248: 3055032
A249: VS ĐL Cá Viên Funny gói 250g (1T=30G) | B249: 2 | C249: 0 | D249: 0 | E249: 0 | F249: 0 | G249: 0 | H249: 0 | I249: 0 | J249: 0
A250: VS ĐL Cá viên gói 200g | B250: 2 | C250: 270 | D250: 4079585 | E250: 1200 | F250: 3600576 | G250: 40 | H250: 169522 | I250: 1430 | J250: 7510639
A251: VS ĐL Cá Viên ớt xiêm xanh gói 500g | B251: 2 | C251: 161 | D251: 3439584 | E251: 5 | F251: 213639 | G251: 46 | H251: 1012339 | I251: 120 | J251: 2640884
A252: VS ĐL Chả giò chay gói 500g | B252: 2 | C252: 5 | D252: 274480 | E252: 20 | F252: 1097920 | G252: 23 | H252: 1262608 | I252: 2 | J252: 109792
A253: VS ĐL Chả Giò con tôm gói 250g | B253: 2 | C253: 0 | D253: 0 | E253: 0 | F253: 0 | H253: 0 | I253: 0 | J253: 0
A254: VS ĐL Chả giò da xốp gói 400g | B254: 2 | C254: 0 | D254: 0 | E254: 0 | F254: 0 | H254: 0 | I254: 0 | J254: 0
A255: VS ĐL Chả giò hải sản gói 500g | B255: 2 | C255: 2 | D255: 118440 | E255: 80 | F255: 4737600 | G255: 79 | H255: 4678380 | I255: 3 | J255: 177660
A256: VS ĐL Chả giò rế con tôm gói 300g | B256: 2 | C256: 0 | D256: 0 | E256: 30 | F256: 1170000 | G256: 29 | H256: 1131000 | I256: 1 | J256: 39000
A257: VS ĐL Chả giò rế thịt gói 500g | B257: 2 | C257: 5 | D257: 323360 | E257: 5 | F257: 323360 | G257: 10 | H257: 646720 | I257: 0 | J257: 0
A258: VS ĐL Chả Giò rế tôm cua gói 500g | B258: 2 | C258: 2 | D258: 129720 | E258: 0 | F258: 0 | G258: 0 | H258: 0 | I258: 2 | J258: 129720
A259: VS ĐL Chả giò tôm cua gói 500g | B259: 2 | C259: 0 | D259: 0 | E259: 30 | F259: 1170000 | G259: 29 | H259: 1131000 | I259: 1 | J259: 39000
A260: VS ĐL Cốt lết ướp gia vị gói 500g | B260: 2 | C260: 80 | D260: 4419241 | E260: 0 | F260: 0 | G260: 80 | H260: 4419241 | I260: 0 | J260: 0
A261: VS ĐL Cốt lết xốt mật ong gói 500g | B261: 2 | C261: 0 | D261: 0 | E261: 6 | F261: 378000 | G261: 6 | H261: 378000 | I261: 0 | J261: 0
A262: VS ĐL Cốt lết xốt tiêu đen gói 500g | B262: 2 | C262: 0 | D262: 0 | E262: 20 | F262: 1160000 | G262: 20 | H262: 1160000 | I262: 0 | J262: 0
A263: VS ĐL Dồi sụn giòn gói 250g | B263: 2 | C263: 1 | D263: 134195 | E263: 31 | F263: 4160045 | G263: 32 | H263: 4294240 | I263: 0 | J263: 0
A264: VS ĐL Dồi sụn giòn gói 500g | B264: 2 | C264: 0 | D264: 0 | E264: 0 | F264: 0 | G264: 0 | H264: 0 | I264: 0 | J264: 0
A265: VS ĐL Há Cảo gói 250g | B265: 2 | C265: 0 | D265: 0 | E265: 0 | F265: 0 | H265: 0 | I265: 0 | J265: 0
A266: VS ĐL Há Cảo Thanh Long gói 300g | B266: 2 | C266: 0 | D266: 0 | E266: 21 | F266: 745500 | G266: 21 | H266: 745500 | I266: 0 | J266: 0
A267: VS ĐL Há Cảo Thịt gói 300g | B267: 2 | C267: 0 | D267: 0 | E267: 53 | F267: 1325000 | G267: 53 | H267: 1325000 | I267: 0 | J267: 0
A268: VS ĐL Há Cảo Tôm gói 300g | B268: 2 | C268: 1 | D268: 75576 | E268: 65 | F268: 2457000 | G268: 66 | H268: 2532576 | I268: 0 | J268: 0
...

Sheet Tháng 3
C1: Tồn Đầu Kỳ | E1: Nhập | G1: Xuất | I1: Tồn cuối kỳ
A2: Tên Hàng | B2: Tháng | C2: Số Lượng | D2: T,Tiền | E2: Số Lượng | F2: T.Tiền | G2: Số Lượng | H2: T. Tiền | I2: Số Lượng | J2: T.Tiền
A3: Cá viên Funny 500g | B3: 3 | C3: 365 | D3: 9957363 | E3: 130 | F3: 3531580 | G3: 240 | H3: 6540094 | I3: 255 | J3: 6948849
A4: AL Anlene Concentrate Choco 4x125ml | B4: 3 | C4: 0 | D4: 0 | E4: 0 | F4: 0 | G4: 0 | H4: 0 | I4: 0 | J4: 0
A5: AL Anlene Concentrate Vanilla 4x125ml | B5: 3 | C5: 995 | D5: 32652055 | E5: 0 | F5: 0 | G5: 72 | H5: 2362762 | I5: 923 | J5: 30289293
A6: AL Anlene Gold Vanilla Movepro 1Kg | B6: 3 | C6: 120 | D6: 35752144 | E6: 0 | F6: 0 | G6: 0 | H6: 0 | I6: 120 | J6: 35752144
A7: AL Anlene Gold Vanilla Movepro 400g | B7: 3 | C7: 510 | D7: 69373706 | E7: 0 | F7: 0 | G7: 0 | H7: 0 | I7: 510 | J7: 69373706
A8: AL Anlene Gold Vanilla Movepro 440g | B8: 3 | C8: 344 | D8: 53839916 | E8: 0 | F8: 0 | G8: 0 | H8: 0 | I8: 344 | J8: 53839916
A9: AL Anlene Gold Vanilla Movepro 800g | B9: 3 | C9: 159 | D9: 38049584 | E9: 0 | F9: 0 | G9: 0 | H9: 0 | I9: 159 | J9: 38049584
A10: AL Anlene Movepro UHT 180ml - Có đường | B10: 3 | C10: 814 | D10: 17725779 | E10: 0 | F10: 0 | G10: 80 | H10: 1742091 | I10: 734 | J10: 15983688
A11: AL Anlene Movepro UHT 180ml - Không béo | B11: 3 | C11: 180 | D11: 3904035 | E11: 0 | F11: 0 | G11: 0 | H11: 0 | I11: 180 | J11: 3904035
A12: AL Anlene Vanilla Movepro 440g | B12: 3 | C12: 307 | D12: 32682234 | E12: 0 | F12: 0 | G12: 12 | H12: 1277481 | I12: 295 | J12: 31404753
A13: AL Anlene Vanilla Movepro 800g | B13: 3 | C13: 182 | D13: 43553612 | E13: 0 | F13: 0 | G13: 12 | H13: 2871667 | I13: 170 | J13: 40681945
A14: AL Anlene Vanilla Movepro Sachet 20gx3 | B14: 3 | C14: 18 | D14: 407934 | E14: 0 | F14: 0 | G14: 0 | H14: 0 | I14: 18 | J14: 407934
... A284: XXTT Heo 18g gói (T-3.6KG) | B284: 3 | C284: 666 | D284: 51254784 | E284: 341 | F284: 25627392 | G284: 0 | H284: 0 | I284: 1007 | J284: 76882176
D285: 16022965628 | F285: 9550427560 | H285: 8812324506 | J285: 16761068682

Sheet Tháng 4
C1: Tồn Đầu Kỳ | E1: Nhập | G1: Xuất | I1: Tồn cuối kỳ
A2: Tên Hàng | B2: Tháng | C2: Số Lượng | D2: T,Tiền | E2: Số Lượng | F2: T.Tiền | G2: Số Lượng | H2: T. Tiền | I2: Số Lượng | J2: T.Tiền
A3: Cá viên Funny 500g | B3: 4 | C3: 255 | D3: 6948849 | E3: 160 | F3: 4410140 | G3: 184 | H3: 5036275 | I3: 231 | J3: 6322714
A4: AL Anlene Concentrate Choco 4x125ml | B4: 4 | C4: 0 | D4: 0 | E4: 0 | F4: 0 | G4: 0 | H4: 0 | I4: 0 | J4: 0
A5: AL Anlene Concentrate Vanilla 4x125ml | B5: 4 | C5: 923 | D5: 30274687 | E5: 0 | F5: 0 | G5: 24 | H5: 787587 | I5: 899 | J5: 29487100
A6: AL Anlene Gold Vanilla Movepro 1Kg | B6: 4 | C6: 120 | D6: 35752144 | E6: 0 | F6: 0 | G6: 0 | H6: 0 | I6: 120 | J6: 35752144
A7: AL Anlene Gold Vanilla Movepro 400g | B7: 4 | C7: 510 | D7: 69373706 | E7: 0 | F7: 0 | G7: 0 | H7: 0 | I7: 510 | J7: 69373706
A8: AL Anlene Gold Vanilla Movepro 440g | B8: 4 | C8: 344 | D8: 53839916 | E8: 0 | F8: 0 | G8: 0 | H8: 0 | I8: 344 | J8: 53839916
A9: AL Anlene Gold Vanilla Movepro 800g | B9: 4 | C9: 159 | D9: 38049584 | E9: 0 | F9: 0 | G9: 0 | H9: 0 | I9: 159 | J9: 38049584
A10: AL Anlene Movepro UHT 180ml - Có đường | B10: 4 | C10: 734 | D10: 15983688 | E10: 0 | F10: 0 | G10: 0 | H10: 0 | I10: 734 | J10: 15983688
A11: AL Anlene Movepro UHT 180ml - Không béo | B11: 4 | C11: 180 | D11: 3904035 | E11: 0 | F11: 0 | G11: 0 | H11: 0 | I11: 180 | J11: 3904035
A12: AL Anlene Vanilla Movepro 440g | B12: 4 | C12: 295 | D12: 31404753 | E12: 0 | F12: 0 | G12: 0 | H12: 0 | I12: 295 | J12: 31404753
A13: AL Anlene Vanilla Movepro 800g | B13: 4 | C13: 170 | D13: 40681945 | E13: 0 | F13: 0 | G13: 0 | H13: 0 | I13: 170 | J13: 40681945
A14: AL Anlene Vanilla Movepro Sachet 20gx3 | B14: 4 | C14: 18 | D14: 407934 | E14: 0 | F14: 0 | G14: 0 | H14: 0 | I14: 18 | J14: 407934
... A284: XXTT Heo 18g gói (T-3.6KG) | B284: 4 | C284: 1007 | D284: 76882176 | E284: 184 | F284: 9610272 | G284: 0 | H284: 0 | I284: 1191 | J284: 86492448
D285: 16761054076 | F285: 9316351365 | H285: 8659651285 | J285: 17417754156

Sheet Tháng 5
C1: Tồn Đầu Kỳ | E1: Nhập | G1: Xuất | I1: Tồn cuối kỳ
A2: Tên Hàng | B2: Tháng | C2: Số Lượng | D2: T,Tiền | E2: Số Lượng | F2: T.Tiền | G2: Số Lượng | H2: T. Tiền | I2: Số Lượng | J2: T.Tiền
A3: Cá viên Funny 500g | B3: 5 | C3: 231 | D3: 6322714 | E3: 120 | F3: 3329280 | G3: 140 | H3: 3849798 | I3: 211 | J3: 5802196
A4: AL Anlene Concentrate Choco 4x125ml | B4: 5 | C4: 0 | D4: 0 | E4: 0 | F4: 0 | G4: 0 | H4: 0 | I4: 0 | J4: 0
A5: AL Anlene Concentrate Vanilla 4x125ml | B5: 5 | C5: 899 | D5: 29487100 | E5: 0 | F5: 0 | G5: 36 | H5: 1181381 | I5: 863 | J5: 28305719
A6: AL Anlene Gold Vanilla Movepro 1Kg | B6: 5 | C6: 120 | D6: 35752144 | E6: 0 | F6: 0 | G6: 0 | H6: 0 | I6: 120 | J6: 35752144
A7: AL Anlene Gold Vanilla Movepro 400g | B7: 5 | C7: 510 | D7: 69373706 | E7: 0 | F7: 0 | G7: 0 | H7: 0 | I7: 510 | J7: 69373706
A8: AL Anlene Gold Vanilla Movepro 440g | B8: 5 | C8: 344 | D8: 53839916 | E8: 0 | F8: 0 | G8: 0 | H8: 0 | I8: 344 | J8: 53839916
A9: AL Anlene Gold Vanilla Movepro 800g | B9: 5 | C9: 159 | D9: 38049584 | E9: 0 | F9: 0 | G9: 0 | H9: 0 | I9: 159 | J9: 38049584
A10: AL Anlene Movepro UHT 180ml - Có đường | B10: 5 | C10: 734 | D10: 15983688 | E10: 0 | F10: 0 | G10: 0 | H10: 0 | I10: 734 | J10: 15983688
A11: AL Anlene Movepro UHT 180ml - Không béo | B11: 5 | C11: 180 | D11: 3904035 | E11: 0 | F11: 0 | G11: 0 | H11: 0 | I11: 180 | J11: 3904035
A12: AL Anlene Vanilla Movepro 440g | B12: 5 | C12: 295 | D12: 31404753 | E12: 0 | F12: 0 | G12: 0 | H12: 0 | I12: 295 | J12: 31404753
A13: AL Anlene Vanilla Movepro 800g | B13: 5 | C13: 170 | D13: 40681945 | E13: 0 | F13: 0 | G13: 0 | H13: 0 | I13: 170 | J13: 40681945
A14: AL Anlene Vanilla Movepro Sachet 20gx3 | B14: 5 | C14: 18 | D14: 407934 | E14: 0 | F14: 0 | G14: 0 | H14: 0 | I14: 18 | J14: 407934
... A284: XXTT Heo 18g gói (T-3.6KG) | B284: 5 | C284: 1191 | D284: 86492448 | E284: 241 | F284: 12813696 | G284: 0 | H284: 0 | I284: 1432 | J284: 99306144
C285: 1130577 | D285: 17417754156 | E285: 410719 | F285: 7856754302 | G285: 436661 | H285: 9002504084 | I285: 1104635 | J285: 16272004374

Sheet Tháng 6
C1: Tồn Đầu Kỳ | E1: Nhập | G1: Xuất | I1: Tồn cuối kỳ
A2: Tên Hàng | B2: Tháng | C2: Số Lượng | D2: T,Tiền | E2: Số Lượng | F2: T.Tiền | G2: Số Lượng | H2: T. Tiền | I2: Số Lượng | J2: T.Tiền
A3: Cá viên Funny 500g | B3: 6 | C3: 211 | D3: 5802196 | E3: 70 | F3: 1942080 | G3: 80 | H3: 2204776 | I3: 201 | J3: 5539500
A4: AL Anlene Concentrate Choco 4x125ml | B4: 6 | C4: 0 | D4: 0 | E4: 0 | F4: 0 | G4: 0 | H4: 0 | I4: 0 | J4: 0
A5: AL Anlene Concentrate Vanilla 4x125ml | B5: 6 | C5: 863 | D5: 28305719 | E5: 0 | F5: 0 | G5: 0 | H5: 0 | I5: 863 | J5: 28305719
A6: AL Anlene Gold Vanilla Movepro 1Kg | B6: 6 | C6: 120 | D6: 35752144 | E6: 0 | F6: 0 | G6: 0 | H6: 0 | I6: 120 | J6: 35752144
A7: AL Anlene Gold Vanilla Movepro 400g | B7: 6 | C7: 510 | D7: 69373706 | E7: 0 | F7: 0 | G7: 0 | H7: 0 | I7: 510 | J7: 69373706
A8: AL Anlene Gold Vanilla Movepro 440g | B8: 6 | C8: 344 | D8: 53839916 | E8: 0 | F8: 0 | G8: 0 | H8: 0 | I8: 344 | J8: 53839916
A9: AL Anlene Gold Vanilla Movepro 800g | B9: 6 | C9: 159 | D9: 38049584 | E9: 0 | F9: 0 | G9: 0 | H9: 0 | I9: 159 | J9: 38049584
A10: AL Anlene Movepro UHT 180ml - Có đường | B10: 6 | C10: 734 | D10: 15983688 | E10: 0 | F10: 0 | G10: 0 | H10: 0 | I10: 734 | J10: 15983688
A11: AL Anlene Movepro UHT 180ml - Không béo | B11: 6 | C11: 180 | D11: 3904035 | E11: 0 | F11: 0 | G11: 0 | H11: 0 | I11: 180 | J11: 3904035
A12: AL Anlene Vanilla Movepro 440g | B12: 6 | C12: 295 | D12: 31404753 | E12: 0 | F12: 0 | G12: 0 | H12: 0 | I12: 295 | J12: 31404753
A13: AL Anlene Vanilla Movepro 800g | B13: 6 | C13: 170 | D13: 40681945 | E13: 0 | F13: 0 | G13: 0 | H13: 0 | I13: 170 | J13: 40681945
A14: AL Anlene Vanilla Movepro Sachet 20gx3 | B14: 6 | C14: 18 | D14: 407934 | E14: 0 | F14: 0 | G14: 0 | H14: 0 | I14: 18 | J14: 407934
... A284: XXTT Heo 18g gói (T-3.6KG) | B284: 6 | C284: 1432 | D284: 99306144 | E284: 198 | F284: 17618832 | G284: 36 | H284: 2582392 | I284: 1594 | J284: 114342584
D285: 16272004374 | F285: 6671492500 | H285: 6167307223 | J285: 16776189651

Sheet Tháng 7
C1: Tồn Đầu Kỳ | E1: Nhập | G1: Xuất | I1: Tồn cuối kỳ
A2: Tên Hàng | B2: Tháng | C2: Số Lượng | D2: T,Tiền | E2: Số Lượng | F2: T.Tiền | G2: Số Lượng | H2: T. Tiền | I2: Số Lượng | J2: T.Tiền
A3: Cá viên Funny 500g | B3: 7 | C3: 201 | D3: 5539500 | E3: 70 | F3: 1914336 | G3: 125 | H3: 3438116 | I3: 146 | J3: 4015720
A4: AL Anlene Concentrate Choco 4x125ml | B4: 7 | C4: 0 | D4: 0 | E4: 0 | F4: 0 | G4: 0 | H4: 0 | I4: 0 | J4: 0
A5: AL Anlene Concentrate Vanilla 4x125ml | B5: 7 | C5: 863 | D5: 28305719 | E5: 0 | F5: 0 | G5: 60 | H5: 1968968 | I5: 803 | J5: 26336751
A6: AL Anlene Gold Vanilla Movepro 1Kg | B6: 7 | C6: 120 | D6: 35752144 | E6: 0 | F6: 0 | G6: 0 | H6: 0 | I6: 120 | J6: 35752144
A7: AL Anlene Gold Vanilla Movepro 400g | B7: 7 | C7: 510 | D7: 69373706 | E7: 0 | F7: 0 | G7: 0 | H7: 0 | I7: 510 | J7: 69373706
A8: AL Anlene Gold Vanilla Movepro 440g | B8: 7 | C8: 344 | D8: 53839916 | E8: 0 | F8: 0 | G8: 0 | H8: 0 | I8: 344 | J8: 53839916
A9: AL Anlene Gold Vanilla Movepro 800g | B9: 7 | C9: 159 | D9: 38049584 | E9: 0 | F9: 0 | G9: 0 | H9: 0 | I9: 159 | J9: 38049584
A10: AL Anlene Movepro UHT 180ml - Có đường | B10: 7 | C10: 734 | D10: 15983688 | E10: 0 | F10: 0 | G10: 0 | H10: 0 | I10: 734 | J10: 15983688
A11: AL Anlene Movepro UHT 180ml - Không béo | B11: 7 | C11: 180 | D11: 3904035 | E11: 0 | F11: 0 | G11: 0 | H11: 0 | I11: 180 | J11: 3904035
A12: AL Anlene Vanilla Movepro 440g | B12: 7 | C12: 295 | D12: 31404753 | E12: 0 | F12: 0 | G12: 0 | H12: 0 | I12: 295 | J12: 31404753
A13: AL Anlene Vanilla Movepro 800g | B13: 7 | C13: 170 | D13: 40681945 | E13: 0 | F13: 0 | G13: 0 | H13: 0 | I13: 170 | J13: 40681945
A14: AL Anlene Vanilla Movepro Sachet 20gx3 | B14: 7 | C14: 18 | D14: 407934 | E14: 0 | F14: 0 | G14: 0 | H14: 0 | I14: 18 | J14: 407934
... A284: XXTT Heo 18g gói (T-3.6KG) | B284: 7 | C284: 1594 | D284: 114342584 | E284: 436 | F284: 32034240 | G284: 108 | H284: 7787535 | I284: 1922 | J284: 138589289
D285: 16776189651 | F285: 9695173526 | H285: 11337158824 | I285: 1128743 | J285: 15134204353

Sheet Tháng 8
C1: Tồn Đầu Kỳ | E1: Nhập | G1: Xuất | I1: Tồn cuối kỳ
A2: Tên Hàng | B2: Tháng | C2: Số Lượng | D2: T,Tiền | E2: Số Lượng | F2: T.Tiền | G2: Số Lượng | H2: T. Tiền | I2: Số Lượng | J2: T.Tiền
A3: Cá viên Funny 500g | B3: 8 | C3: 146 | D3: 4015720 | E3: 100 | F3: 2774400 | G3: 0 | H3: 0 | I3: 246 | J3: 6790120
A4: AL Anlene Concentrate Choco 4x125ml | B4: 8 | C4: 0 | D4: 0 | E4: 0 | F4: 0 | G4: 0 | H4: 0 | I4: 0 | J4: 0
A5: AL Anlene Concentrate Vanilla 4x125ml | B5: 8 | C5: 803 | D5: 26336751 | E5: 0 | F5: 0 | G5: 0 | H5: 0 | I5: 803 | J5: 26336751
A6: AL Anlene Gold Vanilla Movepro 1Kg | B6: 8 | C6: 120 | D6: 35752144 | E6: 0 | F6: 0 | G6: 0 | H6: 0 | I6: 120 | J6: 35752144
A7: AL Anlene Gold Vanilla Movepro 400g | B7: 8 | C7: 510 | D7: 69373706 | E7: 0 | F7: 0 | G7: 0 | H7: 0 | I7: 510 | J7: 69373706
A8: AL Anlene Gold Vanilla Movepro 440g | B8: 8 | C8: 344 | D8: 53839916 | E8: 0 | F8: 0 | G8: 0 | H8: 0 | I8: 344 | J8: 53839916
A9: AL Anlene Gold Vanilla Movepro 800g | B9: 8 | C9: 159 | D9: 38049584 | E9: 0 | F9: 0 | G9: 0 | H9: 0 | I9: 159 | J9: 38049584
A10: AL Anlene Movepro UHT 180ml - Có đường | B10: 8 | C10: 734 | D10: 15983688 | E10: 0 | F10: 0 | G10: 60 | H10: 1306569 | I10: 674 | J10: 14677119
A11: AL Anlene Movepro UHT 180ml - Không béo | B11: 8 | C11: 180 | D11: 3904035 | E11: 0 | F11: 0 | G11: 0 | H11: 0 | I11: 180 | J11: 3904035
A12: AL Anlene Vanilla Movepro 440g | B12: 8 | C12: 295 | D12: 31404753 | E12: 0 | F12: 0 | G12: 0 | H12: 0 | I12: 295 | J12: 31404753
A13: AL Anlene Vanilla Movepro 800g | B13: 8 | C13: 170 | D13: 40681945 | E13: 0 | F13: 0 | G13: 0 | H13: 0 | I13: 170 | J13: 40681945
A14: AL Anlene Vanilla Movepro Sachet 20gx3 | B14: 8 | C14: 18 | D14: 407934 | E14: 0 | F14: 0 | G14: 0 | H14: 0 | I14: 18 | J14: 407934
... A284: XXTT Heo 18g gói (T-3.6KG) | B284: 8 | C284: 1922 | D284: 138589289 | E284: 270 | F284: 24025680 | G284: 0 | H284: 0 | I284: 2192 | J284: 162614969
C285: =SUM(C2:C284) -> 1128743 | D285: =SUM(D2:D284) -> 15134204353 | E285: =SUM(E2:E284) -> 385682 | F285: =SUM(F2:F284) -> 9410289184 | G285: =SUM(G2:G284) -> 525627 | H285: =SUM(H2:H284) -> 9872002163 | I285: =SUM(I2:I284) -> 988798 | J285: =SUM(J2:J284) -> 14672491374

Sheet Tháng 9
C1: Tồn Đầu Kỳ | E1: Nhập | G1: Xuất | I1: Tồn cuối kỳ
A2: Tên Hàng | B2: Tháng | C2: Số Lượng | D2: T,Tiền | E2: Số Lượng | F2: T.Tiền | G2: Số Lượng | H2: T. Tiền | I2: Số Lượng | J2: T.Tiền
A3: Cá viên Funny 500g | B3: 9 | C3: 246 | D3: 6790120 | E3: 70 | F3: 1942080 | G3: 110 | H3: 3039690 | I3: 206 | J3: 5692510
A4: AL Anlene Concentrate Choco 4x125ml | B4: 9 | C4: 0 | D4: 0 | E4: 0 | F4: 0 | G4: 0 | H4: 0 | I4: 0 | J4: 0
A5: AL Anlene Concentrate Vanilla 4x125ml | B5: 9 | C5: 803 | D5: 26336751 | E5: 0 | F5: 0 | G5: 60 | H5: 1968968 | I5: 743 | J5: 24367783
A6: AL Anlene Gold Vanilla Movepro 1Kg | B6: 9 | C6: 120 | D6: 35752144 | E6: 0 | F6: 0 | G6: 0 | H6: 0 | I6: 120 | J6: 35752144
A7: AL Anlene Gold Vanilla Movepro 400g | B7: 9 | C7: 510 | D7: 69373706 | E7: 0 | F7: 0 | G7: 6 | H7: 816161 | I7: 504 | J7: 68557545
A8: AL Anlene Gold Vanilla Movepro 440g | B8: 9 | C8: 344 | D8: 53839916 | E8: 0 | F8: 0 | G8: 0 | H8: 0 | I8: 344 | J8: 53839916
A9: AL Anlene Gold Vanilla Movepro 800g | B9: 9 | C9: 159 | D9: 38049584 | E9: 0 | F9: 0 | G9: 6 | H9: 1435833 | I9: 153 | J9: 36613751
A10: AL Anlene Movepro UHT 180ml - Có đường | B10: 9 | C10: 674 | D10: 14677119 | E10: 0 | F10: 0 | G10: 0 | H10: 0 | I10: 674 | J10: 14677119
A11: AL Anlene Movepro UHT 180ml - Không béo | B11: 9 | C11: 180 | D11: 3904035 | E11: 0 | F11: 0 | G11: 0 | H11: 0 | I11: 180 | J11: 3904035
A12: AL Anlene Vanilla Movepro 440g | B12: 9 | C12: 295 | D12: 31404753 | E12: 0 | F12: 0 | G12: 0 | H12: 0 | I12: 295 | J12: 31404753
A13: AL Anlene Vanilla Movepro 800g | B13: 9 | C13: 170 | D13: 40681945 | E13: 0 | F13: 0 | G13: 0 | H13: 0 | I13: 170 | J13: 40681945
A14: AL Anlene Vanilla Movepro Sachet 20gx3 | B14: 9 | C14: 18 | D14: 407934 | E14: 0 | F14: 0 | G14: 0 | H14: 0 | I14: 18 | J14: 407934
... A284: XXTT Heo 18g gói (T-3.6KG) | B284: 9 | C284: 2192 | D284: 162614969 | E284: 270 | F284: 24025680 | G284: 1530 | H284: 115987081 | I284: 932 | J284: 70653568
D285: 14672491374 | F285: 8134206560 | H285: 7256403764 | J285: 15550294170

Sheet Tháng 10
C1: Tồn Đầu Kỳ | E1: Nhập | G1: Xuất | I1: Tồn cuối kỳ
A2: Tên Hàng | B2: Tháng | C2: Số Lượng | D2: T,Tiền | E2: Số Lượng | F2: T.Tiền | G2: Số Lượng | H2: T. Tiền | I2: Số Lượng | J2: T.Tiền
A3: Cá viên Funny 500g | B3: 10 | C3: 206 | D3: 5692510 | E3: 80 | F3: 2219520 | G3: 80 | H3: 2213155 | I3: 206 | J3: 5698875
A4: AL Anlene Concentrate Choco 4x125ml | B4: 10 | C4: 0 | D4: 0 | E4: 0 | F4: 0 | G4: 0 | H4: 0 | I4: 0 | J4: 0
A5: AL Anlene Concentrate Vanilla 4x125ml | B5: 10 | C5: 743 | D5: 24367783 | E5: 0 | F5: 0 | G5: 156 | H5: 5119317 | I5: 587 | J5: 19248466
A6: AL Anlene Gold Vanilla Movepro 1Kg | B6: 10 | C6: 120 | D6: 35752144 | E6: 0 | F6: 0 | G6: 0 | H6: 0 | I6: 120 | J6: 35752144
A7: AL Anlene Gold Vanilla Movepro 400g | B7: 10 | C7: 504 | D7: 68557545 | E7: 0 | F7: 0 | G7: 0 | H7: 0 | I7: 504 | J7: 68557545
A8: AL Anlene Gold Vanilla Movepro 440g | B8: 10 | C8: 344 | D8: 53839916 | E8: 0 | F8: 0 | G8: 0 | H8: 0 | I8: 344 | J8: 53839916
A9: AL Anlene Gold Vanilla Movepro 800g | B9: 10 | C9: 153 | D9: 36613751 | E9: 0 | F9: 0 | G9: 0 | H9: 0 | I9: 153 | J9: 36613751
A10: AL Anlene Movepro UHT 180ml - Có đường | B10: 10 | C10: 674 | D10: 14677119 | E10: 0 | F10: 0 | G10: 120 | H10: 2613137 | I10: 554 | J10: 12063982
A11: AL Anlene Movepro UHT 180ml - Không béo | B11: 10 | C11: 180 | D11: 3904035 | E11: 0 | F11: 0 | G11: 0 | H11: 0 | I11: 180 | J11: 3904035
A12: AL Anlene Vanilla Movepro 440g | B12: 10 | C12: 295 | D12: 31404753 | E12: 0 | F12: 0 | G12: 0 | H12: 0 | I12: 295 | J12: 31404753
A13: AL Anlene Vanilla Movepro 800g | B13: 10 | C13: 170 | D13: 40681945 | E13: 0 | F13: 0 | G13: 0 | H13: 0 | I13: 170 | J13: 40681945
A14: AL Anlene Vanilla Movepro Sachet 20gx3 | B14: 10 | C14: 18 | D14: 407934 | E14: 0 | F14: 0 | G14: 0 | H14: 0 | I14: 18 | J14: 407934
... A278: VS ĐL Xúc xích sụn giòn 500g | B278: 10 | C278: 8 | D278: 847410 | E278: 0 | F278: 0 | G278: 0 | H278: 0 | I278: 8 | J278: 847410
A279: VS ĐL Xúc xích sụn giòn- gói 250g ĐL | B279: 10 | C279: 8 | D279: 888480 | E279: 0 | G279: 0 | H279: 0 | I279: 8 | J279: 888480
A280: Xốt tiêu đen TT 190g | B280: 10 | C280: 72 | D280: 1717560 | E280: 0 | F280: 0 | G280: 0 | H280: 0 | I280: 72 | J280: 1717560
A281: Xốt ướp thịt HQ vị cay 90g | B281: 10 | C281: 5445 | D281: 18544800 | E281: 8 | F281: 0 | G281: 0 | H281: 0 | I281: 5453 | J281: 18544800
A282: XXTT Bò 18g gói (T-3.6kg) | B282: 10 | C282: 1489 | D282: 132500193 | E282: 432 | F282: 38441088 | G282: 1170 | H282: 104113118 | I282: 751 | J282: 66828163
A283: XXTT Dinh dưỡng heo gói 175g | B283: 10 | C283: 2558 | D283: 238790929 | E283: 910 | F283: 85077720 | G283: 2426 | H283: 226558634 | I283: 1042 | J283: 97310015
A284: XXTT Heo 18g gói (T-3.6KG) | B284: 10 | C284: 932 | D284: 70653568 | E284: 306 | F284: 27229104 | G284: 1026 | H284: 81120857 | I284: 212 | J284: 16761815
D285: 15550294170 | F285: 9205815555 | H285: 9489921705 | J285: 15266188020

Sheet Tháng 11
C1: Tồn Đầu Kỳ | E1: Nhập | G1: Xuất | I1: Tồn cuối kỳ
A2: Tên Hàng | B2: Tháng | C2: Số Lượng | D2: T,Tiền | E2: Số Lượng | F2: T.Tiền | G2: Số Lượng | H2: T. Tiền | I2: Số Lượng | J2: T.Tiền
A3: Cá viên Funny 500g | B3: 11 | C3: 206 | D3: 5698875 | E3: 50 | F3: 1387200 | G3: 30 | H3: 830399 | I3: 226 | J3: 6255676
A4: AL Anlene Concentrate Choco 4x125ml | B4: 11 | C4: 0 | D4: 0 | E4: 0 | F4: 0 | G4: 0 | H4: 0 | I4: 0 | J4: 0
A5: AL Anlene Concentrate Vanilla 4x125ml | B5: 11 | C5: 587 | D5: 19248466 | E5: 0 | F5: 0 | G5: 0 | H5: 0 | I5: 587 | J5: 19248466
A6: AL Anlene Gold Vanilla Movepro 1Kg | B6: 11 | C6: 120 | D6: 35752144 | E6: 0 | F6: 0 | G6: 0 | H6: 0 | I6: 120 | J6: 35752144
A7: AL Anlene Gold Vanilla Movepro 400g | B7: 11 | C7: 504 | D7: 68557545 | E7: 0 | F7: 0 | G7: 0 | H7: 0 | I7: 504 | J7: 68557545
A8: AL Anlene Gold Vanilla Movepro 440g | B8: 11 | C8: 344 | D8: 53839916 | E8: 0 | F8: 0 | G8: 0 | H8: 0 | I8: 344 | J8: 53839916
A9: AL Anlene Gold Vanilla Movepro 800g | B9: 11 | C9: 153 | D9: 36613751 | E9: 0 | F9: 0 | G9: 0 | H9: 0 | I9: 153 | J9: 36613751
A10: AL Anlene Movepro UHT 180ml - Có đường | B10: 11 | C10: 554 | D10: 12063982 | E10: 0 | F10: 0 | G10: 0 | H10: 0 | I10: 554 | J10: 12063982
A11: AL Anlene Movepro UHT 180ml - Không béo | B11: 11 | C11: 180 | D11: 3904035 | E11: 0 | F11: 0 | G11: 0 | H11: 0 | I11: 180 | J11: 3904035
A12: AL Anlene Vanilla Movepro 440g | B12: 11 | C12: 295 | D12: 31404753 | E12: 0 | F12: 0 | G12: 0 | H12: 0 | I12: 295 | J12: 31404753
A13: AL Anlene Vanilla Movepro 800g | B13: 11 | C13: 170 | D13: 40681945 | E13: 0 | F13: 0 | G13: 0 | H13: 0 | I13: 170 | J13: 40681945
A14: AL Anlene Vanilla Movepro Sachet 20gx3 | B14: 11 | C14: 18 | D14: 407934 | E14: 0 | F14: 0 | G14: 0 | H14: 0 | I14: 18 | J14: 407934
... A284: XXTT Heo 18g gói (T-3.6KG) | B284: 11 | C284: 212 | D284: 16761815 | E284: 332 | F284: 28432224 | G284: 544 | H284: 45194039 | I284: 0 | J284: 0
D285: 15266188020 | F285: 7821004404 | H285: 7330307950 | J285: 15756884474

Sheet GV CTY
A2: DANH SÁCH HÀNG HÓA
A4: masp | B4: tensp | C4: dvt | D4: SỐ LƯỢNG | E4: Gía vốn | F4: Trị giá kho
A5: VB2L(IH1 | B5: VS Bò 2 lát (Lon in) hộp 170g | C5: Hộp | F5: =D5*E5 -> 0
A6: AACC4 | B6: AL Anmum Concentrate Choco 4x125ml | C6: Lốc | F6: =D6*E6 -> 0
A7: AACCC4 | B7: AL Anlene Concentrate Choco 4x125ml | C7: Lốc | F7: =D7*E7 -> 0
A8: AACV4 | B8: AL Anlene Concentrate Vanilla 4x125ml | C8: Lốc | D8: 132 | E8: 17367.3 | F8: =D8*E8 -> 2292483.6
A9: AACV4S | B9: AL Anmum Concentrate Vanilla 4x125ml | C9: Lốc | F9: =D9*E9 -> 0
A10: AAGVM1 | B10: AL Anlene Gold Vanilla Movepro 1Kg | C10: Hộp | F10: =D10*E10 -> 0
A11: AAGVM4 | B11: AL Anlene Gold Vanilla Movepro 400g | C11: Lon | D11: 227 | E11: 83500.2 | F11: =D11*E11 -> 18954545
A12: AAGVM4G | B12: AL Anlene Gold Vanilla Movepro 440g | C12: Hộp | D12: 150 | E12: 75700.8 | F12: =D12*E12 -> 11355120
A13: AAGVM8 | B13: AL Anlene Gold Vanilla Movepro 800g | C13: Lon | D13: 0 | F13: =D13*E13 -> 0
A14: AAMC4 | B14: AL Anmum Materna Choco 400g | C14: Lon | F14: =D14*E14 -> 0
A15: AAMC8 | B15: AL Anmum Materna Choco 800g | C15: Lon | F15: =D15*E15 -> 0
A16: AAMU1-CĐ | B16: AL Anlene Movepro UHT 180ml - Có đường | C16: Lốc | D16: 116 | E16: 12041.1 | F16: =D16*E16 -> 1396767.6
A17: AAMU1-KB | B17: AL Anlene Movepro UHT 180ml - Không béo | C17: Lốc | D17: 78 | E17: 12041.1 | F17: =D17*E17 -> 939205.8
A18: AAMV4 | B18: AL Anmum Materna Vanilla 400g | C18: Lon | F18: =D18*E18 -> 0
A19: AAVM4 | B19: AL Anlene Vanilla Movepro 440g | C19: Hộp | F19: =D19*E19 -> 0
A20: AAVM8 | B20: AL Anlene Vanilla Movepro 800g | C20: Lon | D20: 48 | E20: 139243.5 | F20: =D20*E20 -> 6683688
A21: AAVMS2 | B21: AL Anlene Vanilla Movepro Sachet 20gx3 | C21: Hộp | F21: =D21*E21 -> 0
A22: BBQNPC3 | B22: BEL Bánh que nhúng PM C.DIPPERS 30gx48 | C22: Gói | F22: =D22*E22 -> 0
A23: BPBCC13 | B23: BEL Phomai Bánh Chấm C.Dippers1D 35g | C23: Gói | F23: =D23*E23 -> 0
A24: BPKSK1X6 | B24: BEL PM kem sữa Kiri 108G x 60 | C24: Hộp | F24: =D24*E24 -> 0
A25: BPMBC1M | B25: BEL Phô mai CBC 16M | C25: Hộp | F25: =D25*E25 -> 0
A26: BPMBC4M | B26: BEL Phô mai CBC 4M | C26: Hộp | F26: =D26*E26 -> 0
A27: BPMBC8M | B27: BEL Phô mai CBC 8M | C27: Hộp | D27: 273485 | E27: 31208 | F27: =D27*E27 -> 8534919880
A28: BPMC12T | B28: BEL Phô mai CBC 16M 240g Tết | C28: Hộp | F28: =D28*E28 -> 0
A29: BPMC2 | B29: BEL Phô mai CBC 24M | C29: Hộp | F29: =D29*E29 -> 0
A30: BPMC2H | B30: BEL pho mai CBC 24m HRC6 | C30: Hộp | F30: =D30*E30 -> 0
A31: BPMC81T | B31: BEL Phô mai CBC 8M 120g Tết | C31: Hộp | F31: =D31*E31 -> 0
A32: BPMCVS1 | B32: BEL PM vuông Belcube vị sữa 125g | C32: Gói | D32: 306 | E32: 51389 | F32: =D32*E32 -> 15725034
A33: BPMCVS7 | B33: BEL PM vuông Belcube vị sữa 78g | C33: Gói | D33: 25076 | E33: 36184 | F33: =D33*E33 -> 907349984
A34: BPMLB2 | B34: BEL PM Lát CBC Burger 200gx32 | C34: Gói | D34: 130 | E34: 52485 | F34: =D34*E34 -> 6823050
A35: BPMLSC2 | B35: BEL PM Lát Sandwich cheddar 200g | C35: Gói | F35: =D35*E35 -> 0
A36: BPTTVH7 | B36: BEL Phomai Cube Country (truyền thống ) 78g | C36: Hộp | F36: =D36*E36 -> 0
A37: BXPMC1 | B37: BEL Xốt PM CBC 15Gx10x12 | C37: Dây | F37: =D37*E37 -> 0
A38: CBBNXX2 | B38: CLM ĐL Bánh bao nhân xá xíu 280g | C38: Gói | D38: 62 | E38: 29119.92 | F38: =D38*E38 -> 1805435
A39: CBC1 | B39: CLM Bột canh 180g | C39: Gói | D39: 750 | E39: 3463.24 | F39: =D39*E39 -> 2597430
A40: CBCNBN1 | B40: CLM Bột canh nấm bào ngư 180g | C40: Gói | D40: 995 | E40: 4761.96 | F40: =D40*E40 -> 4738150.2
A41: CBCNH1 | B41: CLM Bột canh nấm hương 180g | C41: Gói | D41: 770 | E41: 3896.14 | F41: =D41*E41 -> 3000027.8
A42: CCNND1 | B42: CLM Cá Ngừ ngâm dầu 185g | C42: Hộp | D42: 1708 | E42: 21643.38 | F42: =D42*E42 -> 36966893
...

Sheet ĐC TH
A1: HÀNG TỒN KHO 31/12/2023 ĐÃ ĐIỀU CHỈNH GIÁ
C2: Tồn Đầu Kỳ | E2: Nhập | G2: Xuất | I2: Tồn cuối kỳ
A3: Tên Hàng | B3: Tháng | C3: Số Lượng | D3: T,Tiền | E3: Số Lượng | F3: T.Tiền | G3: Số Lượng | H3: T. Tiền | I3: Số Lượng | J3: Số ĐV | K3: T.Tiền | L3: Đơn Giá
A4: Cá viên Funny 500g | B4: 12 | C4: 226 | D4: 6255676 | E4: 100 | F4: 2774400 | G4: 100 | H4: =D4+F4-K4 -> 2769962 | I4: 226 | K4: 6260114 | L4: =K4/I4 -> 27699.619
A5: AL Anlene Concentrate Choco 4x125ml | B5: 12 | C5: 0 | D5: 0 | E5: 60 | F5: 1188660 | G5: 60 | H5: =D5+F5-K5 -> 1188660 | I5: 0 | K5: 0
A6: AL Anlene Concentrate Vanilla 4x125ml | B6: 12 | C6: 587 | D6: 19248466 | E6: 0 | F6: 0 | G6: 338 | H6: =D6+F6-K6 -> 14931342 | I6: 249 | K6: 4317124 | L6: =K6/I6 -> 17337.847
A7: AL Anlene Gold Vanilla Movepro 1Kg | B7: 12 | C7: 120 | D7: 35752144 | E7: 0 | F7: 0 | G7: 120 | H7: =D7+F7-K7 -> 35752144 | I7: 0 | K7: 0
A8: AL Anlene Gold Vanilla Movepro 400g | B8: 12 | C8: 504 | D8: 68557545 | E8: 0 | F8: 0 | G8: 134 | H8: =D8+F8-K8 -> 37679444 | I8: 370 | K8: 30878101 | L8: =K8/I8 -> 83454.327
A9: AL Anlene Gold Vanilla Movepro 440g | B9: 12 | C9: 344 | D9: 53839916 | E9: 0 | F9: 0 | G9: 34 | H9: =D9+F9-K9 -> 30363208 | I9: 310 | K9: 23476708 | L9: =K9/I9 -> 75731.316
A10: AL Anlene Gold Vanilla Movepro 800g | B10: 12 | C10: 153 | D10: 36613751 | E10: 0 | F10: 0 | G10: 153 | H10: =D10+F10-K10 -> 36613751 | I10: 0 | K10: 0
A11: AL Anlene Movepro UHT 180ml - Có đường | B11: 12 | C11: 554 | D11: 12063982 | E11: 0 | F11: 0 | G11: 344 | H11: =D11+F11-K11 -> 9537950 | I11: 210 | K11: 2526032 | L11: =K11/I11 -> 12028.724
A12: AL Anlene Movepro UHT 180ml - Không béo | B12: 12 | C12: 180 | D12: 3904035 | E12: 0 | F12: 0 | G12: 40 | H12: =D12+F12-K12 -> 2212287 | I12: 140 | K12: 1691748 | L12: =K12/I12 -> 12083.914
A13: AL Anlene Vanilla Movepro 440g | B13: 12 | C13: 295 | D13: 31404753 | E13: 0 | F13: 0 | G13: 277 | H13: =D13+F13-K13 -> 29488531 | I13: 18 | K13: 1916222 | L13: =K13/I13 -> 106456.78
A14: AL Anlene Vanilla Movepro 800g | B14: 12 | C14: 170 | D14: 40681945 | E14: 0 | F14: 0 | G14: 88 | H14: =D14+F14-K14 -> 29195278 | I14: 82 | K14: 11486667 | L14: =K14/I14 -> 140081.3
A15: AL Anlene Vanilla Movepro Sachet 20gx3 | B15: 12 | C15: 18 | D15: 407934 | E15: 0 | F15: 0 | G15: 18 | H15: =D15+F15-K15 -> 407934 | I15: 0 | K15: 0
A16: AL Anmum Concentrate Choco 4x125ml | B16: 12 | C16: 0 | D16: 0 | E16: 3 | F16: 57891 | G16: 3 | H16: =D16+F16-K16 -> 57891 | I16: 0 | K16: 0
A17: AL Anmum Concentrate Vanilla 4x125ml | B17: 12 | C17: 0 | D17: 0 | E17: 12 | F17: 231564 | G17: 12 | H17: =D17+F17-K17 -> 231564 | I17: 0 | K17: 0
A18: Bánh bao chay 300gr | B18: 12 | C18: 72 | D18: 1533524 | E18: 35 | F18: 745360 | G18: 67 | H18: =D18+F18-K18 -> 1490606 | I18: 40 | K18: 788278 | L18: =K18/I18 -> 19706.95
A19: Bánh bao nhân thịt 400gr | B19: 12 | C19: 96 | D19: 2486575 | E19: 51 | F19: 1322226 | G19: 4 | H19: =D19+F19-K19 -> 388653 | I19: 143 | K19: 3420148 | L19: =K19/I19 -> 23917.119
A20: Bánh bao nhân xá xíu 280g | B20: 12 | C20: 67 | D20: 2083589 | E20: 0 | F20: 0 | G20: 1 | H20: =D20+F20-K20 -> 155492 | I20: 66 | K20: 1928097 | L20: =K20/I20 -> 29213.591
A21: Bánh kem xốp phô mai – Richeese Nabati Cheese Cream Wafer 6g | B21: 12 | C21: 650 | D21: 74700000 | E21: 160 | F21: 18432000 | G21: 0 | H21: =D21+F21-K21 -> 0 | I21: 810 | K21: 93132000 | L21: =K21/I21 -> 114977.78
A22: Bánh Kem Xốp Phủ Sô Cô La - Nabati Richoco Time Break 48g | B22: 12 | C22: 280 | D22: 74052080 | E22: 0 | F22: 0 | G22: 0 | H22: =D22+F22-K22 -> 0 | I22: 280 | K22: 74052080 | L22: =K22/I22 -> 264471.71
A23: Bánh kem xốp sữa chua hương phúc bồn tử- Nabati Richberry 110g | B23: 12 | C23: 102 | D23: 19779439 | E23: 0 | F23: 0 | G23: 100 | H23: =D23+F23-K23 -> 19391607 | I23: 2 | K23: 387832 | L23: =K23/I23 -> 193916
A24: Bánh ống lớn nhân phô mai - Nabati Cheese Wafer Stick- Big rolls cheese 14g | B24: 12 | C24: 0 | D24: 0 | E24: 50 | F24: 8509100 | G24: 0 | H24: =D24+F24-K24 -> 0 | I24: 50 | K24: 8509100 | L24: =K24/I24 -> 170182
A25: Bánh Quy Nhân Kem Hương Vani - Nabati Cookies & Cream - Sandwich Cookies with Vanilla Flavour Cream 16g | B25: 12 | C25: 137 | D25: 22821826 | E25: 0 | F25: 0 | G25: 20 | H25: =D25+F25-K25 -> 3331653 | I25: 117 | K25: 19490173 | L25: =K25/I25 -> 166582.68
A26: Bánh quy nhân kem hương Vani - Nabati Cookies & Cream 112g | B26: 12 | C26: 106 | D26: 16323470 | E26: 45 | F26: 10556505 | G26: 58 | H26: =D26+F26-K26 -> 4984366 | I26: 93 | K26: 21895609 | L26: =K26/I26 -> 235436.66
A27: Bánh Quy Nhân Phô Mai - Nabati Richeese Cookies 112g | B27: 12 | C27: 94 | D27: 17372116 | E27: 40 | F27: 9383560 | G27: 63 | H27: =D27+F27-K27 -> 9983461 | I27: 71 | K27: 16772215 | L27: =K27/I27 -> 236228.38
A28: Bánh sôcôla (dạng xốp) – Richoco Nabati Chocolate Cream Wafer 6g | B28: 12 | C28: 351 | D28: 40194000 | E28: 0 | F28: 0 | G28: 0 | H28: =D28+F28-K28 -> 0 | I28: 351 | K28: 40194000 | L28: =K28/I28 -> 114512.82
A29: Bánh xếp kiểu nhật mini 360g | B29: 12 | C29: 40 | D29: 1818200 | E29: 0 | F29: 0 | G29: 0 | H29: =D29+F29-K29 -> 0 | I29: 40 | K29: 1818200 | L29: =K29/I29 -> 45455
A30: BEL Phô mai CBC 16M | B30: 12 | C30: 833 | D30: 46378988 | E30: 4571 | F30: 254508576 | G30: 5404 | H30: =D30+F30-K30 -> 300887564 | I30: 0 | K30: 0 | M30: BEL Phô mai CBC 16M 240g Tết | N30: Hộp | O30: 729
A31: BEL Phô mai CBC 8M | B31: 12 | C31: 273867 | D31: 255643095 | E31: 8568 | F31: 267390144 | G31: 274625 | H31: =D31+F31-K31 -> 279311599 | I31: 7810 | K31: 243721640 | L31: =K31/I31 -> 31206.356 | M31: BEL pho mai CBC 24m HRC6 | N31: Hộp | O31: 120
A32: BEL Pho mai Cube vị sữa 78g | B32: 12 | C32: 25915 | D32: 50321430 | E32: 1500 | F32: 54276000 | G32: 26863 | H32: =D32+F32-K32 -> 84634375 | I32: 552 | K32: 19963055 | L32: =K32/I32 -> 36164.955 | M32: BEL Phô mai CBC 8M 120g Tết | N32: Hộp | O32: 3377
A33: BEL Phô mai vuông LeCube Tổ yến 78g | B33: 12 | C33: 2430 | D33: 87927120 | E33: 0 | F33: 0 | G33: 0 | H33: =D33+F33-K33 -> 0 | I33: 2430 | K33: 87927120 | L33: =K33/I33 -> 36184 | M33: BEL PM Lát CBC Burger 200gx32 | N33: Gói | O33: 130
A34: BEL Phomai Cube Country (truyền thống ) 78g | B34: 12 | C34: 0 | D34: 189538 | E34: 0 | F34: 0 | G34: 0 | H34: =D34+F34-K34 -> 0 | I34: 0 | K34: 189538 | M34: BEL PM vuông Belcube vị ngọt Dâu 78g | N34: Gói | O34: 750
A35: BEL PM Lát CBC Burger 200gx32 | B35: 12 | C35: 160 | D35: 8538638 | E35: 0 | F35: 0 | G35: 26 | H35: =D35+F35-K35 -> 1526583 | I35: 134 | K35: 7012055 | L35: =K35/I35 -> 52328.769 | M35: BEL PM vuông Belcube vị ngọt Socola 78g | N35: Gói | O35: 245
A36: BEL PM Vuông LeCube 9C/ 47G (12/LỐ ) | B36: 12 | C36: 0 | D36: 0 | E36: 0 | F36: 0 | G36: 0 | H36: =D36+F36-K36 -> 0 | I36: 0 | K36: 0 | M36: BEL PM vuông Belcube vị ngọt Vani 78g | N36: Gói | O36: 125
A37: BEL PM vuông Belcube vị ngọt Dâu 78g | B37: 12 | C37: 9485 | D37: 33640650 | E37: 1050 | F37: 37993200 | G37: 9635 | H37: =D37+F37-K37 -> 39077621 | I37: 900 | K37: 32556229 | L37: =K37/I37 -> 36173.588 | M37: BEL PM vuông Belcube vị sữa 125g | N37: Gói | O37: 399
A38: BEL PM vuông Belcube vị ngọt Socola 78g | B38: 12 | C38: 320 | D38: 11571799 | E38: 405 | F38: 14654520 | G38: 630 | H38: =D38+F38-K38 -> 22789767 | I38: 95 | K38: 3436552 | L38: =K38/I38 -> 36174.232 | M38: BEL PM vuông Belcube vị sữa 78g | N38: Gói | O38: 486
A39: BEL PM vuông Belcube vị ngọt Vani 78g | B39: 12 | C39: 270 | D39: 9896208 | E39: 120 | F39: 4342080 | G39: 319 | H39: =D39+F39-K39 -> 11669303 | I39: 71 | K39: 2568985 | L39: =K39/I39 -> 36182.887 | M39: BEL PM vuông Belcube vị Việt Quất 78g | N39: Gói | O39: 558
A40: Bột canh nấm bào ngư 180g | B40: 12 | C40: 1500 | D40: 7597338 | E40: 250 | F40: 1273250 | G40: 691 | H40: =D40+F40-K40 -> 3827026 | I40: 1059 | K40: 5043562 | L40: =K40/I40 -> 4762.5703 | M40: 1070
...

Sheet CHỈN LẦN 3
A2: XUẤT NHẬP TỒN THÁNG 12 NĂM 2023
D4: TỒN ĐẦU KỲ | F4: NHẬP TRONG KỲ | H4: XUẤT TRONG KỲ | J4: TỒN CUỐI KỲ
A5: MHH | B5: TÊN HÀNG HOÁ | C5: dvt | D5: SL | E5: T.TIỀN | F5: SL | G5: T.TIỀN | H5: SL | I5: T.TIỀN | J5: SỐ LƯỢNG | K5: Gía vốn | L5: Trị giá kho
A6: VB2L(IH1 | B6: VS Bò 2 lát (Lon in) hộp 170g | C6: Hộp | L6: =J6*K6 -> 0
A7: AACC4 | B7: AL Anmum Concentrate Choco 4x125ml | C7: Lốc | L7: =J7*K7 -> 0
A8: AACCC4 | B8: AL Anlene Concentrate Choco 4x125ml | C8: Lốc | L8: =J8*K8 -> 0
A9: AACV4 | B9: AL Anlene Concentrate Vanilla 4x125ml | C9: Lốc | D9: 587 | E9: 19248466 | F9: 0 | G9: 0 | H9: 338 | I9: =E9+G9-K9 -> 19231099 | J9: 132 | K9: 17367.3 | L9: =J9*K9 -> 2292483.6
A10: AACV4S | B10: AL Anmum Concentrate Vanilla 4x125ml | C10: Lốc | L10: =J10*K10 -> 0
A11: AAGVM1 | B11: AL Anlene Gold Vanilla Movepro 1Kg | C11: Hộp | L11: =J11*K11 -> 0
A12: AAGVM4 | B12: AL Anlene Gold Vanilla Movepro 400g | C12: Lon | D12: 504 | E12: 68557545 | F12: 0 | G12: 0 | H12: 134 | I12: =E12+G12-K12 -> 68474045 | J12: 227 | K12: 83500.2 | L12: =J12*K12 -> 18954545
A13: AAGVM4G | B13: AL Anlene Gold Vanilla Movepro 440g | C13: Hộp | D13: 344 | E13: 53839916 | F13: 0 | G13: 0 | H13: 34 | I13: =E13+G13-K13 -> 53764215 | J13: 150 | K13: 75700.8 | L13: =J13*K13 -> 11355120
A14: AAGVM8 | B14: AL Anlene Gold Vanilla Movepro 800g | C14: Lon | J14: 0 | L14: =J14*K14 -> 0
A15: AAMC4 | B15: AL Anmum Materna Choco 400g | C15: Lon | L15: =J15*K15 -> 0
A16: AAMC8 | B16: AL Anmum Materna Choco 800g | C16: Lon | L16: =J16*K16 -> 0
A17: AAMU1-CĐ | B17: AL Anlene Movepro UHT 180ml - Có đường | C17: Lốc | D17: 554 | E17: 12063982 | F17: 0 | G17: 0 | H17: 344 | I17: =E17+G17-K17 -> 12051941 | J17: 116 | K17: 12041.1 | L17: =J17*K17 -> 1396767.6
A18: AAMU1-KB | B18: AL Anlene Movepro UHT 180ml - Không béo | C18: Lốc | D18: 180 | E18: 3904035 | F18: 0 | G18: 0 | H18: 40 | I18: =E18+G18-K18 -> 3891993.9 | J18: 78 | K18: 12041.1 | L18: =J18*K18 -> 939205.8
A19: AAMV4 | B19: AL Anmum Materna Vanilla 400g | C19: Lon | L19: =J19*K19 -> 0
A20: AAVM4 | B20: AL Anlene Vanilla Movepro 440g | C20: Hộp | L20: =J20*K20 -> 0
A21: AAVM8 | B21: AL Anlene Vanilla Movepro 800g | C21: Lon | D21: 170 | E21: 40681945 | F21: 0 | G21: 0 | H21: 88 | I21: =E21+G21-K21 -> 40542702 | J21: 48 | K21: 139243.5 | L21: =J21*K21 -> 6683688
A22: AAVMS2 | B22: AL Anlene Vanilla Movepro Sachet 20gx3 | C22: Hộp | L22: =J22*K22 -> 0
A23: BBQNPC3 | B23: BEL Bánh que nhúng PM C.DIPPERS 30gx48 | C23: Gói | L23: =J23*K23 -> 0
A24: BPBCC13 | B24: BEL Phomai Bánh Chấm C.Dippers1D 35g | C24: Gói | L24: =J24*K24 -> 0
A25: BPKSK1X6 | B25: BEL PM kem sữa Kiri 108G x 60 | C25: Hộp | L25: =J25*K25 -> 0
A26: BPMBC1M | B26: BEL Phô mai CBC 16M | C26: Hộp | D26: 833 | E26: 46378988 | F26: 4571 | G26: 254508576 | H26: 5404 | I26: =E26+G26-K26 -> 300821345 | J26: 3840 | K26: 66219 | L26: =J26*K26 -> 254280960
A27: BPMBC4M | B27: BEL Phô mai CBC 4M | C27: Hộp | L27: =J27*K27 -> 0
A28: BPMBC8M | B28: BEL Phô mai CBC 8M | C28: Hộp | D28: 273867 | E28: 255643095 | F28: 8568 | G28: 267390144 | H28: 274625 | I28: =E28+G28-K28 -> 523002031 | J28: 5200 | K28: 31208 | L28: =J28*K28 -> 162281600
A29: BPMC12T | B29: BEL Phô mai CBC 16M 240g Tết | C29: Hộp | L29: =J29*K29 -> 0
A30: BPMC2 | B30: BEL Phô mai CBC 24M | C30: Hộp | L30: =J30*K30 -> 0
A31: BPMC2H | B31: BEL pho mai CBC 24m HRC6 | C31: Hộp | L31: =J31*K31 -> 0
A32: BPMC81T | B32: BEL Phô mai CBC 8M 120g Tết | C32: Hộp | L32: =J32*K32 -> 0
A33: BPMCVS1 | B33: BEL PM vuông Belcube vị sữa 125g | C33: Gói | J33: 306 | K33: 51389 | L33: =J33*K33 -> 15725034
A34: BPMCVS7 | B34: BEL PM vuông Belcube vị sữa 78g | C34: Gói | D34: 25915 | E34: 50321430 | F34: 1500 | G34: 54276000 | H34: 26863 | I34: =E34+G34-K34 -> 104561246 | J34: 2000 | K34: 36184 | L34: =J34*K34 -> 72368000
A35: BPMLB2 | B35: BEL PM Lát CBC Burger 200gx32 | C35: Gói | D35: 160 | E35: 8538638 | F35: 0 | G35: 0 | H35: 26 | I35: =E35+G35-K35 -> 8486153 | J35: 130 | K35: 52485 | L35: =J35*K35 -> 6823050
A36: BPMLSC2 | B36: BEL PM Lát Sandwich cheddar 200g | C36: Gói | L36: =J36*K36 -> 0
A37: BPTTVH7 | B37: BEL Phomai Cube Country (truyền thống ) 78g | C37: Hộp | L37: =J37*K37 -> 0
A38: BXPMC1 | B38: BEL Xốt PM CBC 15Gx10x12 | C38: Dây | L38: =J38*K38 -> 0
A39: CBBNXX2 | B39: CLM ĐL Bánh bao nhân xá xíu 280g | C39: Gói | J39: 62 | K39: 29119.92 | L39: =J39*K39 -> 1805435
A40: CBC1 | B40: CLM Bột canh 180g | C40: Gói | D40: 750 | E40: 2517000 | F40: 0 | G40: 0 | H40: 23 | I40: =E40+G40-K40 -> 2513536.8 | J40: 750 | K40: 3463.24 | L40: =J40*K40 -> 2597430
A41: CBCNBN1 | B41: CLM Bột canh nấm bào ngư 180g | C41: Gói | D41: 1500 | E41: 7597338 | F41: 250 | G41: 1273250 | H41: 691 | I41: =E41+G41-K41 -> 8865826 | J41: 995 | K41: 4761.96 | L41: =J41*K41 -> 4738150.2
A42: CBCNH1 | B42: CLM Bột canh nấm hương 180g | C42: Gói | D42: 1350 | E42: 5561964 | F42: 200 | G42: 833400 | H42: 780 | I42: =E42+G42-K42 -> 6391467.9 | J42: 770 | K42: 3896.14 | L42: =J42*K42 -> 3000027.8
...

Sheet ĐC theo Lý
A1: HÀNG TỒN KHO 31/12/2023 ĐÃ ĐIỀU CHỈNH GIÁ
C2: Tồn Đầu Kỳ | E2: Nhập | G2: Xuất | I2: Tồn cuối kỳ | M2: masp | N2: tensp | O2: dvt | P2: SỐ LƯỢNG | Q2: Gía vốn | R2: Trị giá kho
A3: Tên Hàng | B3: Tháng | C3: Số Lượng | D3: T,Tiền | E3: Số Lượng | F3: T.Tiền | G3: Số Lượng | H3: T. Tiền | I3: Số Lượng | J3: T.Tiền | K3: Đơn Giá | L3: 1 | M3: VB2L(IH1 | N3: VS Bò 2 lát (Lon in) hộp 170g | O3: Hộp | R3: 0
A4: Cá viên Funny 500g | B4: 12 | C4: 226 | D4: 6255676 | E4: 100 | F4: 2774400 | G4: 100 | H4: =D4+F4-J4 -> 2769962 | I4: 226 | J4: 6260114 | K4: =J4/I4 -> 27699.619 | L4: 2 | M4: AACC4 | N4: AL Anmum Concentrate Choco 4x125ml | O4: Lốc | R4: 0
A5: AL Anlene Concentrate Choco 4x125ml | B5: 12 | C5: 0 | D5: 0 | E5: 60 | F5: 1188660 | G5: 60 | H5: =D5+F5-J5 -> 1188660 | I5: 0 | J5: 0 | L5: 3 | M5: AACCC4 | N5: AL Anlene Concentrate Choco 4x125ml | O5: Lốc | R5: 0
A6: AL Anlene Concentrate Vanilla 4x125ml | B6: 12 | C6: 587 | D6: 19248466 | E6: 0 | F6: 0 | G6: 338 | H6: =D6+F6-J6 -> 16955982 | I6: 132 | J6: =I6*K6 -> 2292483.6 | K6: 17367.3 | L6: 4 | M6: AACV4 | N6: AL Anlene Concentrate Vanilla 4x125ml | O6: Lốc | P6: 132 | Q6: 17367.3 | R6: 2292483.6
A7: AL Anlene Gold Vanilla Movepro 1Kg | B7: 12 | C7: 120 | D7: 35752144 | E7: 0 | F7: 0 | G7: 120 | H7: =D7+F7-J7 -> 35752144 | I7: 0 | J7: 0 | L7: 5 | M7: AACV4S | N7: AL Anmum Concentrate Vanilla 4x125ml | O7: Lốc | R7: 0
A8: AL Anlene Gold Vanilla Movepro 400g | B8: 12 | C8: 504 | D8: 68557545 | E8: 0 | F8: 0 | G8: 134 | H8: =D8+F8-J8 -> 49603045 | I8: 227 | J8: =I8*K8 -> 18954500 | K8: 83500 | L8: 6 | M8: AAGVM1 | N8: AL Anlene Gold Vanilla Movepro 1Kg | O8: Hộp | R8: 0
A9: AL Anlene Gold Vanilla Movepro 440g | B9: 12 | C9: 344 | D9: 53839916 | E9: 0 | F9: 0 | G9: 34 | H9: =D9+F9-J9 -> 42484796 | I9: 150 | J9: =I9*K9 -> 11355120 | K9: 75700.8 | L9: 7 | M9: AAGVM4 | N9: AL Anlene Gold Vanilla Movepro 400g | O9: Lon | P9: 227 | Q9: 83500.2 | R9: 18954545
A10: AL Anlene Gold Vanilla Movepro 800g | B10: 12 | C10: 153 | D10: 36613751 | E10: 0 | F10: 0 | G10: 153 | H10: =D10+F10-J10 -> 36613751 | I10: 0 | J10: 0 | L10: 8 | M10: AAGVM4G | N10: AL Anlene Gold Vanilla Movepro 440g | O10: Hộp | P10: 150 | Q10: 75700.8 | R10: 11355120
A11: AL Anlene Movepro UHT 180ml - Có đường | B11: 12 | C11: 554 | D11: 12063982 | E11: 0 | F11: 0 | G11: 344 | H11: =D11+F11-J11 -> 10667226 | I11: 116 | J11: =I11*K11 -> 1396756 | K11: 12041 | L11: 9 | M11: AAGVM8 | N11: AL Anlene Gold Vanilla Movepro 800g | O11: Lon | P11: 0 | R11: 0
A12: AL Anlene Movepro UHT 180ml - Không béo | B12: 12 | C12: 180 | D12: 3904035 | E12: 0 | F12: 0 | G12: 40 | H12: =D12+F12-J12 -> 2964837 | I12: 78 | J12: =I12*K12 -> 939198 | K12: 12041 | L12: 10 | M12: AAMC4 | N12: AL Anmum Materna Choco 400g | O12: Lon | R12: 0
A13: AL Anlene Vanilla Movepro 440g | B13: 12 | C13: 295 | D13: 31404753 | E13: 0 | F13: 0 | G13: 277 | H13: =D13+F13-J13 -> 29488531 | I13: 18 | J13: 1916222 | K13: =J13/I13 -> 106456.78 | L13: 11 | M13: AAMC8 | N13: AL Anmum Materna Choco 800g | O13: Lon | R13: 0
A14: AL Anlene Vanilla Movepro 800g | B14: 12 | C14: 170 | D14: 40681945 | E14: 0 | F14: 0 | G14: 88 | H14: =D14+F14-J14 -> 33998257 | I14: 48 | J14: =I14*K14 -> 6683688 | K14: 139243.5 | L14: 12 | M14: AAMU1-CĐ | N14: AL Anlene Movepro UHT 180ml - Có đường | O14: Lốc | P14: 116 | Q14: 12041.1 | R14: 1396767.6
A15: AL Anlene Vanilla Movepro Sachet 20gx3 | B15: 12 | C15: 18 | D15: 407934 | E15: 0 | F15: 0 | G15: 18 | H15: =D15+F15-J15 -> 407934 | I15: 0 | J15: 0 | L15: 13 | M15: AAMU1-KB | N15: AL Anlene Movepro UHT 180ml - Không béo | O15: Lốc | P15: 78 | Q15: 12041.1 | R15: 939205.8
A16: AL Anmum Concentrate Choco 4x125ml | B16: 12 | C16: 0 | D16: 0 | E16: 3 | F16: 57891 | G16: 3 | H16: =D16+F16-J16 -> 57891 | I16: 0 | J16: 0 | L16: 14 | M16: AAMV4 | N16: AL Anmum Materna Vanilla 400g | O16: Lon | R16: 0
A17: AL Anmum Concentrate Vanilla 4x125ml | B17: 12 | C17: 0 | D17: 0 | E17: 12 | F17: 231564 | G17: 12 | H17: =D17+F17-J17 -> 231564 | I17: 0 | J17: 0 | L17: 15 | M17: AAVM4 | N17: AL Anlene Vanilla Movepro 440g | O17: Hộp | R17: 0
A18: Bánh bao chay 300gr | B18: 12 | C18: 72 | D18: 1533524 | E18: 35 | F18: 745360 | G18: 67 | H18: =D18+F18-J18 -> 1490606 | I18: 40 | J18: 788278 | K18: =J18/I18 -> 19706.95 | L18: 16 | M18: AAVM8 | N18: AL Anlene Vanilla Movepro 800g | O18: Lon | P18: 48 | Q18: 139243.5 | R18: 6683688
A19: Bánh bao nhân thịt 400gr | B19: 12 | C19: 96 | D19: 2486575 | E19: 51 | F19: 1322226 | G19: 4 | H19: =D19+F19-J19 -> 388653 | I19: 143 | J19: 3420148 | K19: =J19/I19 -> 23917.119 | L19: 17 | M19: AAVMS2 | N19: AL Anlene Vanilla Movepro Sachet 20gx3 | O19: Hộp | R19: 0
A20: Bánh bao nhân xá xíu 280g | B20: 12 | C20: 67 | D20: 2083589 | E20: 0 | F20: 0 | G20: 1 | H20: =D20+F20-J20 -> 155492 | I20: 66 | J20: 1928097 | K20: =J20/I20 -> 29213.591 | L20: 18 | M20: BBQNPC3 | N20: BEL Bánh que nhúng PM C.DIPPERS 30gx48 | O20: Gói | R20: 0
A21: Bánh kem xốp phô mai – Richeese Nabati Cheese Cream Wafer 6g | B21: 12 | C21: 650 | D21: 74700000 | E21: 160 | F21: 18432000 | G21: 0 | H21: =D21+F21-J21 -> 0 | I21: 810 | J21: 93132000 | K21: =J21/I21 -> 114977.78 | L21: 19 | M21: BPBCC13 | N21: BEL Phomai Bánh Chấm C.Dippers1D 35g | O21: Gói | R21: 0
A22: Bánh Kem Xốp Phủ Sô Cô La - Nabati Richoco Time Break 48g | B22: 12 | C22: 280 | D22: 74052080 | E22: 0 | F22: 0 | G22: 0 | H22: =D22+F22-J22 -> 0 | I22: 280 | J22: 74052080 | K22: =J22/I22 -> 264471.71 | L22: 20 | M22: BPKSK1X6 | N22: BEL PM kem sữa Kiri 108G x 60 | O22: Hộp | R22: 0
A23: Bánh kem xốp sữa chua hương phúc bồn tử- Nabati Richberry 110g | B23: 12 | C23: 102 | D23: 19779439 | E23: 0 | F23: 0 | G23: 100 | H23: =D23+F23-J23 -> 19391607 | I23: 2 | J23: 387832 | K23: =J23/I23 -> 193916 | L23: 21 | M23: BPMBC1M | N23: BEL Phô mai CBC 16M | O23: Hộp | P23: 3840 | Q23: 66219 | R23: 254280960
A24: Bánh ống lớn nhân phô mai - Nabati Cheese Wafer Stick- Big rolls cheese 14g | B24: 12 | C24: 0 | D24: 0 | E24: 50 | F24: 8509100 | G24: 0 | H24: =D24+F24-J24 -> 0 | I24: 50 | J24: 8509100 | K24: =J24/I24 -> 170182 | L24: 22 | M24: BPMBC4M | N24: BEL Phô mai CBC 4M | O24: Hộp | R24: 0
A25: Bánh Quy Nhân Kem Hương Vani - Nabati Cookies & Cream - Sandwich Cookies with Vanilla Flavour Cream 16g | B25: 12 | C25: 137 | D25: 22821826 | E25: 0 | F25: 0 | G25: 20 | H25: =D25+F25-J25 -> 3331653 | I25: 117 | J25: 19490173 | K25: =J25/I25 -> 166582.68 | L25: 23 | M25: BPMBC8M | N25: BEL Phô mai CBC 8M | O25: Hộp | P25: 5200 | Q25: 31208 | R25: 162281600
A26: Bánh quy nhân kem hương Vani - Nabati Cookies & Cream 112g | B26: 12 | C26: 106 | D26: 16323470 | E26: 45 | F26: 10556505 | G26: 58 | H26: =D26+F26-J26 -> 4984366 | I26: 93 | J26: 21895609 | K26: =J26/I26 -> 235436.66 | L26: 24 | M26: BPMC12T | N26: BEL Phô mai CBC 16M 240g Tết | O26: Hộp | R26: 0
A27: Bánh Quy Nhân Phô Mai - Nabati Richeese Cookies 112g | B27: 12 | C27: 94 | D27: 17372116 | E27: 40 | F27: 9383560 | G27: 63 | H27: =D27+F27-J27 -> 9983461 | I27: 71 | J27: 16772215 | K27: =J27/I27 -> 236228.38 | L27: 25 | M27: BPMC2 | N27: BEL Phô mai CBC 24M | O27: Hộp | R27: 0
A28: Bánh sôcôla (dạng xốp) – Richoco Nabati Chocolate Cream Wafer 6g | B28: 12 | C28: 351 | D28: 40194000 | E28: 0 | F28: 0 | G28: 0 | H28: =D28+F28-J28 -> 0 | I28: 351 | J28: 40194000 | K28: =J28/I28 -> 114512.82 | L28: 26 | M28: BPMC2H | N28: BEL pho mai CBC 24m HRC6 | O28: Hộp | R28: 0
A29: Bánh xếp kiểu nhật mini 360g | B29: 12 | C29: 40 | D29: 1818200 | E29: 0 | F29: 0 | G29: 0 | H29: =D29+F29-J29 -> 0 | I29: 40 | J29: 1818200 | K29: =J29/I29 -> 45455 | L29: 27 | M29: BPMC81T | N29: BEL Phô mai CBC 8M 120g Tết | O29: Hộp | R29: 0
A30: BEL Phô mai CBC 16M | B30: 12 | C30: 833 | D30: 46378988 | E30: 4571 | F30: 254508576 | G30: 5404 | H30: =D30+F30-J30 -> 46606604 | I30: 3840 | J30: =I30*K30 -> 254280960 | K30: 66219 | L30: 28 | M30: BPMCVS1 | N30: BEL PM vuông Belcube vị sữa 125g | O30: Gói | P30: 306 | Q30: 51389 | R30: 15725034
A31: BEL Phô mai CBC 8M | B31: 12 | C31: 273867 | D31: 255643095 | E31: 8568 | F31: 267390144 | G31: 274625 | H31: =D31+F31-J31 -> 360751639 | I31: 5200 | J31: =I31*K31 -> 162281600 | K31: 31208 | L31: 29 | M31: BPMCVS7 | N31: BEL PM vuông Belcube vị sữa 78g | O31: Gói | P31: 2000 | Q31: 36184 | R31: 72368000
A32: BEL Pho mai Cube vị sữa 78g | B32: 12 | C32: 25915 | D32: 50321430 | E32: 1500 | F32: 54276000 | G32: 26863 | H32: =D32+F32-J32 -> 32229430 | I32: 2000 | J32: =I32*K32 -> 72368000 | K32: 36184 | L32: 30 | M32: BPMLB2 | N32: BEL PM Lát CBC Burger 200gx32 | O32: Gói | P32: 130 | Q32: 52485 | R32: 6823050
A33: BEL Phô mai vuông LeCube Tổ yến 78g | B33: 12 | C33: 2430 | D33: 87927120 | E33: 0 | F33: 0 | G33: 0 | H33: =D33+F33-J33 -> 0 | I33: 2430 | J33: 87927120 | K33: =J33/I33 -> 36184 | L33: 31 | M33: BPMLSC2 | N33: BEL PM Lát Sandwich cheddar 200g | O33: Gói | R33: 0
A34: BEL Phomai Cube Country (truyền thống ) 78g | B34: 12 | C34: 0 | D34: 189538 | E34: 0 | F34: 0 | G34: 0 | H34: =D34+F34-J34 -> 0 | I34: 0 | J34: 189538 | L34: 32 | M34: BPTTVH7 | N34: BEL Phomai Cube Country (truyền thống ) 78g | O34: Hộp | R34: 0
A35: BEL PM Lát CBC Burger 200gx32 | B35: 12 | C35: 160 | D35: 8538638 | E35: 0 | F35: 0 | G35: 26 | H35: =D35+F35-J35 -> 1715588 | I35: 130 | J35: =I35*K35 -> 6823050 | K35: 52485 | L35: 33 | M35: BXPMC1 | N35: BEL Xốt PM CBC 15Gx10x12 | O35: Dây | R35: 0
A36: BEL PM Vuông LeCube 9C/ 47G (12/LỐ ) | B36: 12 | C36: 0 | D36: 0 | E36: 0 | F36: 0 | G36: 0 | H36: =D36+F36-J36 -> 0 | I36: 0 | J36: 0 | L36: 34 | M36: CBBNXX2 | N36: CLM ĐL Bánh bao nhân xá xíu 280g | O36: Gói | P36: 62 | Q36: 29119.92 | R36: 1805435
A37: BEL PM vuông Belcube vị ngọt Dâu 78g | B37: 12 | C37: 9485 | D37: 33640650 | E37: 1050 | F37: 37993200 | G37: 9635 | H37: =D37+F37-J37 -> 39077621 | I37: 900 | J37: 32556229 | K37: =J37/I37 -> 36173.588 | L37: 35 | M37: CBC1 | N37: CLM Bột canh 180g | O37: Gói | P37: 750 | Q37: 3463.24 | R37: 2597430
A38: BEL PM vuông Belcube vị ngọt Socola 78g | B38: 12 | C38: 320 | D38: 11571799 | E38: 405 | F38: 14654520 | G38: 630 | H38: =D38+F38-J38 -> 22789767 | I38: 95 | J38: 3436552 | K38: =J38/I38 -> 36174.232 | L38: 36 | M38: CBCNBN1 | N38: CLM Bột canh nấm bào ngư 180g | O38: Gói | P38: 995 | Q38: 4761.96 | R38: 4738150.2
A39: BEL PM vuông Belcube vị ngọt Vani 78g | B39: 12 | C39: 270 | D39: 9896208 | E39: 120 | F39: 4342080 | G39: 319 | H39: =D39+F39-J39 -> 11669303 | I39: 71 | J39: 2568985 | K39: =J39/I39 -> 36182.887 | L39: 37 | M39: CBCNH1 | N39: CLM Bột canh nấm hương 180g | O39: Gói | P39: 770 | Q39: 3896.14 | R39: 3000027.8
A40: Bột canh nấm bào ngư 180g | B40: 12 | C40: 1500 | D40: 7597338 | E40: 250 | F40: 1273250 | G40: 691 | H40: =D40+F40-J40 -> 4132398 | I40: 995 | J40: =I40*K40 -> 4738190 | K40: 4762 | L40: 38 | M40: CCNND1 | N40: CLM Cá Ngừ ngâm dầu 185g | O40: Hộp | P40: 1708 | Q40: 21643.38 | R40: 36966893
...

Sheet ĐC Chính
A1: HÀNG TỒN KHO 31/12/2023 ĐÃ ĐIỀU CHỈNH GIÁ
C2: Tồn Đầu Kỳ | E2: Nhập | G2: Xuất | I2: Tồn cuối kỳ
A3: Tên Hàng | B3: Tháng | C3: Số Lượng | D3: T,Tiền | E3: Số Lượng | F3: T.Tiền | G3: Số Lượng | H3: T. Tiền | I3: Số Lượng | J3: T.Tiền | K3: Đơn Giá
A4: Cá viên Funny 500g | B4: 12 | C4: 226 | D4: 6255676 | E4: 100 | F4: 2774400 | G4: 100 | H4: =D4+F4-J4 -> 2769962 | I4: 226 | J4: 6260114 | K4: =J4/I4 -> 27699.619
A5: AL Anlene Concentrate Choco 4x125ml | B5: 12 | C5: 0 | D5: 0 | E5: 60 | F5: 1188660 | G5: 60 | H5: =D5+F5-J5 -> 1188660 | I5: 0 | J5: 0
A6: AL Anlene Concentrate Vanilla 4x125ml | B6: 12 | C6: 587 | D6: 19248466 | E6: 0 | F6: 0 | G6: 338 | H6: =D6+F6-J6 -> 14931342 | I6: 249 | J6: 4317124 | K6: =J6/I6 -> 17337.847
A7: AL Anlene Gold Vanilla Movepro 1Kg | B7: 12 | C7: 120 | D7: 35752144 | E7: 0 | F7: 0 | G7: 120 | H7: =D7+F7-J7 -> 35752144 | I7: 0 | J7: 0
A8: AL Anlene Gold Vanilla Movepro 400g | B8: 12 | C8: 504 | D8: 68557545 | E8: 0 | F8: 0 | G8: 134 | H8: =D8+F8-J8 -> 37679444 | I8: 370 | J8: 30878101 | K8: =J8/I8 -> 83454.327
A9: AL Anlene Gold Vanilla Movepro 440g | B9: 12 | C9: 344 | D9: 53839916 | E9: 0 | F9: 0 | G9: 34 | H9: =D9+F9-J9 -> 30363208 | I9: 310 | J9: 23476708 | K9: =J9/I9 -> 75731.316
A10: AL Anlene Gold Vanilla Movepro 800g | B10: 12 | C10: 153 | D10: 36613751 | E10: 0 | F10: 0 | G10: 153 | H10: =D10+F10-J10 -> 36613751 | I10: 0 | J10: 0
A11: AL Anlene Movepro UHT 180ml - Có đường | B11: 12 | C11: 554 | D11: 12063982 | E11: 0 | F11: 0 | G11: 344 | H11: =D11+F11-J11 -> 9537950 | I11: 210 | J11: 2526032 | K11: =J11/I11 -> 12028.724
A12: AL Anlene Movepro UHT 180ml - Không béo | B12: 12 | C12: 180 | D12: 3904035 | E12: 0 | F12: 0 | G12: 40 | H12: =D12+F12-J12 -> 2212287 | I12: 140 | J12: 1691748 | K12: =J12/I12 -> 12083.914
A13: AL Anlene Vanilla Movepro 440g | B13: 12 | C13: 295 | D13: 31404753 | E13: 0 | F13: 0 | G13: 277 | H13: =D13+F13-J13 -> 29488531 | I13: 18 | J13: 1916222 | K13: =J13/I13 -> 106456.78
A14: AL Anlene Vanilla Movepro 800g | B14: 12 | C14: 170 | D14: 40681945 | E14: 0 | F14: 0 | G14: 88 | H14: =D14+F14-J14 -> 29195278 | I14: 82 | J14: 11486667 | K14: =J14/I14 -> 140081.3
A15: AL Anlene Vanilla Movepro Sachet 20gx3 | B15: 12 | C15: 18 | D15: 407934 | E15: 0 | F15: 0 | G15: 18 | H15: =D15+F15-J15 -> 407934 | I15: 0 | J15: 0
A16: AL Anmum Concentrate Choco 4x125ml | B16: 12 | C16: 0 | D16: 0 | E16: 3 | F16: 57891 | G16: 3 | H16: =D16+F16-J16 -> 57891 | I16: 0 | J16: 0
A17: AL Anmum Concentrate Vanilla 4x125ml | B17: 12 | C17: 0 | D17: 0 | E17: 12 | F17: 231564 | G17: 12 | H17: =D17+F17-J17 -> 231564 | I17: 0 | J17: 0
A18: Bánh bao chay 300gr | B18: 12 | C18: 72 | D18: 1533524 | E18: 35 | F18: 745360 | G18: 67 | H18: =D18+F18-J18 -> 1490606 | I18: 40 | J18: 788278 | K18: =J18/I18 -> 19706.95
A19: Bánh bao nhân thịt 400gr | B19: 12 | C19: 96 | D19: 2486575 | E19: 51 | F19: 1322226 | G19: 4 | H19: =D19+F19-J19 -> 388653 | I19: 143 | J19: 3420148 | K19: =J19/I19 -> 23917.119
A20: Bánh bao nhân xá xíu 280g | B20: 12 | C20: 67 | D20: 2083589 | E20: 0 | F20: 0 | G20: 1 | H20: =D20+F20-J20 -> 155492 | I20: 66 | J20: 1928097 | K20: =J20/I20 -> 29213.591
A21: Bánh kem xốp phô mai – Richeese Nabati Cheese Cream Wafer 6g | B21: 12 | C21: 650 | D21: 74700000 | E21: 160 | F21: 18432000 | G21: 0 | H21: =D21+F21-J21 -> 0 | I21: 810 | J21: 93132000 | K21: =J21/I21 -> 114977.78
A22: Bánh Kem Xốp Phủ Sô Cô La - Nabati Richoco Time Break 48g | B22: 12 | C22: 280 | D22: 74052080 | E22: 0 | F22: 0 | G22: 0 | H22: =D22+F22-J22 -> 0 | I22: 280 | J22: 74052080 | K22: =J22/I22 -> 264471.71
A23: Bánh kem xốp sữa chua hương phúc bồn tử- Nabati Richberry 110g | B23: 12 | C23: 102 | D23: 19779439 | E23: 0 | F23: 0 | G23: 100 | H23: =D23+F23-J23 -> 19391607 | I23: 2 | J23: 387832 | K23: =J23/I23 -> 193916
A24: Bánh ống lớn nhân phô mai - Nabati Cheese Wafer Stick- Big rolls cheese 14g | B24: 12 | C24: 0 | D24: 0 | E24: 50 | F24: 8509100 | G24: 0 | H24: =D24+F24-J24 -> 0 | I24: 50 | J24: 8509100 | K24: =J24/I24 -> 170182
A25: Bánh Quy Nhân Kem Hương Vani - Nabati Cookies & Cream - Sandwich Cookies with Vanilla Flavour Cream 16g | B25: 12 | C25: 137 | D25: 22821826 | E25: 0 | F25: 0 | G25: 20 | H25: =D25+F25-J25 -> 3331653 | I25: 117 | J25: 19490173 | K25: =J25/I25 -> 166582.68
A26: Bánh quy nhân kem hương Vani - Nabati Cookies & Cream 112g | B26: 12 | C26: 106 | D26: 16323470 | E26: 45 | F26: 10556505 | G26: 58 | H26: =D26+F26-J26 -> 4984366 | I26: 93 | J26: 21895609 | K26: =J26/I26 -> 235436.66
A27: Bánh Quy Nhân Phô Mai - Nabati Richeese Cookies 112g | B27: 12 | C27: 94 | D27: 17372116 | E27: 40 | F27: 9383560 | G27: 63 | H27: =D27+F27-J27 -> 9983461 | I27: 71 | J27: 16772215 | K27: =J27/I27 -> 236228.38
A28: Bánh sôcôla (dạng xốp) – Richoco Nabati Chocolate Cream Wafer 6g | B28: 12 | C28: 351 | D28: 40194000 | E28: 0 | F28: 0 | G28: 0 | H28: =D28+F28-J28 -> 0 | I28: 351 | J28: 40194000 | K28: =J28/I28 -> 114512.82
A29: Bánh xếp kiểu nhật mini 360g | B29: 12 | C29: 40 | D29: 1818200 | E29: 0 | F29: 0 | G29: 0 | H29: =D29+F29-J29 -> 0 | I29: 40 | J29: 1818200 | K29: =J29/I29 -> 45455
A30: BEL Phô mai CBC 16M | B30: 12 | C30: 833 | D30: 46378988 | E30: 4571 | F30: 254508576 | G30: 5404 | H30: =D30+F30-J30 -> 300887564 | I30: 0 | J30: 0
