Workbook

Sheet Dashboard
B2: TỔNG TÀI SẢN 2025 | D2: DOANH THU 2025 | F2: LỢI NHUẬN (LỖ) 2025
B3: ='BCĐ Kế Toán'!C11 | D3: ='Kết quả kinh doanh'!C5 | F3: ='Kết quả kinh doanh'!C14

Sheet BCĐ Tài Khoản
A1: BẢNG CÂN ĐỐI TÀI KHOẢN 2025
A3: Số hiệu TK | B3: Tên tài khoản | C3: Đầu năm | E3: Phát sinh | G3: Cuối năm
C4: Nợ | D4: Có | E4: Nợ | F4: Có | G4: Nợ | H4: Có
A5: 111 | B5: Tiền mặt | D5: 0 | H5: 0
A6: 1111 | B6: Tiền Việt Nam | C6: 106031280 | D6: 0 | E6: 23787126489 | F6: 23866025769 | G6: 27132000 | H6: 0
A7: 112 | B7: Tiền gửi Ngân hàng | D7: 0 | H7: 0
A8: 1121 | B8: Tiền Việt Nam | C8: 357350 | D8: 0 | E8: 22488338318 | F8: 22475878318 | G8: 12817350 | H8: 0
A9: 131 | B9: Phải thu của khách hàng | C9: 5835849554 | D9: 0 | E9: 23787126489 | F9: 27244263394 | G9: 2378712649 | H9: 0
A10: 133 | B10: Thuế GTGT được khấu trừ | D10: 0 | G10: 0 | H10: 0
A11: 1331 | B11: Thuế GTGT được khấu trừ của hàng hóa, dịch vụ | D11: 0 | G11: 0 | H11: 0
A12: 152 | B12: Nguyên liệu, vật liệu | C12: 0 | D12: 0 | G12: 0 | H12: 0
A13: 153 | B13: Công cụ, dụng cụ | C13: 0 | D13: 0 | G13: 0 | H13: 0
A14: 1531 | B14: Công cụ, dụng cụ | C14: 0 | D14: 0 | G14: 0 | H14: 0
A15: 156 | B15: Hàng hóa | D15: 0 | H15: 0
A16: 1561 | B16: Giá mua hàng hóa | C16: 20633108385 | D16: 0 | E16: 19151978036 | F16: 2.0762261e+10 | G16: 1.9022825e+10 | H16: 0
A17: 211 | B17: Tài sản cố định hữu hình | D17: 0 | G17: 0 | H17: 0
A18: 2113 | B18: Phương tiện vận tải, truyền dẫn | C18: 2200000000 | D18: 0 | G18: 2200000000 | H18: 0
A19: 214 | B19: Hao mòn tài sản cố định | C19: 0 | D19: 0 | G19: 0
A20: 2141 | B20: Hao mòn TSCĐ hữu hình | G20: 0
A21: 331 | B21: Phải trả cho người bán | D21: 4632756100 | E21: 24986184461 | F21: 20831635858 | H21: 478207497
A22: 333 | B22: Thuế và các khoản phải nộp Nhà nước | D22: 0 | H22: 0
A23: 3331 | B23: Thuế giá trị gia tăng phải nộp | C23: 0 | D23: 0 | E23: 70237166 | F23: 70237166 | H23: 0
A24: 3334 | B24: Thuế thu nhập doanh nghiệp | D24: 0 | E24: 20000000 | G24: 20000000 | H24: 0
A25: 3338 | B25: Thuế bảo vệ môi trường và các loại thuế khác | C25: 0 | D25: 0 | E25: 2000000 | F25: 2000000 | H25: 0
A26: 334 | B26: Phải trả người lao động | C26: 0 | D26: 0 | E26: 0 | F26: 0 | G26: 0 | H26: 0
A27: 3348 | B27: Phải trả người lao động khác | C27: 0 | D27: 0 | G27: 0 | H27: 0
A28: 338 | B28: Phải trả, phải nộp khác | C28: 0 | D28: 0 | F28: 0 | G28: 0 | H28: 0
A29: 3388 | B29: Phải trả, phải nộp khác | D29: 56465573 | E29: 56465573 | G29: 0 | H29: 0
A30: 341 | B30: Vay và nợ thuê tài chính | C30: 0
A31: 3411 | B31: Các khoản đi vay | D31: 34090168080 | E31: 11949137184 | F31: 11185296033 | G31: 0 | H31: 33326326929
A32: 411 | B32: Vốn đầu tư của chủ sở hữu | G32: 0
A33: 4118 | B33: Vốn khác | D33: 3500000000 | G33: 0 | H33: 3500000000
A34: 421 | B34: Lợi nhuận sau thuế chưa phân phối
A35: 4211 | B35: Lợi nhuận sau thuế chưa phân phối năm trước | D35: -13504043184 | E35: 0 | F35: -1.390039e+08 | H35: -1.3643047e+10
A36: 4212 | B36: Lợi nhuận sau thuế chưa phân phối năm nay | H36: 0
A37: 511 | B37: Doanh thu bán hàng và cung cấp dịch vụ | C37: 0 | D37: 0 | G37: 0 | H37: 0
A38: 5111 | B38: Doanh thu bán hàng hóa | C38: 0 | D38: 0 | E38: 21855011663 | F38: 21855011663 | G38: 0 | H38: 0
A39: 515 | B39: Doanh thu hoạt động tài chính | C39: 0 | D39: 0 | G39: 0 | H39: 0
A40: 521 | B40: Các khoản giảm trừ doanh thu | C40: 0 | D40: 0 | E40: 0 | F40: 0 | G40: 0 | H40: 0
A41: 5211 | B41: Chiết khấu thương mại | C41: 0 | D41: 0 | G41: 0 | H41: 0
...

Sheet BCĐ Kế Toán
A1: BẢNG CÂN ĐỐI KẾ TOÁN 2025
A3: CHỈ TIÊU | B3: MÃ SỐ | C3: SỐ CUỐI NĂM
A5: TÀI SẢN (ASSETS)
A6: 1. Tiền và tương đương tiền | B6: 110 | C6: ='BCĐ Tài Khoản'!G6+'BCĐ Tài Khoản'!G8
A7: 2. Phải thu khách hàng | B7: 130 | C7: ='BCĐ Tài Khoản'!G9
A8: 3. Hàng tồn kho | B8: 140 | C8: ='BCĐ Tài Khoản'!G16
A9: 4. Thuế GTGT được khấu trừ (Overpaid) | B9: 150 | C9: ='BCĐ Tài Khoản'!G24
A10: 5. Tài sản cố định | B10: 210 | C10: ='BCĐ Tài Khoản'!G18
A11: TỔNG CỘNG TÀI SẢN | B11: 270 | C11: =SUM(C5:C9)
A13: NGUỒN VỐN (RESOURCES)
A14: 1. Phải trả người bán | B14: 310 | C14: ='BCĐ Tài Khoản'!H21
A15: 2. Vay và nợ tài chính | B15: 320 | C15: ='BCĐ Tài Khoản'!H31
A16: 3. Vốn chủ sở hữu | B16: 410 | C16: ='BCĐ Tài Khoản'!H33
A17: 4. Lợi nhuận chưa phân phối | B17: 420 | C17: ='BCĐ Tài Khoản'!H35 - 'BCĐ Tài Khoản'!G35
A18: TỔNG CỘNG NGUỒN VỐN | B18: 440 | C18: =SUM(C14:C17)

Sheet Kết quả kinh doanh
A3: CHỈ TIÊU | B3: MÃ SỐ | C3: NĂM NAY
A5: 1. Doanh thu bán hàng | C5: ='BCĐ Tài Khoản'!F38
A6: 2. Các khoản giảm trừ | C6: ='BCĐ Tài Khoản'!E41
A7: 3. Doanh thu thuần | C7: =C5-C6
A8: 4. Giá vốn hàng bán | C8: ='BCĐ Tài Khoản'!E42
A9: 5. Lợi nhuận gộp | C9: =C7-C8
A10: 6. Chi phí tài chính | C10: ='BCĐ Tài Khoản'!E44
A11: 7. Chi phí bán hàng | C11: ='BCĐ Tài Khoản'!E47
A12: 8. Chi phí quản lý DN | C12: ='BCĐ Tài Khoản'!E49
A13: 9. Chi phí khác/ Thu nhập khác (Net) | C13: ='BCĐ Tài Khoản'!F52 - 'BCĐ Tài Khoản'!E52
A14: 10. Lợi nhuận trước thuế | C14: =C9 - C10 - C11 - C12 + C13
