Workbook

Sheet xn chỉnh 2023
C1: =SUBTOTAL(109,C4:C8813) -> 40650 | D1: =SUBTOTAL(109,D4:D8813) -> 41057364766 | F1: =SUBTOTAL(109,F4:F8813) -> 40650 | G1: =SUBTOTAL(109,G4:G8813) -> 41057364766 | H1: =SUBTOTAL(109,H4:H8813) -> 39820 | I1: =SUBTOTAL(109,I4:I8813) -> 33017098796 | J1: =SUBTOTAL(109,J4:J8813) -> 1.4563094e+10 | K1: =SUBTOTAL(109,K4:K8813) -> 27556 | L1: =SUBTOTAL(109,L4:L8813) -> 3.1612617e+10 | M1: =SUBTOTAL(109,M4:M8813) -> 52914 | N1: =SUBTOTAL(109,N4:N8813) -> 4.2461847e+10
F2: Đầu Kỳ | H2: Nhập Kho | J2: Xuất Kho | M2: Tồn Kho
A3: Tên Sản Phẩm | B3: DVT | C3: Gốc | F3: Số Lượng | G3: Thành Tiền | H3: Số Lượng | I3: Thành Tiền | J3: Đơn giá Giá Vốn | K3: Số Lượng | L3: Thành Tiền | M3: Số Lượng | N3: Thành Tiền
A4: Thiết bị thu phát vô tuyến RG - EW1200G Pro | B4: Cái | C4: 0 | D4: 0 | F4: 0 | G4: 0 | H4: 11 | I4: 6445453 | J4: =IFERROR((G4+I4)/(F4+H4),0) -> 585950.27 | K4: 1 | L4: =J4*K4 -> 585950.27 | M4: =F4+H4-K4 -> 10 | N4: =G4+I4-L4 -> 5859502.7
A5: MÁY VI TÍNH ĐỂ BÀN (PC) LENOVO ThinkCentre neo 50t Gen 3 i3- 12100(4*3.3)/4GD4/256GSSD/WL/BT/KB/M/nOS/ĐEN( 11SC001LVA) | B5: Cái | C5: 0 | D5: 0 | F5: 0 | G5: 0 | H5: 66 | I5: 565620000 | J5: =IFERROR((G5+I5)/(F5+H5),0) -> 8570000 | K5: 61 | L5: =J5*K5 -> 522770000 | M5: =F5+H5-K5 -> 5 | N5: =G5+I5-L5 -> 42850000
A6: MÁY TÍNH XÁCH TAY (NB) LENOVO V14 G3 IAP i3-1215U/8GD4/256GSSD/14.0FHD/IPS/WL/BT/2C38/NoOS/ĐEN (82TS0060VN) | B6: Cái | C6: 0 | D6: 0 | F6: 0 | G6: 0 | H6: 61 | I6: 572491269 | J6: =IFERROR((G6+I6)/(F6+H6),0) -> 9385102.8 | K6: 39 | L6: =J6*K6 -> 3.6601901e+08 | M6: =F6+H6-K6 -> 22 | N6: =G6+I6-L6 -> 2.0647226e+08
A7: Máy in laser Brother HL-L2321D | B7: Cái | C7: 0 | D7: 0 | F7: 0 | G7: 0 | H7: 290 | I7: 761781620 | J7: =IFERROR((G7+I7)/(F7+H7),0) -> 2626833.2 | K7: 151 | L7: =J7*K7 -> 3.9665181e+08 | M7: =F7+H7-K7 -> 139 | N7: =G7+I7-L7 -> 3.6512981e+08
A8: Ổ cứng máy tính SSD Western WDS240G2G0A,240GB | B8: Cái | C8: 50 | D8: 33229084 | F8: 50 | G8: 33229084 | H8: 0 | I8: 0 | J8: =IFERROR((G8+I8)/(F8+H8),0) -> 664581.68 | K8: 50 | L8: =J8*K8 -> 33229084 | M8: =F8+H8-K8 -> 0 | N8: =G8+I8-L8 -> 0
A9: Camera quan sát CS-C6N (1080P) | B9: Cái | C9: 71 | D9: 30048522 | F9: 71 | G9: 30048522 | H9: 185 | I9: 78295445 | J9: =IFERROR((G9+I9)/(F9+H9),0) -> 423218.62 | K9: 256 | L9: =J9*K9 -> 108343967 | M9: =F9+H9-K9 -> 0 | N9: =G9+I9-L9 -> 0
A10: Máy tính xách tay MSI Katana GF66 12UCK-815VN/Alder Lake i5-12450H/512GB SSD/DDR4 8GB (3200MHz)/RTX3050 GDDR6 4GB/15.6" FHD/WIN11/màu đen/ ba lô | B10: Cái | C10: 0 | D10: 0 | F10: 0 | G10: 0 | H10: 2 | I10: 39163636 | J10: =IFERROR((G10+I10)/(F10+H10),0) -> 19581818 | K10: 2 | L10: =J10*K10 -> 39163636 | M10: =F10+H10-K10 -> 0 | N10: =G10+I10-L10 -> 0
A11: Thẻ nhớ 32GB Micro SDHC Exceria Plus UHS-I C10 U3 V30 A1 98MB/65MB/s Kioxia ( Có Adapter) | B11: Cái | C11: 50 | D11: 9545454 | F11: 50 | G11: 9545454 | H11: 0 | I11: 0 | J11: =IFERROR((G11+I11)/(F11+H11),0) -> 190909.08 | K11: 40 | L11: =J11*K11 -> 7636363.2 | M11: =F11+H11-K11 -> 10 | N11: =G11+I11-L11 -> 1909090.8
A12: Máy tính bàn Lenovo ThinkCentre Neo 50t Gen 4 - Intel Corei5-13400 (4.60 GHz) - 8GB RAM - 512GB SSD - Wifi & BL -UHD Graphics 730 - NOS - 1YR Premier NBD,P/n 12JB001HVA | B12: Bộ | C12: 0 | D12: 0 | F12: 0 | G12: 0 | H12: 25 | I12: 269795450 | J12: =IFERROR((G12+I12)/(F12+H12),0) -> 10791818 | K12: 21 | L12: =J12*K12 -> 226628178 | M12: =F12+H12-K12 -> 4 | N12: =G12+I12-L12 -> 43167272
A13: Máy tính xách tay AsusA415EA - EBI750W (i3-1125G4/8GB/256GB (90NB0RLB-M32730) | B13: Bộ | C13: 2 | D13: 23547273 | F13: 2 | G13: 23547273 | H13: 0 | I13: 0 | J13: =IFERROR((G13+I13)/(F13+H13),0) -> 11773636 | K13: 2 | L13: =J13*K13 -> 23547273 | M13: =F13+H13-K13 -> 0 | N13: =G13+I13-L13 -> 0
A14: Máy tính xách tay MSI Katana GF66 12UCK-699VN/Alder Lake i5-12450H/512GB SSD/DDR4 8GB (3200MHz)/RTX3050 GDDR6 4GB/15.6" FHD/WIN 11/màu đen/ba lô | B14: Cái | C14: 0 | D14: 0 | F14: 0 | G14: 0 | H14: 2 | I14: 38254544 | J14: =IFERROR((G14+I14)/(F14+H14),0) -> 19127272 | K14: 1 | L14: =J14*K14 -> 19127272 | M14: =F14+H14-K14 -> 1 | N14: =G14+I14-L14 -> 19127272
A15: Máy tính bàn Lenovo ThinkCentre M70s Gen 3 i3-12100 ( 4.3 GHZ) - 8GB RAM - 256GB SSD - Wireless & Bluetooth - None -1Yr; P/n 11TC000QVA | B15: Bộ | C15: 0 | D15: 0 | F15: 0 | G15: 0 | H15: 30 | I15: 247363620 | J15: =IFERROR((G15+I15)/(F15+H15),0) -> 8245454 | K15: 11 | L15: =J15*K15 -> 90699994 | M15: =F15+H15-K15 -> 19 | N15: =G15+I15-L15 -> 156663626
... A169: Chuột gaming có dây Logitech G203, màu tím lilac (910-005853) | B169: Cái | C169: 0 | D169: 0 | F169: 0 | G169: 0 | H169: 5 | I169: 1636360 | J169: =IFERROR((G169+I169)/(F169+H169),0) -> 327272 | K169: 0 | L169: =J169*K169 -> 0 | M169: =F169+H169-K169 -> 5 | N169: =G169+I169-L169 -> 1636360
A170: Bàn phím Logitech K120 | B170: Cái | C170: 83 | D170: 12131794 | F170: 83 | G170: 12131794 | H170: 150 | I170: 17272650 | J170: =IFERROR((G170+I170)/(F170+H170),0) -> 126199.33 | K170: 83 | L170: 12131794 | M170: =F170+H170-K170 -> 150 | N170: =G170+I170-L170 -> 17272650
A171: Tai nghe USB Logitech H540 (981-000482) | B171: Cái | C171: 0 | D171: 0 | F171: 0 | G171: 0 | H171: 1 | I171: 681818 | J171: =IFERROR((G171+I171)/(F171+H171),0) -> 681818 | K171: 0 | L171: =J171*K171 -> 0 | M171: =F171+H171-K171 -> 1 | N171: =G171+I171-L171 -> 681818
A172: Tai nghe PC Logitech Stereo H151, màu đen - BLACK (981-000587) | B172: Cái | C172: 0 | D172: 0 | F172: 0 | G172: 0 | H172: 14 | I172: 3081814 | J172: =IFERROR((G172+I172)/(F172+H172),0) -> 220129.57 | K172: 0 | L172: =J172*K172 -> 0 | M172: =F172+H172-K172 -> 14 | N172: =G172+I172-L172 -> 3081814
A173: Tai nghe PC Logitech H110 (981-000459) | B173: Cái | C173: 0 | D173: 0 | F173: 0 | G173: 0 | H173: 16 | I173: 2109088 | J173: =IFERROR((G173+I173)/(F173+H173),0) -> 131818 | K173: 0 | L173: =J173*K173 -> 0 | M173: =F173+H173-K173 -> 16 | N173: =G173+I173-L173 -> 2109088
A174: Mực MP3054 | B174: Hộp | C174: 0 | D174: 0 | F174: 0 | G174: 0 | H174: 1 | I174: 400000 | J174: =IFERROR((G174+I174)/(F174+H174),0) -> 400000 | K174: 0 | L174: =J174*K174 -> 0 | M174: =F174+H174-K174 -> 1 | N174: =G174+I174-L174 -> 400000
A175: Máy tính xách tay MSI Cyborg 15 A12VE-412VN/i5-12450H/512GB SSD/DDR5 8GB/RTX 4050,GDDR6 6GB/15.6" FHD 144Hz/Win11/màu đen,ba lô | B175: Cái | C175: 0 | D175: 0 | F175: 0 | G175: 0 | H175: 1 | I175: 20445455 | J175: =IFERROR((G175+I175)/(F175+H175),0) -> 20445455 | K175: 0 | L175: =J175*K175 -> 0 | M175: =F175+H175-K175 -> 1 | N175: =G175+I175-L175 -> 20445455
A176: Chuột Gaming MSI M99 (BTS 2022) | B176: Cái | C176: 0 | D176: 0 | F176: 0 | G176: 0 | H176: 5 | I176: 0 | J176: =IFERROR((G176+I176)/(F176+H176),0) -> 0 | K176: 0 | L176: =J176*K176 -> 0 | M176: =F176+H176-K176 -> 5 | N176: =G176+I176-L176 -> 0
A177: Túi rút Kingston Fury | B177: Cái | C177: 0 | D177: 0 | F177: 0 | G177: 0 | H177: 2 | I177: 0 | J177: =IFERROR((G177+I177)/(F177+H177),0) -> 0 | K177: 0 | L177: =J177*K177 -> 0 | M177: =F177+H177-K177 -> 2 | N177: =G177+I177-L177 -> 0
A178: Đầu máy in kim Epson LQ 310 | B178: Bộ | C178: 0 | D178: 0 | F178: 0 | G178: 0 | H178: 3 | I178: 5100000 | J178: =IFERROR((G178+I178)/(F178+H178),0) -> 1700000 | K178: 3 | L178: =J178*K178 -> 5100000 | M178: =F178+H178-K178 -> 0 | N178: =G178+I178-L178 -> 0
A179: Camera DH - HAC - HFW 1200DP - S5 | B179: Cái | C179: 0 | D179: 0 | F179: 0 | G179: 0 | H179: 2 | I179: 1000000 | J179: =IFERROR((G179+I179)/(F179+H179),0) -> 500000 | K179: 0 | L179: =J179*K179 -> 0 | M179: =F179+H179-K179 -> 2 | N179: =G179+I179-L179 -> 1000000
A180: Thiết bị truyền hình ảnh Webcam Logitech HD C270 (960-000584) | B180: Cái | C180: 0 | D180: 0 | F180: 0 | G180: 0 | H180: 13 | I180: 4136353 | J180: =IFERROR((G180+I180)/(F180+H180),0) -> 318181 | K180: 0 | L180: =J180*K180 -> 0 | M180: =F180+H180-K180 -> 13 | N180: =G180+I180-L180 -> 4136353
A181: Bộ bàn phím + chuột không dây Logitech MK220 (920-003235) | B181: Bộ | C181: 0 | D181: 0 | F181: 0 | G181: 0 | H181: 8 | I181: 2554543 | J181: =IFERROR((G181+I181)/(F181+H181),0) -> 319317.88 | K181: 0 | L181: =J181*K181 -> 0 | M181: =F181+H181-K181 -> 8 | N181: =G181+I181-L181 -> 2554543
A182: Bộ bàn phím + chuột không dây Logitech MK240 Nano, màu đen (920-008202) | B182: Bộ | C182: 0 | D182: 0 | F182: 0 | G182: 0 | H182: 7 | I182: 2672726 | J182: =IFERROR((G182+I182)/(F182+H182),0) -> 381818 | K182: 0 | L182: =J182*K182 -> 0 | M182: =F182+H182-K182 -> 7 | N182: =G182+I182-L182 -> 2672726
... A2274: Monitor - E2223HN (Theo Hợp đồng kinh tế số 01/HĐKT-XDBTN-HV ký ngày 18 tháng 12 năm 2023) | B2274: Bộ | C2274: 30 | D2274: 456000000 | F2274: 30 | G2274: 456000000 | H2274: 0 | I2274: 0 | J2274: =IFERROR((G2274+I2274)/(F2274+H2274),0) -> 15200000 | K2274: 30 | L2274: =J2274*K2274 -> 456000000 | M2274: =F2274+H2274-K2274 -> 0 | N2274: =G2274+I2274-L2274 -> 0
C2275: =SUM(C4:C2274) -> 20325 | D2275: =SUM(D4:D2274) -> 20528682383 | F2275: =SUM(F4:F2274) -> 20325 | G2275: =SUM(G4:G2274) -> 20528682383 | H2275: =SUM(H4:H2274) -> 19910 | I2275: =SUM(I4:I2274) -> 16508549398 | J2275: =SUM(J4:J2274) -> 7.281547e+09 | K2275: =SUM(K4:K2274) -> 13778 | L2275: =SUM(L4:L2274) -> 1.5806308e+10 | M2275: =SUM(M4:M2274) -> 26457 | N2275: =SUM(N4:N2274) -> 2.1230923e+10

Sheet 2023
C1: =SUBTOTAL(109,C4:C8981) -> 40650 | D1: =SUBTOTAL(109,D4:D8981) -> 41057364766 | F1: =SUBTOTAL(109,F4:F8981) -> 40650 | G1: =SUBTOTAL(109,G4:G8981) -> 41057364766 | H1: =SUBTOTAL(109,H4:H8981) -> 40624 | I1: =SUBTOTAL(109,I4:I8981) -> 33111107234 | J1: =SUBTOTAL(109,J4:J8981) -> 1.4620099e+10 | K1: =SUBTOTAL(109,K4:K8981) -> 27560 | L1: =SUBTOTAL(109,L4:L8981) -> 3.1612617e+10 | M1: =SUBTOTAL(109,M4:M8981) -> 53714 | N1: =SUBTOTAL(109,N4:N8981) -> 4.2555855e+10
F2: Đầu Kỳ | H2: Nhập Kho | J2: Xuất Kho | M2: Tồn Kho
A3: Tên Sản Phẩm | B3: DVT | C3: Gốc | F3: Số Lượng | G3: Thành Tiền | H3: Số Lượng | I3: Thành Tiền | J3: Đơn giá Giá Vốn | K3: Số Lượng | L3: Thành Tiền | M3: Số Lượng | N3: Thành Tiền
A4: Thiết bị thu phát vô tuyến RG - EW1200G Pro | B4: Cái | C4: 0 | D4: 0 | F4: 0 | G4: 0 | H4: 11 | I4: 6445453 | J4: =IFERROR((G4+I4)/(F4+H4),0) -> 585950.27 | K4: 1 | L4: =J4*K4 -> 585950.27 | M4: =F4+H4-K4 -> 10 | N4: =G4+I4-L4 -> 5859502.7
A5: MÁY VI TÍNH ĐỂ BÀN (PC) LENOVO ThinkCentre neo 50t Gen 3 i3- 12100(4*3.3)/4GD4/256GSSD/WL/BT/KB/M/nOS/ĐEN( 11SC001LVA) | B5: Cái | C5: 0 | D5: 0 | F5: 0 | G5: 0 | H5: 66 | I5: 565620000 | J5: =IFERROR((G5+I5)/(F5+H5),0) -> 8570000 | K5: 61 | L5: =J5*K5 -> 522770000 | M5: =F5+H5-K5 -> 5 | N5: =G5+I5-L5 -> 42850000
A6: MÁY TÍNH XÁCH TAY (NB) LENOVO V14 G3 IAP i3-1215U/8GD4/256GSSD/14.0FHD/IPS/WL/BT/2C38/NoOS/ĐEN (82TS0060VN) | B6: Cái | C6: 0 | D6: 0 | F6: 0 | G6: 0 | H6: 61 | I6: 572491269 | J6: =IFERROR((G6+I6)/(F6+H6),0) -> 9385102.8 | K6: 39 | L6: =J6*K6 -> 3.6601901e+08 | M6: =F6+H6-K6 -> 22 | N6: =G6+I6-L6 -> 2.0647226e+08
A7: Máy in laser Brother HL-L2321D | B7: Cái | C7: 0 | D7: 0 | F7: 0 | G7: 0 | H7: 290 | I7: 761781620 | J7: =IFERROR((G7+I7)/(F7+H7),0) -> 2626833.2 | K7: 151 | L7: =J7*K7 -> 3.9665181e+08 | M7: =F7+H7-K7 -> 139 | N7: =G7+I7-L7 -> 3.6512981e+08
A8: Ổ cứng máy tính SSD Western WDS240G2G0A,240GB | B8: Cái | C8: 50 | D8: 33229084 | F8: 50 | G8: 33229084 | H8: 0 | I8: 0 | J8: =IFERROR((G8+I8)/(F8+H8),0) -> 664581.68 | K8: 50 | L8: =J8*K8 -> 33229084 | M8: =F8+H8-K8 -> 0 | N8: =G8+I8-L8 -> 0
A9: Camera quan sát CS-C6N (1080P) | B9: Cái | C9: 71 | D9: 30048522 | F9: 71 | G9: 30048522 | H9: 185 | I9: 78295445 | J9: =IFERROR((G9+I9)/(F9+H9),0) -> 423218.62 | K9: 256 | L9: =J9*K9 -> 108343967 | M9: =F9+H9-K9 -> 0 | N9: =G9+I9-L9 -> 0
A10: Máy tính xách tay MSI Katana GF66 12UCK-815VN/Alder Lake i5-12450H/512GB SSD/DDR4 8GB (3200MHz)/RTX3050 GDDR6 4GB/15.6" FHD/WIN11/màu đen/ ba lô | B10: Cái | C10: 0 | D10: 0 | F10: 0 | G10: 0 | H10: 2 | I10: 39163636 | J10: =IFERROR((G10+I10)/(F10+H10),0) -> 19581818 | K10: 2 | L10: =J10*K10 -> 39163636 | M10: =F10+H10-K10 -> 0 | N10: =G10+I10-L10 -> 0
A11: Thẻ nhớ 32GB Micro SDHC Exceria Plus UHS-I C10 U3 V30 A1 98MB/65MB/s Kioxia ( Có Adapter) | B11: Cái | C11: 50 | D11: 9545454 | F11: 50 | G11: 9545454 | H11: 0 | I11: 0 | J11: =IFERROR((G11+I11)/(F11+H11),0) -> 190909.08 | K11: 40 | L11: =J11*K11 -> 7636363.2 | M11: =F11+H11-K11 -> 10 | N11: =G11+I11-L11 -> 1909090.8
A12: Máy tính bàn Lenovo ThinkCentre Neo 50t Gen 4 - Intel Corei5-13400 (4.60 GHz) - 8GB RAM - 512GB SSD - Wifi & BL -UHD Graphics 730 - NOS - 1YR Premier NBD,P/n 12JB001HVA | B12: Bộ | C12: 0 | D12: 0 | F12: 0 | G12: 0 | H12: 25 | I12: 269795450 | J12: =IFERROR((G12+I12)/(F12+H12),0) -> 10791818 | K12: 21 | L12: =J12*K12 -> 226628178 | M12: =F12+H12-K12 -> 4 | N12: =G12+I12-L12 -> 43167272
A13: Máy tính xách tay AsusA415EA - EBI750W (i3-1125G4/8GB/256GB (90NB0RLB-M32730) | B13: Bộ | C13: 2 | D13: 23547273 | F13: 2 | G13: 23547273 | H13: 0 | I13: 0 | J13: =IFERROR((G13+I13)/(F13+H13),0) -> 11773636 | K13: 2 | L13: =J13*K13 -> 23547273 | M13: =F13+H13-K13 -> 0 | N13: =G13+I13-L13 -> 0
A14: Máy tính xách tay MSI Katana GF66 12UCK-699VN/Alder Lake i5-12450H/512GB SSD/DDR4 8GB (3200MHz)/RTX3050 GDDR6 4GB/15.6" FHD/WIN 11/màu đen/ba lô | B14: Cái | C14: 0 | D14: 0 | F14: 0 | G14: 0 | H14: 2 | I14: 38254544 | J14: =IFERROR((G14+I14)/(F14+H14),0) -> 19127272 | K14: 1 | L14: =J14*K14 -> 19127272 | M14: =F14+H14-K14 -> 1 | N14: =G14+I14-L14 -> 19127272
A15: Máy tính bàn Lenovo ThinkCentre M70s Gen 3 i3-12100 ( 4.3 GHZ) - 8GB RAM - 256GB SSD - Wireless & Bluetooth - None -1Yr; P/n 11TC000QVA | B15: Bộ | C15: 0 | D15: 0 | F15: 0 | G15: 0 | H15: 30 | I15: 247363620 | J15: =IFERROR((G15+I15)/(F15+H15),0) -> 8245454 | K15: 11 | L15: =J15*K15 -> 90699994 | M15: =F15+H15-K15 -> 19 | N15: =G15+I15-L15 -> 156663626
... A196: Chuột gaming có dây Logitech G203, màu tím lilac (910-005853) | B196: Cái | C196: 0 | D196: 0 | F196: 0 | G196: 0 | H196: 5 | I196: 1636360 | J196: =IFERROR((G196+I196)/(F196+H196),0) -> 327272 | K196: 0 | L196: =J196*K196 -> 0 | M196: =F196+H196-K196 -> 5 | N196: =G196+I196-L196 -> 1636360
A197: Bàn phím Logitech K120 | B197: Cái | C197: 83 | D197: 12131794 | F197: 83 | G197: 12131794 | H197: 150 | I197: 17272650 | J197: =IFERROR((G197+I197)/(F197+H197),0) -> 126199.33 | K197: 83 | L197: 12131794 | M197: =F197+H197-K197 -> 150 | N197: =G197+I197-L197 -> 17272650
A198: Tai nghe USB Logitech H540 (981-000482) | B198: Cái | C198: 0 | D198: 0 | F198: 0 | G198: 0 | H198: 1 | I198: 681818 | J198: =IFERROR((G198+I198)/(F198+H198),0) -> 681818 | K198: 0 | L198: =J198*K198 -> 0 | M198: =F198+H198-K198 -> 1 | N198: =G198+I198-L198 -> 681818
A199: Tai nghe PC Logitech Stereo H151, màu đen - BLACK (981-000587) | B199: Cái | C199: 0 | D199: 0 | F199: 0 | G199: 0 | H199: 14 | I199: 3081814 | J199: =IFERROR((G199+I199)/(F199+H199),0) -> 220129.57 | K199: 0 | L199: =J199*K199 -> 0 | M199: =F199+H199-K199 -> 14 | N199: =G199+I199-L199 -> 3081814
A200: Tai nghe PC Logitech H110 (981-000459) | B200: Cái | C200: 0 | D200: 0 | F200: 0 | G200: 0 | H200: 16 | I200: 2109088 | J200: =IFERROR((G200+I200)/(F200+H200),0) -> 131818 | K200: 0 | L200: =J200*K200 -> 0 | M200: =F200+H200-K200 -> 16 | N200: =G200+I200-L200 -> 2109088
A201: Cước dịch vụ Viễn thông-Công nghệ thông tin tháng 05 năm 2023 | B201: Tháng | C201: 0 | D201: 0 | F201: 0 | G201: 0 | H201: 9 | I201: 0 | J201: =IFERROR((G201+I201)/(F201+H201),0) -> 0 | K201: 0 | L201: =J201*K201 -> 0 | M201: =F201+H201-K201 -> 9 | N201: =G201+I201-L201 -> 0
A202: Mực MP3054 | B202: Hộp | C202: 0 | D202: 0 | F202: 0 | G202: 0 | H202: 1 | I202: 400000 | J202: =IFERROR((G202+I202)/(F202+H202),0) -> 400000 | K202: 0 | L202: =J202*K202 -> 0 | M202: =F202+H202-K202 -> 1 | N202: =G202+I202-L202 -> 400000
A203: Máy tính xách tay MSI Cyborg 15 A12VE-412VN/i5-12450H/512GB SSD/DDR5 8GB/RTX 4050,GDDR6 6GB/15.6" FHD 144Hz/Win11/màu đen,ba lô | B203: Cái | C203: 0 | D203: 0 | F203: 0 | G203: 0 | H203: 1 | I203: 20445455 | J203: =IFERROR((G203+I203)/(F203+H203),0) -> 20445455 | K203: 0 | L203: =J203*K203 -> 0 | M203: =F203+H203-K203 -> 1 | N203: =G203+I203-L203 -> 20445455
A204: Chuột Gaming MSI M99 (BTS 2022) | B204: Cái | C204: 0 | D204: 0 | F204: 0 | G204: 0 | H204: 5 | I204: 0 | J204: =IFERROR((G204+I204)/(F204+H204),0) -> 0 | K204: 0 | L204: =J204*K204 -> 0 | M204: =F204+H204-K204 -> 5 | N204: =G204+I204-L204 -> 0
A205: Túi rút Kingston Fury | B205: Cái | C205: 0 | D205: 0 | F205: 0 | G205: 0 | H205: 2 | I205: 0 | J205: =IFERROR((G205+I205)/(F205+H205),0) -> 0 | K205: 0 | L205: =J205*K205 -> 0 | M205: =F205+H205-K205 -> 2 | N205: =G205+I205-L205 -> 0
A206: Đầu máy in kim Epson LQ 310 | B206: Bộ | C206: 0 | D206: 0 | F206: 0 | G206: 0 | H206: 3 | I206: 5100000 | J206: =IFERROR((G206+I206)/(F206+H206),0) -> 1700000 | K206: 3 | L206: =J206*K206 -> 5100000 | M206: =F206+H206-K206 -> 0 | N206: =G206+I206-L206 -> 0
A207: Camera DH - HAC - HFW 1200DP - S5 | B207: Cái | C207: 0 | D207: 0 | F207: 0 | G207: 0 | H207: 2 | I207: 1000000 | J207: =IFERROR((G207+I207)/(F207+H207),0) -> 500000 | K207: 0 | L207: =J207*K207 -> 0 | M207: =F207+H207-K207 -> 2 | N207: =G207+I207-L207 -> 1000000
A208: Thiết bị truyền hình ảnh Webcam Logitech HD C270 (960-000584) | B208: Cái | C208: 0 | D208: 0 | F208: 0 | G208: 0 | H208: 13 | I208: 4136353 | J208: =IFERROR((G208+I208)/(F208+H208),0) -> 318181 | K208: 0 | L208: =J208*K208 -> 0 | M208: =F208+H208-K208 -> 13 | N208: =G208+I208-L208 -> 4136353
A209: Bộ bàn phím + chuột không dây Logitech MK220 (920-003235) | B209: Bộ | C209: 0 | D209: 0 | F209: 0 | G209: 0 | H209: 8 | I209: 2554543 | J209: =IFERROR((G209+I209)/(F209+H209),0) -> 319317.88 | K209: 0 | L209: =J209*K209 -> 0 | M209: =F209+H209-K209 -> 8 | N209: =G209+I209-L209 -> 2554543
... A2442: Monitor - E2223HN (Theo Hợp đồng kinh tế số 01/HĐKT-XDBTN-HV ký ngày 18 tháng 12 năm 2023) | B2442: Bộ | C2442: 30 | D2442: 456000000 | F2442: 30 | G2442: 456000000 | H2442: 0 | I2442: 0 | J2442: =IFERROR((G2442+I2442)/(F2442+H2442),0) -> 15200000 | K2442: 30 | L2442: =J2442*K2442 -> 456000000 | M2442: =F2442+H2442-K2442 -> 0 | N2442: =G2442+I2442-L2442 -> 0
C2443: =SUM(C4:C2442) -> 20325 | D2443: =SUM(D4:D2442) -> 20528682383 | F2443: =SUM(F4:F2442) -> 20325 | G2443: =SUM(G4:G2442) -> 20528682383 | H2443: =SUM(H4:H2442) -> 20312 | I2443: =SUM(I4:I2442) -> 16555553617 | J2443: =SUM(J4:J2442) -> 7.3100494e+09 | K2443: =SUM(K4:K2442) -> 13780 | L2443: =SUM(L4:L2442) -> 1.5806308e+10 | M2443: =SUM(M4:M2442) -> 26857 | N2443: =SUM(N4:N2442) -> 2.1277928e+10

Sheet Sheet2
A3: Bàn phím Logitech K120 | B3: Cái | C3: 0 | D3: 0 | E3: 150 | F3: 150 | G3: 17272650 | H3: 0 | I3: 0 | J3: 115151 | K3: 394 | L3: 49500035 | M3: 45369494 | N3: -244 | O3: -28096844
A4: Bộ máy vi tính | B4: Bộ | C4: 0 | D4: 0 | E4: 0 | F4: 0 | G4: 0 | H4: 0 | I4: 0 | J4: 0 | K4: 213 | L4: 2051237247 | M4: 0 | N4: -213 | O4: 0
A5: Chuột vi tính có dây Rapoo N120 | B5: Cái | C5: 0 | D5: 0 | E5: 0 | F5: 0 | G5: 0 | H5: 0 | I5: 0 | J5: 0 | K5: 209 | L5: 6270000 | M5: 0 | N5: -209 | O5: 0
A6: Chuột máy tính Dell MS116 | B6: Cái | C6: 0 | D6: 0 | E6: 0 | F6: 0 | G6: 0 | H6: 0 | I6: 0 | J6: 0 | K6: 131 | L6: 11936360 | M6: 0 | N6: -131 | O6: 0
A7: Camera quan sát CS-C6N (1080P) | B7: Cái | C7: 0 | D7: 0 | E7: 0 | F7: 0 | G7: 0 | H7: 90 | I7: 34709090 | J7: 385656.56 | K7: 218 | L7: 68940007 | M7: 84073129 | N7: -128 | O7: -49364039
A8: Bộ Nhớ Trong Kingston 4GB D4-2400U17 (KVR24N17S6/4) | B8: Cái | C8: 0 | D8: 0 | E8: 0 | F8: 0 | G8: 0 | H8: 0 | I8: 0 | J8: 0 | K8: 115 | L8: 26136395 | M8: 0 | N8: -115 | O8: 0
A9: Máy in laser Canon LBP 2900 | B9: cái | C9: 0 | D9: 0 | E9: 109 | F9: 109 | G9: 3.8275779e+08 | H9: 7 | I9: 26627272 | J9: 3529181.5 | K9: 226 | L9: 787963655 | M9: 7.9759503e+08 | N9: -110 | O9: -3.8820997e+08
A10: BÀN PHÍM DELL MULTIMEDIA KB216 | B10: Cái | C10: 0 | D10: 0 | E10: 0 | F10: 0 | G10: 0 | H10: 130 | I10: 16681840 | J10: 128321.85 | K10: 239 | L10: 34131835 | M10: 30668921 | N10: -109 | O10: -13987081
A11: Bộ Nhớ Ngoài Sandisk 16G SDCZ50-016G-B35,USB,Cruzer | B11: Cái | C11: 0 | D11: 0 | E11: 0 | F11: 0 | G11: 0 | H11: 0 | I11: 0 | J11: 0 | K11: 100 | L11: 5454500 | M11: 0 | N11: -100 | O11: 0
A12: Nguồn Jetek Model Y600T | B12: Cái | C12: 0 | D12: 0 | E12: 0 | F12: 0 | G12: 0 | H12: 0 | I12: 0 | J12: 0 | K12: 100 | L12: 18000000 | M12: 0 | N12: -100 | O12: 0
A13: Bảng mạch chính Asus PRIME H510M-K | B13: Cái | C13: 0 | D13: 0 | E13: 0 | F13: 0 | G13: 0 | H13: 10 | I13: 13545460 | J13: 1354546 | K13: 108 | L13: 142331819 | M13: 146290968 | N13: -98 | O13: -132745508
A14: Bộ định tuyến TP-Link 300M,2.4GHz-TL-WR840N | B14: Cái | C14: 0 | D14: 0 | E14: 0 | F14: 0 | G14: 0 | H14: 0 | I14: 0 | J14: 0 | K14: 95 | L14: 15545420 | M14: 0 | N14: -95 | O14: 0
... A472: Máy tính xách tay Dell Inspiron15 3520, i5-1235U, 16GB,512GB SSD, Intel Iris XeGraphics, 15.6" FHD, 3C 41Wh,ac+BT, OfficeHS21, McAfee LS,FP, KYHD, Win 11 Home, Đen(Black), 1Y WTY-(71045026) | B472: Chiếc | C472: 0 | D472: 0 | E472: 0 | F472: 0 | G472: 0 | H472: 0 | I472: 0 | J472: 0 | K472: 1 | L472: 13990909 | M472: 0 | N472: -1 | O472: 0
L473: =SUM(L3:L472) -> 8268525537

Sheet Sheet1
A2: Màn hình vi tính DELL LCD-E2423H-23.8-WHD-3Y | B2: Bộ | C2: 4 | D2: 10090908 | E2: 0 | F2: 4 | G2: 10090908 | H2: 2 | I2: 4336364 | J2: 2404545.3 | K2: 0 | L2: 0 | M2: 0 | N2: 6 | O2: 14427272
A3: Mực MP 3054/3554/2554 | B3: Hộp | C3: 0 | D3: 0 | E3: 0 | F3: 0 | G3: 0 | H3: 3 | I3: 1300000 | J3: 433333.33 | K3: 3 | L3: 2045454 | M3: 1300000 | N3: 0 | O3: 0
A4: Chuột vi tính Rapoo M20 | B4: Cái | C4: 0 | D4: 0 | E4: 0 | F4: 0 | G4: 0 | H4: 0 | I4: 0 | J4: 0 | K4: 314 | L4: 34900891 | M4: 0 | N4: -314 | O4: 0
A5: Mực T2323 | B5: Hộp | C5: 0 | D5: 0 | E5: 0 | F5: 0 | G5: 0 | H5: 3 | I5: 1500000 | J5: 500000 | K5: 2 | L5: 1772727 | M5: 1000000 | N5: 1 | O5: 500000
A6: Hộp mực Prospect CF276A/CRG057 | B6: Hộp | C6: 0 | D6: 0 | E6: 0 | F6: 0 | G6: 0 | H6: 1 | I6: 163636 | J6: 163636 | K6: 1 | L6: 436364 | M6: 163636 | N6: 0 | O6: 0
A7: Hộp mực (Cartridge) đã có mực in dùng cho máy in Laser loại PTB - T420 , hiệu POLYTONER | B7: Hộp | C7: 0 | D7: 0 | E7: 0 | F7: 0 | G7: 0 | H7: 1 | I7: 181818 | J7: 181818 | K7: 0 | L7: 0 | M7: 0 | N7: 1 | O7: 181818
A8: Mực TN 118 | B8: Hộp | C8: 0 | D8: 0 | E8: 0 | F8: 0 | G8: 0 | H8: 1 | I8: 250000 | J8: 250000 | K8: 0 | L8: 0 | M8: 0 | N8: 1 | O8: 250000
A9: Mực T2309 | B9: Hộp | C9: 3 | D9: 1125000 | E9: 0 | F9: 3 | G9: 1125000 | H9: 5 | I9: 1963636 | J9: 386079.5 | K9: 5 | L9: 3390908 | M9: 1930397.5 | N9: 3 | O9: 1158238.5
A10: Ruy băng LQ310 (N653BK) | B10: Cái | C10: 5 | D10: 240740 | E10: 0 | F10: 5 | G10: 240740 | H10: 5 | I10: 240740 | J10: 48148 | K10: 0 | L10: 0 | M10: 0 | N10: 10 | O10: 481480
A11: Mực photo (DP-5570) | B11: Gói | C11: 0 | D11: 0 | E11: 0 | F11: 0 | G11: 0 | H11: 3 | I11: 750000 | J11: 250000 | K11: 3 | L11: 1409090 | M11: 750000 | N11: 0 | O11: 0
A12: Thiết bị chuyển mạch MS106LP , hiệu MERCUSYS | B12: Cái | C12: 0 | D12: 0 | E12: 0 | F12: 0 | G12: 0 | H12: 2 | I12: 590910 | J12: 295455 | K12: 0 | L12: 0 | M12: 0 | N12: 2 | O12: 590910
A13: Bản quyền phần mềm Kaspersky dùng cho máy tính KES Premium SEA 1-Dvc 1Y BsRP (KL10474UAFS) | B13: Cái | C13: 0 | D13: 0 | E13: 0 | F13: 0 | G13: 0 | H13: 60 | I13: 19500000 | J13: 325000 | K13: 60 | L13: 25200000 | M13: 19500000 | N13: 0 | O13: 0
... A2075: MÁY TÍNH XÁCH TAY (NB) LENOVO V14 G3 IAP i3-1215U/8GD4/256GSSD/14.0FHD/IPS/WL/BT/2C38/NoOS/ĐEN (82TS0060VN) | B2075: Cái | C2075: 22 | D2075: 206472261 | E2075: 0 | F2075: 22 | G2075: 2.0647226e+08 | H2075: 0 | I2075: 0 | J2075: 9385102.8 | K2075: 0 | L2075: 0 | M2075: 0 | N2075: 22 | O2075: 2.0647226e+08
A2076: Máy tính xách tay MSI Katana GF66 12UCK-699VN/Alder Lake i5-12450H/512GB SSD/DDR4 8GB (3200MHz)/RTX3050 GDDR6 4GB/15.6" FHD/WIN 11/màu đen/ba lô | B2076: Cái | C2076: 1 | D2076: 19127272 | F2076: 1 | G2076: 19127272 | H2076: 0 | I2076: 0 | J2076: 19127272 | K2076: 0 | L2076: 0 | M2076: 0 | N2076: 1 | O2076: 19127272
A2077: Máy tính bàn Lenovo ThinkCentre M70s Gen 3 i3-12100 ( 4.3 GHZ) - 8GB RAM - 256GB SSD - Wireless & Bluetooth - None -1Yr; P/n 11TC000QVA | B2077: Bộ | C2077: 19 | D2077: 156663626 | F2077: 19 | G2077: 156663626 | H2077: 0 | I2077: 0 | J2077: 8245454 | K2077: 0 | L2077: 0 | M2077: 0 | N2077: 19 | O2077: 156663626
A2078: Máy tính xách tay Lenovo V15 G4 IRU - Intel Core i3-1315U (4.50 GHz) - 8GB RAM - 512GB SSD - WF+BL - 15.6FHD 60Hz - NOS - 2YR Premium NBD,P/n 83A10007VN | B2078: Chiếc | C2078: 3 | D2078: 30000000 | F2078: 3 | G2078: 30000000 | H2078: 0 | I2078: 0 | J2078: 10000000 | K2078: 0 | L2078: 0 | M2078: 0 | N2078: 3 | O2078: 30000000
A2079: Máy tính xách tay MSI GF63 Thin11SC-664VN (i5-11400H; 8GB;512GB SSD; GTX 1650/4GB; 15.6"FHD 144Hz; Win11; Đen) | B2079: Bộ | C2079: 1 | D2079: 15545454 | F2079: 1 | G2079: 15545454 | H2079: 0 | I2079: 0 | J2079: 15545454 | K2079: 0 | L2079: 0 | M2079: 0 | N2079: 1 | O2079: 15545454
A2080: Màn hình máy tính Lenovo H20215FE0 - "E22-28 (H20215FE0) 21.5 inch Monitor-HDMI, Linecord, 3YR WTYWarrantyCode: 3years limited", P/N:62B9MAR4WW | B2080: Chiếc | C2080: 103 | D2080: 220980969 | F2080: 103 | G2080: 2.2098097e+08 | H2080: 0 | I2080: 0 | J2080: 2145446.3 | K2080: 0 | L2080: 0 | M2080: 0 | N2080: 103 | O2080: 2.2098097e+08
A2081: MÀN HÌNH VI TÍNH (LCD) LENOVO ThinkVision S27e-20 27.0INCH/1920x1080/IPS/WLED/VGA/HDMI/ĐEN/3Y(62AFKAR2WW) | B2081: CÁI | C2081: 17 | D2081: 47268918 | F2081: 17 | G2081: 47268918 | H2081: 0 | I2081: 0 | J2081: 2780524.6 | K2081: 0 | L2081: 0 | M2081: 0 | N2081: 17 | O2081: 47268918
A2082: Máy tính xách tay MSI GF63 Thin11UC-1228VN (i7-11800H; 8GB;512GB SSD; RTX3050/4GB; 15.6"FHD; Win11; Đen) | B2082: Bộ | C2082: 2 | D2082: 34727271 | F2082: 2 | G2082: 34727271 | H2082: 0 | I2082: 0 | J2082: 17363636 | K2082: 0 | L2082: 0 | M2082: 0 | N2082: 2 | O2082: 34727271
A2083: Màn hình LCD VIEWSONIC VX2718-PC - MHD/27'' LCD MONITOR | B2083: Bộ | C2083: 6 | D2083: 23072724 | F2083: 6 | G2083: 23072724 | H2083: 0 | I2083: 0 | J2083: 3845454 | K2083: 0 | L2083: 0 | M2083: 0 | N2083: 6 | O2083: 23072724
A2084: Màn hình máy tính Viewsonic VX3276 - MHD -3/32 inch, Full HD, IPS,75Hz | B2084: Cái | C2084: 8 | D2084: 32000000 | F2084: 8 | G2084: 32000000 | H2084: 0 | I2084: 0 | J2084: 4000000 | K2084: 0 | L2084: 0 | M2084: 0 | N2084: 8 | O2084: 32000000
A2085: Ổ CỨNG DI ĐỘNG (HDD) SEAGATE ONETOUCH 2TB2.5" USB3.0 - ĐEN (BLACK)(STKY2000400) | B2085: Cái | C2085: 1 | D2085: 2004545 | F2085: 1 | G2085: 2004545 | H2085: 0 | I2085: 0 | J2085: 2004545 | K2085: 0 | L2085: 0 | M2085: 0 | N2085: 1 | O2085: 2004545
A2086: Bộ Vi xử lý Intel Core i3-10105 Processor3.70GHz 6M Cache, Sockets FCLGA1200-BX8070110105 | B2086: Cái | C2086: 38 | D2086: 90244901 | F2086: 38 | G2086: 90244901 | H2086: 0 | I2086: 0 | J2086: 2374865.8 | K2086: 0 | L2086: 0 | M2086: 0 | N2086: 38 | O2086: 90244901
A2087: Ổ đĩa cứng máy tính KingmaxSA3080 128GB (M.2 Sata 3) | B2087: Cái | C2087: 5 | D2087: 1590907 | F2087: 5 | G2087: 1590906.7 | H2087: 0 | I2087: 0 | J2087: 318181.33 | K2087: 0 | L2087: 0 | M2087: 0 | N2087: 5 | O2087: 1590906.7
... A2474: MÁY IN HP LASER JET PRO M404DN (W1A53A) | B2474: Cái | C2474: 1 | D2474: 5072727 | F2474: 1 | G2474: 5072726.8 | H2474: 0 | I2474: 0 | J2474: 5072726.8 | K2474: 0 | L2474: 0 | M2474: 0 | N2474: 1 | O2474: 5072726.8
C2475: 25472 | D2475: 21149688603 | E2475: 1855 | F2475: 26470 | G2475: 2.1651388e+10 | H2475: 18759 | I2475: 19400397646 | J2475: 6.6183816e+09 | K2475: 13287 | L2475: 17950769158 | M2475: 1.148427e+10 | N2475: 31942 | O2475: 2.9567515e+10

Sheet 2024
F1: Đầu Kỳ | H1: Nhập Kho | K1: Xuất Kho | N1: Tồn Kho
A2: Tên Sản Phẩm | B2: DVT | C2: Gốc | F2: Số Lượng | G2: Thành Tiền | H2: Số Lượng | I2: Thành Tiền | J2: Giá Vốn | K2: Số Lượng | L2: Thành Tiền | M2: TT Giá Vốn | N2: Số Lượng | O2: TT Giá Vốn
A3: tensp | B3: dvtinh | F3: tong_dauky | G3: thtien_dauky | H3: tong_nhap | I3: thtien_nhap | K3: tong_xuat | L3: thtien_xuat | N3: ton_kho
A4: Màn hình vi tính DELL LCD-E2423H-23.8-WHD-3Y | B4: Bộ | C4: 4 | D4: 10090908 | E4: =F4-C4 -> 0 | F4: =IFERROR(VLOOKUP(A4,'2023'!A:N,13,0),0) -> 4 | G4: =IFERROR(VLOOKUP(A4,'2023'!A:N,14,0),0) -> 10090908 | H4: 2 | I4: 4336364 | J4: =IFERROR(IF((G4+I4)/(H4+F4)<0,0,(G4+I4)/(H4+F4)),0) -> 2404545.3 | K4: 0 | L4: 0 | M4: =J4*K4 -> 0 | N4: =F4+H4-K4 -> 6 | O4: =G4+I4-M4 -> 14427272
A5: Điều chỉnh giảm đơn giá, giảm thành tiền của hàng hóa dịch vụ: Máy tính xách tay Lenovo ThinkPad E14 G5 T (gồm I5-13420H ( 2.1Ghz ) - 1x8G Ram -512G SSD - Wifi,BT,Finger Print - 14"WUXGA 300N - No OS - 2 Yrs Premier support_21JK00H3VA) | B5: Chiếc | C5: 0 | D5: 0 | E5: =F5-C5 -> 0 | F5: =IFERROR(VLOOKUP(A5,'2023'!A:N,13,0),0) -> 0 | G5: =IFERROR(VLOOKUP(A5,'2023'!A:N,14,0),0) -> 0 | H5: 2 | I5: -909090 | J5: =IFERROR(IF((G5+I5)/(H5+F5)<0,0,(G5+I5)/(H5+F5)),0) -> 0 | K5: 0 | L5: 0 | M5: =J5*K5 -> 0 | N5: =F5+H5-K5 -> 2 | O5: =G5+I5-M5 -> -909090
A6: Mực MP 3054/3554/2554 | B6: Hộp | C6: 0 | D6: 0 | E6: =F6-C6 -> 0 | F6: =IFERROR(VLOOKUP(A6,'2023'!A:N,13,0),0) -> 0 | G6: =IFERROR(VLOOKUP(A6,'2023'!A:N,14,0),0) -> 0 | H6: 3 | I6: 1300000 | J6: =IFERROR(IF((G6+I6)/(H6+F6)<0,0,(G6+I6)/(H6+F6)),0) -> 433333.33 | K6: 3 | L6: 2045454 | M6: =J6*K6 -> 1300000 | N6: =F6+H6-K6 -> 0 | O6: =G6+I6-M6 -> 0
A7: Chiết khấu thương mại Mua vào Từ 23/10/2023 đến 30/11/2023 Sản phẩm DELL MKT-DLL-VF-SI-2023-000154 | B7: Dịch vụ | C7: 0 | D7: 0 | E7: =F7-C7 -> 0 | F7: =IFERROR(VLOOKUP(A7,'2023'!A:N,13,0),0) -> 0 | G7: =IFERROR(VLOOKUP(A7,'2023'!A:N,14,0),0) -> 0 | H7: 1 | I7: 872727 | J7: =IFERROR(IF((G7+I7)/(H7+F7)<0,0,(G7+I7)/(H7+F7)),0) -> 872727 | K7: 0 | L7: 0 | M7: =J7*K7 -> 0 | N7: =F7+H7-K7 -> 1 | O7: =G7+I7-M7 -> 872727
A8: Chuột vi tính Rapoo M20 | B8: Cái | C8: 0 | D8: 0 | E8: =F8-C8 -> 0 | F8: =IFERROR(VLOOKUP(A8,'2023'!A:N,13,0),0) -> 0 | G8: =IFERROR(VLOOKUP(A8,'2023'!A:N,14,0),0) -> 0 | H8: 0 | I8: 0 | J8: =IFERROR(IF((G8+I8)/(H8+F8)<0,0,(G8+I8)/(H8+F8)),0) -> 0 | K8: 314 | L8: 34900891 | M8: =J8*K8 -> 0 | N8: =F8+H8-K8 -> -314 | O8: =G8+I8-M8 -> 0
A9: Hàng KM_Balo máy tính xách tay dành cho máy tính Lenovo | B9: Chiếc | C9: 0 | D9: 0 | E9: =F9-C9 -> 0 | F9: =IFERROR(VLOOKUP(A9,'2023'!A:N,13,0),0) -> 0 | G9: =IFERROR(VLOOKUP(A9,'2023'!A:N,14,0),0) -> 0 | H9: 30 | I9: 0 | J9: =IFERROR(IF((G9+I9)/(H9+F9)<0,0,(G9+I9)/(H9+F9)),0) -> 0 | K9: 0 | L9: 0 | M9: =J9*K9 -> 0 | N9: =F9+H9-K9 -> 30 | O9: =G9+I9-M9 -> 0
A10: Ổ cắm điện Philips CHP1130WB (Hàng khuyến mại) | B10: Cái | C10: 0 | D10: 0 | E10: =F10-C10 -> 0 | F10: =IFERROR(VLOOKUP(A10,'2023'!A:N,13,0),0) -> 0 | G10: =IFERROR(VLOOKUP(A10,'2023'!A:N,14,0),0) -> 0 | H10: 123 | I10: 0 | J10: =IFERROR(IF((G10+I10)/(H10+F10)<0,0,(G10+I10)/(H10+F10)),0) -> 0 | K10: 0 | L10: 0 | M10: =J10*K10 -> 0 | N10: =F10+H10-K10 -> 123 | O10: =G10+I10-M10 -> 0
A11: Mực T2323 | B11: Hộp | C11: 0 | D11: 0 | E11: =F11-C11 -> 0 | F11: =IFERROR(VLOOKUP(A11,'2023'!A:N,13,0),0) -> 0 | G11: =IFERROR(VLOOKUP(A11,'2023'!A:N,14,0),0) -> 0 | H11: 3 | I11: 1500000 | J11: =IFERROR(IF((G11+I11)/(H11+F11)<0,0,(G11+I11)/(H11+F11)),0) -> 500000 | K11: 2 | L11: 1772727 | M11: =J11*K11 -> 1000000 | N11: =F11+H11-K11 -> 1 | O11: =G11+I11-M11 -> 500000
A12: Cước đường bộ xe 81C06495T đi qua trạm Gia Lai 1 thời gian GD 09:27:42 ngày 05/11/2024 mã GD 1481911561 | B12: Lượt | C12: 0 | D12: 0 | E12: =F12-C12 -> 0 | F12: =IFERROR(VLOOKUP(A12,'2023'!A:N,13,0),0) -> 0 | G12: =IFERROR(VLOOKUP(A12,'2023'!A:N,14,0),0) -> 0 | H12: 1 | I12: 37037 | J12: =IFERROR(IF((G12+I12)/(H12+F12)<0,0,(G12+I12)/(H12+F12)),0) -> 37037 | K12: 0 | L12: 0 | M12: =J12*K12 -> 0 | N12: =F12+H12-K12 -> 1 | O12: =G12+I12-M12 -> 37037
A13: Cước đường bộ xe 81C06495T đi qua trạm Gia Lai 1 thời gian GD 12:23:14 ngày 05/11/2024 mã GD 1482140210 | B13: Lượt | C13: 0 | D13: 0 | E13: =F13-C13 -> 0 | F13: =IFERROR(VLOOKUP(A13,'2023'!A:N,13,0),0) -> 0 | G13: =IFERROR(VLOOKUP(A13,'2023'!A:N,14,0),0) -> 0 | H13: 1 | I13: 37037 | J13: =IFERROR(IF((G13+I13)/(H13+F13)<0,0,(G13+I13)/(H13+F13)),0) -> 37037 | K13: 0 | L13: 0 | M13: =J13*K13 -> 0 | N13: =F13+H13-K13 -> 1 | O13: =G13+I13-M13 -> 37037
A14: Phí dịch vụ Đăng ký/Thay đổi E-Tag cho biển số xe 81C06495TL thời gian GD 17:09:00 ngày 14/06/2024 mã GD 11279174 | B14: Lượt | C14: 0 | D14: 0 | E14: =F14-C14 -> 0 | F14: =IFERROR(VLOOKUP(A14,'2023'!A:N,13,0),0) -> 0 | G14: =IFERROR(VLOOKUP(A14,'2023'!A:N,14,0),0) -> 0 | H14: 1 | I14: 109091 | J14: =IFERROR(IF((G14+I14)/(H14+F14)<0,0,(G14+I14)/(H14+F14)),0) -> 109091 | K14: 0 | L14: 0 | M14: =J14*K14 -> 0 | N14: =F14+H14-K14 -> 1 | O14: =G14+I14-M14 -> 109091
A15: Cước đường bộ xe 81C06495T đi qua trạm Gia Lai 1 thời gian GD 17:11:16 ngày 02/07/2024 mã GD 1298533240 | B15: Lượt | C15: 0 | D15: 0 | E15: =F15-C15 -> 0 | F15: =IFERROR(VLOOKUP(A15,'2023'!A:N,13,0),0) -> 0 | G15: =IFERROR(VLOOKUP(A15,'2023'!A:N,14,0),0) -> 0 | H15: 1 | I15: 37037 | J15: =IFERROR(IF((G15+I15)/(H15+F15)<0,0,(G15+I15)/(H15+F15)),0) -> 37037 | K15: 0 | L15: 0 | M15: =J15*K15 -> 0 | N15: =F15+H15-K15 -> 1 | O15: =G15+I15-M15 -> 37037
... A2379: MÁY TÍNH XÁCH TAY (NB) LENOVO V14 G3 IAP i3-1215U/8GD4/256GSSD/14.0FHD/IPS/WL/BT/2C38/NoOS/ĐEN (82TS0060VN) | B2379: Cái | C2379: 22 | D2379: 206472261 | E2379: =F2379-C2379 -> 0 | F2379: =IFERROR(VLOOKUP(A2379,'2023'!A:N,13,0),0) -> 22 | G2379: =IFERROR(VLOOKUP(A2379,'2023'!A:N,14,0),0) -> 2.0647226e+08 | H2379: 0 | I2379: 0 | J2379: =IFERROR(IF((G2379+I2379)/(H2379+F2379)<0,0,(G2379+I2379)/(H2379+F2379)),0) -> 9385102.8 | K2379: 0 | L2379: 0 | M2379: =J2379*K2379 -> 0 | N2379: =F2379+H2379-K2379 -> 22 | O2379: =G2379+I2379-M2379 -> 2.0647226e+08
A2380: Máy tính xách tay MSI Katana GF66 12UCK-699VN/Alder Lake i5-12450H/512GB SSD/DDR4 8GB (3200MHz)/RTX3050 GDDR6 4GB/15.6" FHD/WIN 11/màu đen/ba lô | B2380: Cái | C2380: 1 | D2380: 19127272 | F2380: =IFERROR(VLOOKUP(A2380,'2023'!A:N,13,0),0) -> 1 | G2380: =IFERROR(VLOOKUP(A2380,'2023'!A:N,14,0),0) -> 19127272 | H2380: 0 | I2380: 0 | J2380: =IFERROR(IF((G2380+I2380)/(H2380+F2380)<0,0,(G2380+I2380)/(H2380+F2380)),0) -> 19127272 | K2380: 0 | L2380: 0 | M2380: =J2380*K2380 -> 0 | N2380: =F2380+H2380-K2380 -> 1 | O2380: =G2380+I2380-M2380 -> 19127272
A2381: Máy tính bàn Lenovo ThinkCentre M70s Gen 3 i3-12100 ( 4.3 GHZ) - 8GB RAM - 256GB SSD - Wireless & Bluetooth - None -1Yr; P/n 11TC000QVA | B2381: Bộ | C2381: 19 | D2381: 156663626 | F2381: =IFERROR(VLOOKUP(A2381,'2023'!A:N,13,0),0) -> 19 | G2381: =IFERROR(VLOOKUP(A2381,'2023'!A:N,14,0),0) -> 156663626 | H2381: 0 | I2381: 0 | J2381: =IFERROR(IF((G2381+I2381)/(H2381+F2381)<0,0,(G2381+I2381)/(H2381+F2381)),0) -> 8245454 | K2381: 0 | L2381: 0 | M2381: =J2381*K2381 -> 0 | N2381: =F2381+H2381-K2381 -> 19 | O2381: =G2381+I2381-M2381 -> 156663626
A2382: Máy tính xách tay Lenovo V15 G4 IRU - Intel Core i3-1315U (4.50 GHz) - 8GB RAM - 512GB SSD - WF+BL - 15.6FHD 60Hz - NOS - 2YR Premium NBD,P/n 83A10007VN | B2382: Chiếc | C2382: 3 | D2382: 30000000 | F2382: =IFERROR(VLOOKUP(A2382,'2023'!A:N,13,0),0) -> 3 | G2382: =IFERROR(VLOOKUP(A2382,'2023'!A:N,14,0),0) -> 30000000 | H2382: 0 | I2382: 0 | J2382: =IFERROR(IF((G2382+I2382)/(H2382+F2382)<0,0,(G2382+I2382)/(H2382+F2382)),0) -> 10000000 | K2382: 0 | L2382: 0 | M2382: =J2382*K2382 -> 0 | N2382: =F2382+H2382-K2382 -> 3 | O2382: =G2382+I2382-M2382 -> 30000000
A2383: Máy tính xách tay MSI GF63 Thin11SC-664VN (i5-11400H; 8GB;512GB SSD; GTX 1650/4GB; 15.6"FHD 144Hz; Win11; Đen) | B2383: Bộ | C2383: 1 | D2383: 15545454 | F2383: =IFERROR(VLOOKUP(A2383,'2023'!A:N,13,0),0) -> 1 | G2383: =IFERROR(VLOOKUP(A2383,'2023'!A:N,14,0),0) -> 15545454 | H2383: 0 | I2383: 0 | J2383: =IFERROR(IF((G2383+I2383)/(H2383+F2383)<0,0,(G2383+I2383)/(H2383+F2383)),0) -> 15545454 | K2383: 0 | L2383: 0 | M2383: =J2383*K2383 -> 0 | N2383: =F2383+H2383-K2383 -> 1 | O2383: =G2383+I2383-M2383 -> 15545454
A2384: Màn hình máy tính Lenovo H20215FE0 - "E22-28 (H20215FE0) 21.5 inch Monitor-HDMI, Linecord, 3YR WTYWarrantyCode: 3years limited", P/N:62B9MAR4WW | B2384: Chiếc | C2384: 103 | D2384: 220980969 | F2384: =IFERROR(VLOOKUP(A2384,'2023'!A:N,13,0),0) -> 103 | G2384: =IFERROR(VLOOKUP(A2384,'2023'!A:N,14,0),0) -> 2.2098097e+08 | H2384: 0 | I2384: 0 | J2384: =IFERROR(IF((G2384+I2384)/(H2384+F2384)<0,0,(G2384+I2384)/(H2384+F2384)),0) -> 2145446.3 | K2384: 0 | L2384: 0 | M2384: =J2384*K2384 -> 0 | N2384: =F2384+H2384-K2384 -> 103 | O2384: =G2384+I2384-M2384 -> 2.2098097e+08
A2385: MÀN HÌNH VI TÍNH (LCD) LENOVO ThinkVision S27e-20 27.0INCH/1920x1080/IPS/WLED/VGA/HDMI/ĐEN/3Y(62AFKAR2WW) | B2385: CÁI | C2385: 17 | D2385: 47268918 | F2385: =IFERROR(VLOOKUP(A2385,'2023'!A:N,13,0),0) -> 17 | G2385: =IFERROR(VLOOKUP(A2385,'2023'!A:N,14,0),0) -> 47268918 | H2385: 0 | I2385: 0 | J2385: =IFERROR(IF((G2385+I2385)/(H2385+F2385)<0,0,(G2385+I2385)/(H2385+F2385)),0) -> 2780524.6 | K2385: 0 | L2385: 0 | M2385: =J2385*K2385 -> 0 | N2385: =F2385+H2385-K2385 -> 17 | O2385: =G2385+I2385-M2385 -> 47268918
A2386: Máy tính xách tay MSI GF63 Thin11UC-1228VN (i7-11800H; 8GB;512GB SSD; RTX3050/4GB; 15.6"FHD; Win11; Đen) | B2386: Bộ | C2386: 2 | D2386: 34727271 | F2386: =IFERROR(VLOOKUP(A2386,'2023'!A:N,13,0),0) -> 2 | G2386: =IFERROR(VLOOKUP(A2386,'2023'!A:N,14,0),0) -> 34727271 | H2386: 0 | I2386: 0 | J2386: =IFERROR(IF((G2386+I2386)/(H2386+F2386)<0,0,(G2386+I2386)/(H2386+F2386)),0) -> 17363636 | K2386: 0 | L2386: 0 | M2386: =J2386*K2386 -> 0 | N2386: =F2386+H2386-K2386 -> 2 | O2386: =G2386+I2386-M2386 -> 34727271
A2387: Màn hình LCD VIEWSONIC VX2718-PC - MHD/27'' LCD MONITOR | B2387: Bộ | C2387: 6 | D2387: 23072724 | F2387: =IFERROR(VLOOKUP(A2387,'2023'!A:N,13,0),0) -> 6 | G2387: =IFERROR(VLOOKUP(A2387,'2023'!A:N,14,0),0) -> 23072724 | H2387: 0 | I2387: 0 | J2387: =IFERROR(IF((G2387+I2387)/(H2387+F2387)<0,0,(G2387+I2387)/(H2387+F2387)),0) -> 3845454 | K2387: 0 | L2387: 0 | M2387: =J2387*K2387 -> 0 | N2387: =F2387+H2387-K2387 -> 6 | O2387: =G2387+I2387-M2387 -> 23072724
A2388: Màn hình máy tính Viewsonic VX3276 - MHD -3/32 inch, Full HD, IPS,75Hz | B2388: Cái | C2388: 8 | D2388: 32000000 | F2388: =IFERROR(VLOOKUP(A2388,'2023'!A:N,13,0),0) -> 8 | G2388: =IFERROR(VLOOKUP(A2388,'2023'!A:N,14,0),0) -> 32000000 | H2388: 0 | I2388: 0 | J2388: =IFERROR(IF((G2388+I2388)/(H2388+F2388)<0,0,(G2388+I2388)/(H2388+F2388)),0) -> 4000000 | K2388: 0 | L2388: 0 | M2388: =J2388*K2388 -> 0 | N2388: =F2388+H2388-K2388 -> 8 | O2388: =G2388+I2388-M2388 -> 32000000
A2389: Ổ CỨNG DI ĐỘNG (HDD) SEAGATE ONETOUCH 2TB2.5" USB3.0 - ĐEN (BLACK)(STKY2000400) | B2389: Cái | C2389: 1 | D2389: 2004545 | F2389: =IFERROR(VLOOKUP(A2389,'2023'!A:N,13,0),0) -> 1 | G2389: =IFERROR(VLOOKUP(A2389,'2023'!A:N,14,0),0) -> 2004545 | H2389: 0 | I2389: 0 | J2389: =IFERROR(IF((G2389+I2389)/(H2389+F2389)<0,0,(G2389+I2389)/(H2389+F2389)),0) -> 2004545 | K2389: 0 | L2389: 0 | M2389: =J2389*K2389 -> 0 | N2389: =F2389+H2389-K2389 -> 1 | O2389: =G2389+I2389-M2389 -> 2004545
A2390: Bộ Vi xử lý Intel Core i3-10105 Processor3.70GHz 6M Cache, Sockets FCLGA1200-BX8070110105 | B2390: Cái | C2390: 38 | D2390: 90244901 | F2390: =IFERROR(VLOOKUP(A2390,'2023'!A:N,13,0),0) -> 38 | G2390: =IFERROR(VLOOKUP(A2390,'2023'!A:N,14,0),0) -> 90244901 | H2390: 0 | I2390: 0 | J2390: =IFERROR(IF((G2390+I2390)/(H2390+F2390)<0,0,(G2390+I2390)/(H2390+F2390)),0) -> 2374865.8 | K2390: 0 | L2390: 0 | M2390: =J2390*K2390 -> 0 | N2390: =F2390+H2390-K2390 -> 38 | O2390: =G2390+I2390-M2390 -> 90244901
A2391: Ổ đĩa cứng máy tính KingmaxSA3080 128GB (M.2 Sata 3) | B2391: Cái | C2391: 5 | D2391: 1590907 | F2391: =IFERROR(VLOOKUP(A2391,'2023'!A:N,13,0),0) -> 5 | G2391: =IFERROR(VLOOKUP(A2391,'2023'!A:N,14,0),0) -> 1590906.7 | H2391: 0 | I2391: 0 | J2391: =IFERROR(IF((G2391+I2391)/(H2391+F2391)<0,0,(G2391+I2391)/(H2391+F2391)),0) -> 318181.33 | K2391: 0 | L2391: 0 | M2391: =J2391*K2391 -> 0 | N2391: =F2391+H2391-K2391 -> 5 | O2391: =G2391+I2391-M2391 -> 1590906.7
... A2778: MÁY IN HP LASER JET PRO M404DN (W1A53A) | B2778: Cái | C2778: 1 | D2778: 5072727 | F2778: =IFERROR(VLOOKUP(A2778,'2023'!A:N,13,0),0) -> 1 | G2778: =IFERROR(VLOOKUP(A2778,'2023'!A:N,14,0),0) -> 5072726.8 | H2778: 0 | I2778: 0 | J2778: =IFERROR(IF((G2778+I2778)/(H2778+F2778)<0,0,(G2778+I2778)/(H2778+F2778)),0) -> 5072726.8 | K2778: 0 | L2778: 0 | M2778: =J2778*K2778 -> 0 | N2778: =F2778+H2778-K2778 -> 1 | O2778: =G2778+I2778-M2778 -> 5072726.8
C2779: =SUM(C4:C2778) -> 25472 | D2779: =SUM(D4:D2778) -> 21149688603 | E2779: =SUM(E4:E2778) -> 1855 | F2779: =SUM(F4:F2778) -> 26470 | G2779: =SUM(G4:G2778) -> 2.1651388e+10 | H2779: =SUM(H4:H2778) -> 18759 | I2779: =SUM(I4:I2778) -> 19400397646 | J2779: =SUM(J4:J2778) -> 6.6183816e+09 | ... O2779: =SUM(O4:O2778) -> 2.9567515e+10

Sheet tk 2024 bs
B1: TK MUA VÀO | D1: TK ĐC MUA VÀO | F1: ĐC THUẾ KT | G1: HĐ MUA VÀO | I1: CL HĐ VÀ TK | L1: TK BÁN RA | N1: DT KCT | O1: TK ĐC | Q1: HĐ BÁN RA | S1: CL TK VÀ HĐ | V1: TGTGT CÒN KT | W1: DT K CT | X1: tgtgt kt
A2: 1 | B2: DT | C2: TGTGT | G2: DT | H2: TGTGT | I2: CT | J2: DT | K2: TGTGT | L2: DT | M2: TGTGT | O2: DT BÁN | P2: TH GTGT | Q2: DT | R2: TGTGT | S2: DT CT | T2: DT | U2: TGTGT | V2: 59486211
A3: 1 | B3: 666062561 | C3: 64523279 | D3: 854267106 | E3: 83343734 | G3: ='[1]sheet 1'!$I$74 -> 877855283 | H3: ='[1]sheet 1'!$J$74 -> 85692554 | I3: =G3-B3 -> 211792722 | J3: =H3-E3 -> 2348820 | L3: 637005562 | M3: ='[2]sheet 1'!$J$126 -> 63622258 | N3: 31480000 | O3: =L3+N3 -> 668485562 | P3: =M3 -> 63622258 | Q3: ='[2]sheet 1'!$I$128 -> 663563744 | R3: ='[2]sheet 1'!$J$126 -> 63622258 | S3: =Q3+N3 -> 695043744 | V3: =M3-E3-V2 -> -79207687 | W3: ='[2]sheet 1'!$I$127 -> 5740000 | X3: 60469045
A4: 2 | B4: 1119239102 | C4: 111834913 | D4: 1119239102 | E4: 111834913 | F4: 18820455 | G4: ='[3]sheet 1'!$I$52 -> 1292172526 | H4: ='[3]sheet 1'!$J$52 -> 129128259 | I4: =G4-B4 -> 172933424 | J4: =H4-C4 -> 17293346 | L4: 392055119 | M4: 39095882 | O4: =L4 -> 392055119 | P4: =M4 -> 39095882 | Q4: 392055119 | R4: 39095881 | X4: 152028531
A5: 3 | B5: 1911919749 | C5: 189212555 | D5: 1911919749 | E5: 189212555 | G5: ='[4]sheet 1'!$I$88 -> 1892536439 | H5: ='[4]sheet 1'!$J$88 -> 187274225 | I5: =G5-B5 -> -19383310 | J5: =H5-E5 -> -1938330 | L5: 1669919838 | M5: 166627169 | N5: 1840000 | O5: =L5+N5 -> 1671759838 | P5: =M5 -> 166627169 | Q5: =[5]Sheet2!$I$159 -> 1672478020 | R5: =[5]Sheet2!$J$159 -> 166608983 | S5: =Q5-N5 -> 1670638020 | X5: 174613917 | Y5: 106806622
A6: 4 | B6: 232501787 | C6: 19834310 | G6: 582801104 | H6: 58106369 | I6: =G6-B6 -> 350299317 | J6: =H6-C6 -> 38272059 | L6: =Q6-N6 -> 1022538904 | M6: 101987409 | N6: ='[6]sheet 1'!$I$137 -> 300000 | Q6: ='[7]sheet 1'!$I$136 -> 1022838904 | R6: ='[7]sheet 1'!$J$136 -> 101987394 | S6: =Q6-N6 -> 1022538904 | X6: 92460818
A7: 5 | B7: 704598787 | C7: 70190400 | G7: ='[8]sheet 1'!$I$69 -> 704656787 | H7: ='[8]sheet 1'!$J$69 -> 70196200 | I7: =G7-B7 -> 58000 | J7: =H7-C7 -> 5800 | L7: 1665584554 | M7: 166378455 | N7: ='[9]sheet 1'!$I$174 -> 3240000 | Q7: =L7+N7 -> 1668824554 | R7: ='[10]sheet 1'!$J$173 -> 166378447 | S7: =Q7-N7 -> 1665584554 | X7: 3727237
A8: 6 | B8: 2630860116 | C8: 261091507 | D8: 2630860116 | G8: ='[11]sheet 1'!$I$72 -> 2.6150278e+09 | H8: ='[11]sheet 1'!$J$72 -> 2.5950827e+08 | I8: =G8-B8 -> -15832363 | J8: =H8-C8 -> -1583238.9 | L8: 999889066 | M8: 99890944 | N8: 4970000 | Q8: ='[12]sheet 1'!$I$123 -> 1004859066 | R8: ='[12]sheet 1'!$J$123 -> 99890933 | S8: =Q8-N8 -> 999889066 | X8: 190964200 | Y8: 161200563
A9: 7 | B9: 1245579401 | C9: 123388534 | G9: ='[13]sheet 1'!$I$59 -> 1245657401 | H9: ='[13]sheet 1'!$J$59 -> 123396334 | I9: =G9-B9 -> 78000 | J9: =H9-C9 -> 7800 | L9: 2890656635 | M9: 288794368 | N9: ='[14]sheet 1'!$I$178 -> 30410000 | O9: =L9+N9 -> 2921066635 | Q9: ='[15]sheet 1'!$I$177 -> 2921066635 | R9: ='[15]sheet 1'!$J$177 -> 288794369 | S9: ='[14]sheet 1'!$I$179 -> 2890656635 | X9: 4205271
A10: 8 | B10: 1869275770 | C10: 183637323 | G10: =[16]Sheet1!$I$93 -> 1756620070 | H10: =[16]Sheet1!$J$93 -> 175432628 | I10: =G10-B10 -> -112655700 | J10: =H10-C10 -> -8204695 | L10: 1948039571 | M10: 194255438 | N10: 1860000 | O10: =L10+N10 -> 1949899571 | Q10: ='[17]sheet 1'!$I$167 -> 1949899571 | R10: ='[17]sheet 1'!$J$167 -> 194255429 | X10: 10618115
A11: 9 | B11: 2134167182 | C11: 210572328 | D11: 2134167182 | E11: 210572328 | G11: =[18]Sheet1!$I$91 -> 2202253333 | H11: =[18]Sheet1!$J$91 -> 217380947 | I11: =G11-B11 -> 68086151 | J11: =H11-C11 -> 6808619 | L11: 1674813581 | M11: 167430432 | N11: 19500000 | O11: =L11+N11 -> 1694313581 | Q11: ='[19]sheet 1'!$I$167 -> 1672095399 | R11: ='[20]sheet 1'!$J$165 -> 167158606 | S11: =Q11+N11 -> 1691595399 | X11: 43141896
A12: 10 | B12: 1322953953 | C12: 131928532 | F12: -38129818 | G12: ='[21]sheet 1'!$I$66 -> 1312085145 | H12: ='[21]sheet 1'!$J$66 -> 130841649 | I12: =G12-B12 -> -10868808 | J12: =H12-C12 -> -1086883 | L12: 1473955627 | M12: 147375378 | N12: 2370000 | O12: =L12+N12 -> 1476325627 | Q12: ='[22]sheet 1'!$I$127 -> 1486225627 | R12: ='[22]sheet 1'!$J$127 -> 148365373 | S12: =Q12-N12 -> 1483855627 | X12: 10434768 | Z12: 38129818
A13: 11 | B13: 2172057440 | C13: 215656040 | G13: ='[23]sheet 1'!$I$82 -> 2166229477 | H13: ='[23]sheet 1'!$J$82 -> 215074721 | I13: =G13-B13 -> -5827963 | J13: =H13-C13 -> -581319 | L13: 1373422729 | M13: 135352273 | N13: ='[24]sheet 1'!$I$147 -> 3300000 | O13: =L13+N13 -> 1376722729 | Q13: ='[25]sheet 1'!$I$146 -> 1376722729 | R13: ='[25]sheet 1'!$J$146 -> 135352269 | S13: =Q13-N13 -> 1373422729 | X13: 80303767
A14: 12 | B14: 3709957260 | C14: 369862001 | G14: ='[26]sheet 1'!$I$88 -> 3695240443 | H14: ='[26]sheet 1'!$J$88 -> 368390316 | I14: =G14-B14 -> -14716817 | J14: =H14-C14 -> -1471685 | L14: 2659095597 | M14: 262961412 | N14: 15120000 | O14: =L14+N14 -> 2674215597 | Q14: ='[27]sheet 1'!$I$207 -> 2674215597 | R14: ='[27]sheet 1'!$J$207 -> 262961408
B15: =SUM(B3:B14) -> 19719173108 | C15: =SUM(C3:C14) -> 1951731722 | D15: =SUM(D3:D14) -> 8650453255 | E15: =SUM(E3:E14) -> 594963530 | G15: =SUM(G3:G14) -> 2.0343136e+10 | H15: =SUM(H3:H14) -> 2.0204225e+09 | I15: =SUM(I3:I14) -> 6.2396265e+08 | J15: =H15-C15 -> 68690748 | K15: =SUM(K3:K14) -> 0 | L15: =SUM(L3:L14) -> 18406976783 | M15: =SUM(M3:M14) -> 1833771418 | O15: =SUM(O3:O14) -> 14824844259 | P15: =SUM(P3:P14) -> 269345309 | Q15: =SUM(Q3:Q14) -> 18504844965 | R15: =SUM(R3:R14) -> 1834471350 | Z15: 59486211
G16: =G15-B15 -> 6.2396265e+08 | J16: =H15-C15 -> 68690748 | L16: 19300615206 | S16: =Q15-O15 -> 3680000706
L17: =L16-L15 -> 893638423
S18: =S9+S11 -> 4582252034
S19: =S16-S18 -> -902251328

Sheet tk 2024
B1: TK MUA VÀO | D1: TK ĐC MUA VÀO | F1: HĐ MUA VÀO | H1: CL HĐ VÀ TK | K1: TK BÁN RA | M1: DT KCT | N1: TK ĐC | P1: HĐ BÁN RA | R1: CL TK VÀ HĐ | U1: TGTGT CÒN KT | V1: DT K CT | W1: tgtgt kt
A2: 1 | B2: DT | C2: TGTGT | F2: DT | G2: TGTGT | H2: CT | I2: DT | J2: TGTGT | K2: DT | L2: TGTGT | P2: DT | Q2: TGTGT | R2: DT CT | S2: DT | T2: TGTGT | U2: 59486211
A3: 1 | B3: 666062561 | C3: 64523279 | D3: 854267106 | E3: 83343734 | F3: ='[1]sheet 1'!$I$74 -> 877855283 | G3: ='[1]sheet 1'!$J$74 -> 85692554 | H3: =F3-B3 -> 211792722 | I3: =G3-E3 -> 2348820 | K3: ='[2]sheet 1'!$I$128 -> 663563744 | L3: ='[2]sheet 1'!$J$126 -> 63622258 | M3: ='[2]sheet 1'!$I$127 -> 5740000 | P3: ='[2]sheet 1'!$I$128 -> 663563744 | Q3: ='[2]sheet 1'!$J$126 -> 63622258 | R3: =P3+M3 -> 669303744 | U3: =L3-E3-U2 -> -79207687 | V3: ='[2]sheet 1'!$I$127 -> 5740000 | W3: 60469045
A4: 2 | B4: 1119239102 | C4: 111834913 | F4: ='[3]sheet 1'!$I$52 -> 1292172526 | G4: ='[3]sheet 1'!$J$52 -> 129128259 | H4: =F4-B4 -> 172933424 | I4: =G4-C4 -> 17293346 | K4: 392055119 | L4: 39095882 | P4: 392055119 | Q4: 39095881 | W4: 152028531
A5: 3 | B5: 1911919749 | C5: 189212555 | D5: 1911919749 | E5: 189212555 | F5: ='[4]sheet 1'!$I$88 -> 1892536439 | G5: ='[4]sheet 1'!$J$88 -> 187274225 | H5: =F5-B5 -> -19383310 | I5: =G5-E5 -> -1938330 | K5: 1671759838 | L5: 166627169 | M5: =[5]Sheet2!$I$160 -> 2740000 | P5: =[5]Sheet2!$I$159 -> 1672478020 | Q5: =[5]Sheet2!$J$159 -> 166608983 | R5: =P5-M5 -> 1669738020 | W5: 174613917 | X5: 106806622
A6: 4 | B6: 232501787 | C6: 19834310 | F6: ='[28]sheet 1'!$I$58 -> 579424087 | G6: ='[28]sheet 1'!$J$58 -> 57768665 | H6: =F6-B6 -> 346922300 | I6: =G6-C6 -> 37934355 | K6: 1022838904 | L6: 101987409 | M6: ='[6]sheet 1'!$I$137 -> 300000 | P6: ='[7]sheet 1'!$I$136 -> 1022838904 | Q6: ='[7]sheet 1'!$J$136 -> 101987394 | R6: =P6-M6 -> 1022538904 | W6: 92460818
A7: 5 | B7: 704598787 | C7: 70190400 | F7: ='[8]sheet 1'!$I$69 -> 704656787 | G7: ='[8]sheet 1'!$J$69 -> 70196200 | H7: =F7-B7 -> 58000 | I7: =G7-C7 -> 5800 | K7: 1668824554 | L7: 166378455 | M7: ='[9]sheet 1'!$I$174 -> 3240000 | P7: ='[10]sheet 1'!$I$173 -> 1668824554 | Q7: ='[10]sheet 1'!$J$173 -> 166378447 | R7: =P7-M7 -> 1665584554 | W7: 3727237
A8: 6 | B8: 2630860116 | C8: 261091507 | D8: 2630860116 | F8: ='[11]sheet 1'!$I$72 -> 2.6150278e+09 | G8: ='[11]sheet 1'!$J$72 -> 2.5950827e+08 | H8: =F8-B8 -> -15832363 | I8: =G8-C8 -> -1583238.9 | K8: 706872703 | L8: 70127307 | M8: ='[29]sheet 1'!$I$124 -> 4070000 | P8: ='[12]sheet 1'!$I$123 -> 1004859066 | Q8: ='[12]sheet 1'!$J$123 -> 99890933 | R8: =P8-M8 -> 1000789066 | W8: 190964200 | X8: 161200563
A9: 7 | B9: 1245579401 | C9: 123388534 | F9: ='[13]sheet 1'!$I$59 -> 1245657401 | G9: ='[13]sheet 1'!$J$59 -> 123396334 | H9: =F9-B9 -> 78000 | I9: =G9-C9 -> 7800 | K9: 2890656635 | L9: 288794368 | M9: ='[14]sheet 1'!$I$178 -> 30410000 | P9: ='[15]sheet 1'!$I$177 -> 2921066635 | Q9: ='[15]sheet 1'!$J$177 -> 288794369 | R9: ='[14]sheet 1'!$I$179 -> 2890656635 | W9: 4205271
A10: 8 | B10: 1869275770 | C10: 183637323 | F10: =[16]Sheet1!$I$93 -> 1756620070 | G10: =[16]Sheet1!$J$93 -> 175432628 | H10: =F10-B10 -> -112655700 | I10: =G10-C10 -> -8204695 | K10: 1949899571 | L10: 194255438 | P10: ='[17]sheet 1'!$I$167 -> 1949899571 | Q10: ='[17]sheet 1'!$J$167 -> 194255429 | W10: 10618115
A11: 9 | B11: 2134167182 | C11: 210572328 | D11: 2134167182 | E11: 210572328 | F11: =[18]Sheet1!$I$91 -> 2202253333 | G11: =[18]Sheet1!$J$91 -> 217380947 | H11: =F11-B11 -> 68086151 | I11: =G11-C11 -> 6808619 | K11: 1674813581 | L11: 167430432 | M11: ='[19]sheet 1'!$I$166 -> 30870000 | P11: ='[19]sheet 1'!$I$167 -> 1672095399 | Q11: ='[20]sheet 1'!$J$165 -> 167158606 | R11: =P11+M11 -> 1702965399 | W11: 43141896
A12: 10 | B12: 1322953953 | C12: 131928532 | F12: ='[21]sheet 1'!$I$66 -> 1312085145 | G12: ='[21]sheet 1'!$J$66 -> 130841649 | H12: =F12-B12 -> -10868808 | I12: =G12-C12 -> -1086883 | K12: 1476325627 | L12: 147375378 | M12: ='[30]sheet 1'!$I$128 -> 1520000 | P12: ='[22]sheet 1'!$I$127 -> 1486225627 | Q12: ='[22]sheet 1'!$J$127 -> 148365373 | R12: =P12-M12 -> 1484705627 | W12: 10434768 | Y12: 38129818
A13: 11 | B13: 2172057440 | C13: 215656040 | F13: ='[23]sheet 1'!$I$82 -> 2166229477 | G13: ='[23]sheet 1'!$J$82 -> 215074721 | H13: =F13-B13 -> -5827963 | I13: =G13-C13 -> -581319 | K13: 1376722729 | L13: 135352273 | M13: ='[24]sheet 1'!$I$147 -> 3300000 | P13: ='[25]sheet 1'!$I$146 -> 1376722729 | Q13: ='[25]sheet 1'!$J$146 -> 135352269 | R13: =P13-M13 -> 1373422729 | W13: 80303767
A14: 12 | B14: 3709957260 | C14: 369862001 | F14: ='[26]sheet 1'!$I$88 -> 3695240443 | G14: ='[26]sheet 1'!$J$88 -> 368390316 | H14: =F14-B14 -> -14716817 | I14: =G14-C14 -> -1471685 | K14: 2674215597 | L14: 262961412 | P14: ='[27]sheet 1'!$I$207 -> 2674215597 | Q14: ='[27]sheet 1'!$J$207 -> 262961408
B15: =SUM(B3:B14) -> 19719173108 | C15: =SUM(C3:C14) -> 1951731722 | D15: =SUM(D3:D14) -> 7531214153 | E15: =SUM(E3:E14) -> 483128617 | F15: =SUM(F3:F14) -> 2.0339759e+10 | G15: =SUM(G3:G14) -> 2.0200848e+09 | H15: =SUM(H3:H14) -> 6.2058564e+08 | I15: =G15-C15 -> 68353044 | J15: =SUM(J3:J14) -> 0 | K15: =SUM(K3:K14) -> 18168548602 | L15: =SUM(L3:L14) -> 1804007781 | N15: =SUM(N3:N14) -> 0 | O15: =SUM(O3:O14) -> 0 | P15: =SUM(P3:P14) -> 18504844965 | Q15: =SUM(Q3:Q14) -> 1834471350 | Y15: 59486211
F16: =F15-B15 -> 6.2058564e+08 | I16: =G15-C15 -> 68353044 | K16: 19300615206 | R16: =P15-N15 -> 18504844965
K17: =K16-K15 -> 1132066604
R18: =R9+R11 -> 4593622034
R19: =R16-R18 -> 13911222931

Sheet xn chỉnh 2024
F1: Đầu Kỳ | H1: Nhập Kho | K1: Xuất Kho | N1: Tồn Kho
A2: Tên Sản Phẩm | B2: DVT | C2: Gốc | F2: Số Lượng | G2: Thành Tiền | H2: Số Lượng | I2: Thành Tiền | J2: Giá Vốn | K2: Số Lượng | L2: Thành Tiền | M2: TT Giá Vốn | N2: Số Lượng | O2: TT Giá Vốn
A3: tensp | B3: dvtinh | F3: tong_dauky | G3: thtien_dauky | H3: tong_nhap | I3: thtien_nhap | K3: tong_xuat | L3: thtien_xuat | N3: ton_kho
A4: Màn hình vi tính DELL LCD-E2423H-23.8-WHD-3Y | B4: Bộ | C4: 4 | D4: 10090908 | E4: =F4-C4 -> 0 | F4: =IFERROR(VLOOKUP(A4,'2023'!A:N,13,0),0) -> 4 | G4: =IFERROR(VLOOKUP(A4,'2023'!A:N,14,0),0) -> 10090908 | H4: 2 | I4: 4336364 | J4: =IFERROR(IF((G4+I4)/(H4+F4)<0,0,(G4+I4)/(H4+F4)),0) -> 2404545.3 | K4: 0 | L4: 0 | M4: =J4*K4 -> 0 | N4: =F4+H4-K4 -> 6 | O4: =G4+I4-M4 -> 14427272
A5: Mực MP 3054/3554/2554 | B5: Hộp | C5: 0 | D5: 0 | E5: =F5-C5 -> 0 | F5: =IFERROR(VLOOKUP(A5,'2023'!A:N,13,0),0) -> 0 | G5: =IFERROR(VLOOKUP(A5,'2023'!A:N,14,0),0) -> 0 | H5: 3 | I5: 1300000 | J5: =IFERROR(IF((G5+I5)/(H5+F5)<0,0,(G5+I5)/(H5+F5)),0) -> 433333.33 | K5: 3 | L5: 2045454 | M5: =J5*K5 -> 1300000 | N5: =F5+H5-K5 -> 0 | O5: =G5+I5-M5 -> 0
A6: Chuột vi tính Rapoo M20 | B6: Cái | C6: 0 | D6: 0 | E6: =F6-C6 -> 0 | F6: =IFERROR(VLOOKUP(A6,'2023'!A:N,13,0),0) -> 0 | G6: =IFERROR(VLOOKUP(A6,'2023'!A:N,14,0),0) -> 0 | H6: 0 | I6: 0 | J6: =IFERROR(IF((G6+I6)/(H6+F6)<0,0,(G6+I6)/(H6+F6)),0) -> 0 | K6: 314 | L6: 34900891 | M6: =J6*K6 -> 0 | N6: =F6+H6-K6 -> -314 | O6: =G6+I6-M6 -> 0
A7: Mực T2323 | B7: Hộp | C7: 0 | D7: 0 | E7: =F7-C7 -> 0 | F7: =IFERROR(VLOOKUP(A7,'2023'!A:N,13,0),0) -> 0 | G7: =IFERROR(VLOOKUP(A7,'2023'!A:N,14,0),0) -> 0 | H7: 3 | I7: 1500000 | J7: =IFERROR(IF((G7+I7)/(H7+F7)<0,0,(G7+I7)/(H7+F7)),0) -> 500000 | K7: 2 | L7: 1772727 | M7: =J7*K7 -> 1000000 | N7: =F7+H7-K7 -> 1 | O7: =G7+I7-M7 -> 500000
A8: Hộp mực Prospect CF276A/CRG057 | B8: Hộp | C8: 0 | D8: 0 | E8: =F8-C8 -> 0 | F8: =IFERROR(VLOOKUP(A8,'2023'!A:N,13,0),0) -> 0 | G8: =IFERROR(VLOOKUP(A8,'2023'!A:N,14,0),0) -> 0 | H8: 1 | I8: 163636 | J8: =IFERROR(IF((G8+I8)/(H8+F8)<0,0,(G8+I8)/(H8+F8)),0) -> 163636 | K8: 1 | L8: 436364 | M8: =J8*K8 -> 163636 | N8: =F8+H8-K8 -> 0 | O8: =G8+I8-M8 -> 0
A9: Hộp mực (Cartridge) đã có mực in dùng cho máy in Laser loại PTB - T420 , hiệu POLYTONER | B9: Hộp | C9: 0 | D9: 0 | E9: =F9-C9 -> 0 | F9: =IFERROR(VLOOKUP(A9,'2023'!A:N,13,0),0) -> 0 | G9: =IFERROR(VLOOKUP(A9,'2023'!A:N,14,0),0) -> 0 | H9: 1 | I9: 181818 | J9: =IFERROR(IF((G9+I9)/(H9+F9)<0,0,(G9+I9)/(H9+F9)),0) -> 181818 | K9: 0 | L9: 0 | M9: =J9*K9 -> 0 | N9: =F9+H9-K9 -> 1 | O9: =G9+I9-M9 -> 181818
A10: Kiểm định xe tô dưới 10 ghế, CThg (BĐK: 81A-002.83) | B10: Xe | C10: 1 | D10: 227273 | E10: =F10-C10 -> 0 | F10: =IFERROR(VLOOKUP(A10,'2023'!A:N,13,0),0) -> 1 | G10: =IFERROR(VLOOKUP(A10,'2023'!A:N,14,0),0) -> 227273 | H10: 1 | I10: 227273 | J10: =IFERROR(IF((G10+I10)/(H10+F10)<0,0,(G10+I10)/(H10+F10)),0) -> 227273 | K10: 0 | L10: 0 | M10: =J10*K10 -> 0 | N10: =F10+H10-K10 -> 2 | O10: =G10+I10-M10 -> 454546
A11: Mực TN 118 | B11: Hộp | C11: 0 | D11: 0 | E11: =F11-C11 -> 0 | F11: =IFERROR(VLOOKUP(A11,'2023'!A:N,13,0),0) -> 0 | G11: =IFERROR(VLOOKUP(A11,'2023'!A:N,14,0),0) -> 0 | H11: 1 | I11: 250000 | J11: =IFERROR(IF((G11+I11)/(H11+F11)<0,0,(G11+I11)/(H11+F11)),0) -> 250000 | K11: 0 | L11: 0 | M11: =J11*K11 -> 0 | N11: =F11+H11-K11 -> 1 | O11: =G11+I11-M11 -> 250000
A12: Mực T2309 | B12: Hộp | C12: 3 | D12: 1125000 | E12: =F12-C12 -> 0 | F12: =IFERROR(VLOOKUP(A12,'2023'!A:N,13,0),0) -> 3 | G12: =IFERROR(VLOOKUP(A12,'2023'!A:N,14,0),0) -> 1125000 | H12: 5 | I12: 1963636 | J12: =IFERROR(IF((G12+I12)/(H12+F12)<0,0,(G12+I12)/(H12+F12)),0) -> 386079.5 | K12: 5 | L12: 3390908 | M12: =J12*K12 -> 1930397.5 | N12: =F12+H12-K12 -> 3 | O12: =G12+I12-M12 -> 1158238.5
A13: Ruy băng LQ310 (N653BK) | B13: Cái | C13: 5 | D13: 240740 | E13: =F13-C13 -> 0 | F13: =IFERROR(VLOOKUP(A13,'2023'!A:N,13,0),0) -> 5 | G13: =IFERROR(VLOOKUP(A13,'2023'!A:N,14,0),0) -> 240740 | H13: 5 | I13: 240740 | J13: =IFERROR(IF((G13+I13)/(H13+F13)<0,0,(G13+I13)/(H13+F13)),0) -> 48148 | K13: 0 | L13: 0 | M13: =J13*K13 -> 0 | N13: =F13+H13-K13 -> 10 | O13: =G13+I13-M13 -> 481480
A14: Mực photo (DP-5570) | B14: Gói | C14: 0 | D14: 0 | E14: =F14-C14 -> 0 | F14: =IFERROR(VLOOKUP(A14,'2023'!A:N,13,0),0) -> 0 | G14: =IFERROR(VLOOKUP(A14,'2023'!A:N,14,0),0) -> 0 | H14: 3 | I14: 750000 | J14: =IFERROR(IF((G14+I14)/(H14+F14)<0,0,(G14+I14)/(H14+F14)),0) -> 250000 | K14: 3 | L14: 1409090 | M14: =J14*K14 -> 750000 | N14: =F14+H14-K14 -> 0 | O14: =G14+I14-M14 -> 0
A15: Thiết bị chuyển mạch MS106LP , hiệu MERCUSYS | B15: Cái | C15: 0 | D15: 0 | E15: =F15-C15 -> 0 | F15: =IFERROR(VLOOKUP(A15,'2023'!A:N,13,0),0) -> 0 | G15: =IFERROR(VLOOKUP(A15,'2023'!A:N,14,0),0) -> 0 | H15: 2 | I15: 590910 | J15: =IFERROR(IF((G15+I15)/(H15+F15)<0,0,(G15+I15)/(H15+F15)),0) -> 295455 | K15: 0 | L15: 0 | M15: =J15*K15 -> 0 | N15: =F15+H15-K15 -> 2 | O15: =G15+I15-M15 -> 590910
... A2368: MÁY TÍNH XÁCH TAY (NB) LENOVO V14 G3 IAP i3-1215U/8GD4/256GSSD/14.0FHD/IPS/WL/BT/2C38/NoOS/ĐEN (82TS0060VN) | B2368: Cái | C2368: 22 | D2368: 206472261 | E2368: =F2368-C2368 -> 0 | F2368: =IFERROR(VLOOKUP(A2368,'2023'!A:N,13,0),0) -> 22 | G2368: =IFERROR(VLOOKUP(A2368,'2023'!A:N,14,0),0) -> 2.0647226e+08 | H2368: 0 | I2368: 0 | J2368: =IFERROR(IF((G2368+I2368)/(H2368+F2368)<0,0,(G2368+I2368)/(H2368+F2368)),0) -> 9385102.8 | K2368: 0 | L2368: 0 | M2368: =J2368*K2368 -> 0 | N2368: =F2368+H2368-K2368 -> 22 | O2368: =G2368+I2368-M2368 -> 2.0647226e+08
A2369: Máy tính xách tay MSI Katana GF66 12UCK-699VN/Alder Lake i5-12450H/512GB SSD/DDR4 8GB (3200MHz)/RTX3050 GDDR6 4GB/15.6" FHD/WIN 11/màu đen/ba lô | B2369: Cái | C2369: 1 | D2369: 19127272 | F2369: =IFERROR(VLOOKUP(A2369,'2023'!A:N,13,0),0) -> 1 | G2369: =IFERROR(VLOOKUP(A2369,'2023'!A:N,14,0),0) -> 19127272 | H2369: 0 | I2369: 0 | J2369: =IFERROR(IF((G2369+I2369)/(H2369+F2369)<0,0,(G2369+I2369)/(H2369+F2369)),0) -> 19127272 | K2369: 0 | L2369: 0 | M2369: =J2369*K2369 -> 0 | N2369: =F2369+H2369-K2369 -> 1 | O2369: =G2369+I2369-M2369 -> 19127272
A2370: Máy tính bàn Lenovo ThinkCentre M70s Gen 3 i3-12100 ( 4.3 GHZ) - 8GB RAM - 256GB SSD - Wireless & Bluetooth - None -1Yr; P/n 11TC000QVA | B2370: Bộ | C2370: 19 | D2370: 156663626 | F2370: =IFERROR(VLOOKUP(A2370,'2023'!A:N,13,0),0) -> 19 | G2370: =IFERROR(VLOOKUP(A2370,'2023'!A:N,14,0),0) -> 156663626 | H2370: 0 | I2370: 0 | J2370: =IFERROR(IF((G2370+I2370)/(H2370+F2370)<0,0,(G2370+I2370)/(H2370+F2370)),0) -> 8245454 | K2370: 0 | L2370: 0 | M2370: =J2370*K2370 -> 0 | N2370: =F2370+H2370-K2370 -> 19 | O2370: =G2370+I2370-M2370 -> 156663626
A2371: Máy tính xách tay Lenovo V15 G4 IRU - Intel Core i3-1315U (4.50 GHz) - 8GB RAM - 512GB SSD - WF+BL - 15.6FHD 60Hz - NOS - 2YR Premium NBD,P/n 83A10007VN | B2371: Chiếc | C2371: 3 | D2371: 30000000 | F2371: =IFERROR(VLOOKUP(A2371,'2023'!A:N,13,0),0) -> 3 | G2371: =IFERROR(VLOOKUP(A2371,'2023'!A:N,14,0),0) -> 30000000 | H2371: 0 | I2371: 0 | J2371: =IFERROR(IF((G2371+I2371)/(H2371+F2371)<0,0,(G2371+I2371)/(H2371+F2371)),0) -> 10000000 | K2371: 0 | L2371: 0 | M2371: =J2371*K2371 -> 0 | N2371: =F2371+H2371-K2371 -> 3 | O2371: =G2371+I2371-M2371 -> 30000000
A2372: Máy tính xách tay MSI GF63 Thin11SC-664VN (i5-11400H; 8GB;512GB SSD; GTX 1650/4GB; 15.6"FHD 144Hz; Win11; Đen) | B2372: Bộ | C2372: 1 | D2372: 15545454 | F2372: =IFERROR(VLOOKUP(A2372,'2023'!A:N,13,0),0) -> 1 | G2372: =IFERROR(VLOOKUP(A2372,'2023'!A:N,14,0),0) -> 15545454 | H2372: 0 | I2372: 0 | J2372: =IFERROR(IF((G2372+I2372)/(H2372+F2372)<0,0,(G2372+I2372)/(H2372+F2372)),0) -> 15545454 | K2372: 0 | L2372: 0 | M2372: =J2372*K2372 -> 0 | N2372: =F2372+H2372-K2372 -> 1 | O2372: =G2372+I2372-M2372 -> 15545454
