Workbook

Sheet Dashboard
B2: TỔNG TÀI SẢN 2025 | D2: DOANH THU 2025 | F2: LỢI NHUẬN (LỖ) 2025
B3: ='BCĐ Kế Toán'!C11 -> #REF! | D3: ='Kết quả kinh doanh'!C5 -> 0 | F3: ='Kết quả kinh doanh'!C14 -> 0

Sheet BCĐ Tài Khoản
A1: BẢNG CÂN ĐỐI TÀI KHOẢN 2025
A3: Số hiệu TK | B3: Tên tài khoản | C3: Đầu năm | E3: Phát sinh | G3: Cuối năm
C4: Nợ | D4: Có | E4: Nợ | F4: Có | G4: Nợ | H4: Có
A5: 1111 | B5: Tiền Việt Nam | C5: 182946123 | E5: 99344647138 | F5: 99515376180 | G5: =C5+E5-F5 -> 12217081
A6: 112 | B6: Tiền gửi Ngân hàng | C6: 3344179 | E6: 185645165545 | F6: 185633591295 | G6: =C6+E6-F6 -> 14918429
A7: 131 | B7: Phải thu của khách hàng | C7: 249714141 | E7: 14753597975 | F7: 14854230024 | G7: =C7+E7-F7 -> 149082092
A8: 133 | B8: Thuế GTGT được khấu trừ | C8: 10573436 | F8: =C8 -> 10573436 | G8: =C8+E8-F8 -> 0
A9: 1331 | B9: Thuế GTGT được khấu trừ của hàng hóa, dịch vụ
A10: 152 | B10: Nguyên liệu, vật liệu
A11: 153 | B11: Công cụ, dụng cụ
A12: 1531 | B12: Công cụ, dụng cụ
A13: 156 | B13: Hàng hóa | C13: 18429715261 | E13: 97293351210 | F13: 94217380834 | G13: =C13+E13-F13 -> 21505685637
A14: 1561 | B14: Giá mua hàng hóa
A15: 211 | B15: Tài sản cố định hữu hình
A16: 2113 | B16: Phương tiện vận tải, truyền dẫn | C16: 4110323379 | G16: =C16 -> 4110323379
A17: 214 | B17: Hao mòn tài sản cố định | C17: -2254566057 | G17: =C17 -> -2254566057
A18: 2141 | B18: Hao mòn TSCĐ hữu hình
A19: 331 | B19: Phải trả cho người bán | C19: 272315245 | E19: =99787323707.1+4000000000 -> 1.0378732e+11 | F19: 104807024217 | H19: =F19-C19-E19 -> 7.4738526e+08
A20: 333 | B20: Thuế và các khoản phải nộp Nhà nước | C20: 139549502 | E20: 30000000 | F20: =71879770+30000000 -> 101879770 | H20: =C20+E20-F20 -> 67669732
A21: 3331 | B21: Thuế giá trị gia tăng phải nộp | E21: 9119473 | F21: 25840730 | H21: =F21-E21 -> 16721257
A22: 3334 | B22: Thuế thu nhập doanh nghiệp
A23: 3338 | B23: Thuế bảo vệ môi trường và các loại thuế khác
A24: 334 | B24: Phải trả người lao động
A25: 3348 | B25: Phải trả người lao động khác
A26: 338 | B26: Phải trả, phải nộp khác
A27: 3388 | B27: Phải trả, phải nộp khác
A28: 341 | B28: Vay và nợ thuê tài chính
A29: 3411 | B29: Các khoản đi vay | D29: 24841692221 | E29: 82229424534 | F29: 92051059440 | H29: 34663327127
A30: 411 | B30: Vốn đầu tư của chủ sở hữu | D30: 3000000000 | H30: =D30 -> 3000000000
A31: 4118 | B31: Vốn khác
A32: 421 | B32: Lợi nhuận sau thuế chưa phân phối | D32: =D33 -> -6697777012 | F32: =F33+F34 -> -6687027295 | H32: =F32 -> -6687027295
A33: 4211 | B33: Lợi nhuận sau thuế chưa phân phối năm trước | D33: -6697777012 | F33: =D33 -> -6697777012
A34: 4212 | B34: Lợi nhuận sau thuế chưa phân phối năm nay | F34: 10749717
A35: 511 | B35: Doanh thu bán hàng và cung cấp dịch vụ
A36: 5111 | B36: Doanh thu bán hàng hóa
A37: 515 | B37: Doanh thu hoạt động tài chính
A38: 521 | B38: Các khoản giảm trừ doanh thu
A39: 5211 | B39: Chiết khấu thương mại
A40: 632 | B40: Giá vốn hàng bán
A41: 635 | B41: Chi phí tài chính
...

Sheet BCĐ Kế Toán
A1: BẢNG CÂN ĐỐI KẾ TOÁN 2025
A3: CHỈ TIÊU | B3: MÃ SỐ | C3: SỐ CUỐI NĂM
A5: TÀI SẢN (ASSETS)
A6: 1. Tiền và tương đương tiền | B6: 110 | C6: ='BCĐ Tài Khoản'!G5+'BCĐ Tài Khoản'!#REF! -> #REF!
A7: 2. Phải thu khách hàng | B7: 130 | C7: ='BCĐ Tài Khoản'!G7 -> 149082092
A8: 3. Hàng tồn kho | B8: 140 | C8: ='BCĐ Tài Khoản'!G14 -> 0
A9: 4. Thuế GTGT được khấu trừ (Overpaid) | B9: 150 | C9: ='BCĐ Tài Khoản'!G22 -> 0
A10: 5. Tài sản cố định | B10: 210 | C10: ='BCĐ Tài Khoản'!G16 -> 4110323379
A11: TỔNG CỘNG TÀI SẢN | B11: 270 | C11: =SUM(C5:C9) -> #REF!
A13: NGUỒN VỐN (RESOURCES)
A14: 1. Phải trả người bán | B14: 310 | C14: ='BCĐ Tài Khoản'!H19 -> 7.4738526e+08
A15: 2. Vay và nợ tài chính | B15: 320 | C15: ='BCĐ Tài Khoản'!H29 -> 34663327127
A16: 3. Vốn chủ sở hữu | B16: 410 | C16: ='BCĐ Tài Khoản'!H31 -> 0
A17: 4. Lợi nhuận chưa phân phối | B17: 420 | C17: ='BCĐ Tài Khoản'!H33 - 'BCĐ Tài Khoản'!G33 -> 0
A18: TỔNG CỘNG NGUỒN VỐN | B18: 440 | C18: =SUM(C14:C17) -> 3.5410712e+10

Sheet Kết quả kinh doanh
A3: CHỈ TIÊU | B3: MÃ SỐ | C3: NĂM NAY
A5: 1. Doanh thu bán hàng | C5: ='BCĐ Tài Khoản'!F36 -> 0
A6: 2. Các khoản giảm trừ | C6: ='BCĐ Tài Khoản'!E39 -> 0
A7: 3. Doanh thu thuần | C7: =C5-C6 -> 0
A8: 4. Giá vốn hàng bán | C8: ='BCĐ Tài Khoản'!E40 -> 0
A9: 5. Lợi nhuận gộp | C9: =C7-C8 -> 0
A10: 6. Chi phí tài chính | C10: ='BCĐ Tài Khoản'!E42 -> 0
A11: 7. Chi phí bán hàng | C11: ='BCĐ Tài Khoản'!E45 -> 0
A12: 8. Chi phí quản lý DN | C12: ='BCĐ Tài Khoản'!E47 -> 0
A13: 9. Chi phí khác/ Thu nhập khác (Net) | C13: ='BCĐ Tài Khoản'!F50 - 'BCĐ Tài Khoản'!E50 -> 0
A14: 10. Lợi nhuận trước thuế | C14: =C9 - C10 - C11 - C12 + C13 -> 0
