Workbook

Sheet Tháng 1
C1: Tồn Đầu Kỳ | E1: Nhập | G1: Xuất | I1: Tồn cuối kỳ
A2: Tên Hàng | B2: Tháng | C2: Số Lượng | D2: T,Tiền | E2: Số Lượng | F2: T.Tiền | G2: Số Lượng | H2: T. Tiền | I2: Số Lượng | J2: T.Tiền
A3: Cá viên Funny 500g | B3: 1 | C3: 250 | D3: 6861365 | E3: 100 | F3: 2716600 | G3: 135 | H3: 3694358 | I3: 215 | J3: 5883607
A4: AL Anlene Concentrate Choco 4x125ml | B4: 1 | C4: 0 | D4: 0 | E4: 0 | F4: 0 | G4: 0 | H4: 0 | I4: 0 | J4: 0
A5: AL Anlene Concentrate Vanilla 4x125ml | B5: 1 | C5: 1221 | D5: 40068502 | E5: 0 | F5: 0 | G5: 94 | H5: 3084717 | I5: 1127 | J5: 36983785
A6: AL Anlene Gold Vanilla Movepro 1Kg | B6: 1 | C6: 125 | D6: 37241817 | E6: 0 | F6: 0 | G6: 0 | H6: 0 | I6: 125 | J6: 37241817
A7: AL Anlene Gold Vanilla Movepro 400g | B7: 1 | C7: 510 | D7: 69373706 | E7: 0 | F7: 0 | G7: 0 | H7: 0 | I7: 510 | J7: 69373706
A8: AL Anlene Gold Vanilla Movepro 440g | B8: 1 | C8: 354 | D8: 55405030 | E8: 0 | F8: 0 | G8: 0 | H8: 0 | I8: 354 | J8: 55405030
A9: AL Anlene Gold Vanilla Movepro 800g | B9: 1 | C9: 169 | D9: 40442640 | E9: 0 | F9: 0 | G9: 0 | H9: 0 | I9: 169 | J9: 40442640
A10: AL Anlene Movepro UHT 180ml - Có đường | B10: 1 | C10: 894 | D10: 19467870 | E10: 0 | F10: 0 | G10: 0 | H10: 0 | I10: 894 | J10: 19467870
A11: AL Anlene Movepro UHT 180ml - Không béo | B11: 1 | C11: 180 | D11: 3904035 | E11: 0 | F11: 0 | G11: 0 | H11: 0 | I11: 180 | J11: 3904035
A12: AL Anlene Vanilla Movepro 440g | B12: 1 | C12: 307 | D12: 32682234 | E12: 0 | F12: 0 | G12: 0 | H12: 0 | I12: 307 | J12: 32682234
A13: AL Anlene Vanilla Movepro 800g | B13: 1 | C13: 192 | D13: 45946668 | E13: 0 | F13: 0 | G13: 0 | H13: 0 | I13: 192 | J13: 45946668
A14: AL Anlene Vanilla Movepro Sachet 20gx3 | B14: 1 | C14: 18 | D14: 407934 | E14: 0 | F14: 0 | G14: 0 | H14: 0 | I14: 18 | J14: 407934
... A284: XXTT Heo 18g gói (T-3.6KG) | B284: 1 | C284: 0 | D284: 0 | E284: 216 | F284: 19220544 | G284: 0 | H284: 0 | I284: 216 | J284: 19220544
A285: Tổng Cộng | D285: 15447634554 | E285: 480934 | F285: 11706869809 | G285: 371957 | H285: 12007329223 | J285: 15147175140
F290: MUA VÀO 2023 | G290: BÁN RA THEO GIÁ BÁN 2023
D291: 1 | F291: 14226694560 | G291: 11386534989 | K291: 11386534989
D292: 2 | F292: 10040247266 | G292: 7934111935 | K292: 7934111935 | N292: ='Tháng 2'!H285 -> 7676643524
D293: 3 | F293: 7381679783 | G293: 8830045997 | K293: 8830045997 | N293: ='Tháng 3'!H285 -> 8812324506
D294: 4 | F294: 10255784083 | G294: 8927663945 | K294: 8927663945 | N294: ='Tháng 4'!H285 -> 8659651285
D295: 5 | F295: 9491021714 | G295: 9501096775 | K295: 9501096775 | N295: ='Tháng 5'!H285 -> 9002504084
D296: 6 | F296: 9379263229 | G296: 6476704680 | K296: 6476704680 | N296: ='Tháng 6'!H285 -> 6167307223
D297: 7 | F297: 5949569368 | G297: 11809848916 | K297: 11809848916 | N297: ='Tháng 7'!H285 -> 11337158824
D298: 8 | F298: 8159204686 | G298: 10392458795 | K298: 10392458795 | N298: ='Tháng 8'!H285 -> 9872002163
D299: 9 | F299: 8670793221 | G299: 7688034440 | K299: 7688034440 | N299: ='Tháng 9'!H285 -> 7256403764
D300: 10 | F300: 6963184455 | G300: 10074473309 | K300: 10074473309 | N300: ='Tháng 10'!H285 -> 9489921705
D301: 11 | F301: 9802832916 | G301: 7702004013 | K301: 7702004013 | N301: ='Tháng 11'!H285 -> 7330307950
D302: 12 | F302: 10199353340 | G302: 14349920815 | K302: 14349920815 | N302: ='T12 CHÍNH'!H286 -> 2.4081221e+10
F303: =SUM(F291:F302) -> 110519628621 | G303: =SUM(G291:G302) -> 115072898609 | K303: =SUM(K291:K302) -> 115072898609 | N303: =SUM(H285:H302) -> 12007329223

Sheet Tháng 2
C1: Tồn Đầu Kỳ | E1: Nhập | G1: Xuất | I1: Tồn cuối kỳ
A2: Tên Hàng | B2: Tháng | C2: Số Lượng | D2: T,Tiền | E2: Số Lượng | F2: T.Tiền | G2: Số Lượng | H2: T. Tiền | I2: Số Lượng | J2: T.Tiền
A3: Cá viên Funny 500g | B3: 2 | C3: 215 | D3: 5883607 | E3: 160 | F3: 4346560 | G3: 10 | H3: 272804 | I3: 365 | J3: 9957363
A4: AL Anlene Concentrate Choco 4x125ml | B4: 2 | C4: 0 | D4: 0 | E4: 0 | F4: 0 | G4: 0 | H4: 0 | I4: 0 | J4: 0
A5: AL Anlene Concentrate Vanilla 4x125ml | B5: 2 | C5: 1127 | D5: 36983785 | E5: 0 | F5: 0 | G5: 132 | H5: 4331730 | I5: 995 | J5: 32652055
A6: AL Anlene Gold Vanilla Movepro 1Kg | B6: 2 | C6: 125 | D6: 37241817 | E6: 0 | F6: 0 | G6: 5 | H6: 1489673 | I6: 120 | J6: 35752144
A7: AL Anlene Gold Vanilla Movepro 400g | B7: 2 | C7: 510 | D7: 69373706 | E7: 0 | F7: 0 | G7: 0 | H7: 0 | I7: 510 | J7: 69373706
A8: AL Anlene Gold Vanilla Movepro 440g | B8: 2 | C8: 354 | D8: 55405030 | E8: 0 | F8: 0 | G8: 10 | H8: 1565114 | I8: 344 | J8: 53839916
A9: AL Anlene Gold Vanilla Movepro 800g | B9: 2 | C9: 169 | D9: 40442640 | E9: 0 | F9: 0 | G9: 10 | H9: 2393056 | I9: 159 | J9: 38049584
A10: AL Anlene Movepro UHT 180ml - Có đường | B10: 2 | C10: 894 | D10: 19467870 | E10: 0 | F10: 0 | G10: 80 | H10: 1742091 | I10: 814 | J10: 17725779
A11: AL Anlene Movepro UHT 180ml - Không béo | B11: 2 | C11: 180 | D11: 3904035 | E11: 0 | F11: 0 | G11: 0 | H11: 0 | I11: 180 | J11: 3904035
A12: AL Anlene Vanilla Movepro 440g | B12: 2 | C12: 307 | D12: 32682234 | E12: 0 | F12: 0 | G12: 0 | H12: 0 | I12: 307 | J12: 32682234
A13: AL Anlene Vanilla Movepro 800g | B13: 2 | C13: 192 | D13: 45946668 | E13: 0 | F13: 0 | G13: 10 | H13: 2393056 | I13: 182 | J13: 43553612
A14: AL Anlene Vanilla Movepro Sachet 20gx3 | B14: 2 | C14: 18 | D14: 407934 | E14: 0 | F14: 0 | G14: 0 | H14: 0 | I14: 18 | J14: 407934
... A243: VS ĐL Ba rọi sốt tiêu đen gói 500g | B243: 2 | C243: 0 | D243: 0 | E243: 15 | F243: 1122000 | G243: 15 | H243: 1122000 | I243: 0 | J243: 0
A244: VS ĐL Ba rọi ướp gia vị gói 500g | B244: 2 | C244: 0 | D244: 0 | E244: 0 | F244: 0 | H244: 0 | I244: 0 | J244: 0
A245: VS ĐL Ba Rọi Xốt Mật Ong gói 500g | B245: 2 | C245: 0 | D245: 0 | E245: 42 | F245: 3141600 | G245: 42 | H245: 3141600 | I245: 0 | J245: 0
A246: VS ĐL Bò viên 3 ngon gói 500g | B246: 2 | C246: 125 | D246: 4196915 | E246: 170 | F246: 5720840 | G246: 50 | H246: 1680975 | I246: 245 | J246: 8236780
A247: VS ĐL Bò viên gói 200g | B247: 2 | C247: 0 | D247: 0 | E247: 0 | F247: 0 | H247: 0 | I247: 0 | J247: 0
A248: VS ĐL Cá viên 3 ngon gói 500g | B248: 2 | C248: 103 | D248: 2200478 | E248: 20 | F248: 854554 | G248: 0 | H248: 0 | I248: 123 | J248: 3055032
A249: VS ĐL Cá Viên Funny gói 250g (1T=30G) | B249: 2 | C249: 0 | D249: 0 | E249: 0 | F249: 0 | G249: 0 | H249: 0 | I249: 0 | J249: 0
A250: VS ĐL Cá viên gói 200g | B250: 2 | C250: 270 | D250: 4079585 | E250: 1200 | F250: 3600576 | G250: 40 | H250: 169522 | I250: 1430 | J250: 7510639
A251: VS ĐL Cá Viên ớt xiêm xanh gói 500g | B251: 2 | C251: 161 | D251: 3439584 | E251: 5 | F251: 213639 | G251: 46 | H251: 1012339 | I251: 120 | J251: 2640884
A252: VS ĐL Chả giò chay gói 500g | B252: 2 | C252: 5 | D252: 274480 | E252: 20 | F252: 1097920 | G252: 23 | H252: 1262608 | I252: 2 | J252: 109792
A253: VS ĐL Chả Giò con tôm gói 250g | B253: 2 | C253: 0 | D253: 0 | E253: 0 | F253: 0 | H253: 0 | I253: 0 | J253: 0
A254: VS ĐL Chả giò da xốp gói 400g | B254: 2 | C254: 0 | D254: 0 | E254: 0 | F254: 0 | H254: 0 | I254: 0 | J254: 0
A255: VS ĐL Chả giò hải sản gói 500g | B255: 2 | C255: 2 | D255: 118440 | E255: 80 | F255: 4737600 | G255: 79 | H255: 4678380 | I255: 3 | J255: 177660
A256: VS ĐL Chả giò rế con tôm gói 300g | B256: 2 | C256: 0 | D256: 0 | E256: 30 | F256: 1170000 | G256: 29 | H256: 1131000 | I256: 1 | J256: 39000
A257: VS ĐL Chả giò rế thịt gói 500g | B257: 2 | C257: 5 | D257: 323360 | E257: 5 | F257: 323360 | G257: 10 | H257: 646720 | I257: 0 | J257: 0
A258: VS ĐL Chả Giò rế tôm cua gói 500g | B258: 2 | C258: 2 | D258: 129720 | E258: 0 | F258: 0 | G258: 0 | H258: 0 | I258: 2 | J258: 129720
A259: VS ĐL Chả giò tôm cua gói 500g | B259: 2 | C259: 0 | D259: 0 | E259: 30 | F259: 1170000 | G259: 29 | H259: 1131000 | I259: 1 | J259: 39000
A260: VS ĐL Cốt lết ướp gia vị gói 500g | B260: 2 | C260: 80 | D260: 4419241 | E260: 0 | F260: 0 | G260: 80 | H260: 4419241 | I260: 0 | J260: 0
A261: VS ĐL Cốt lết xốt mật ong gói 500g | B261: 2 | C261: 0 | D261: 0 | E261: 6 | F261: 378000 | G261: 6 | H261: 378000 | I261: 0 | J261: 0
A262: VS ĐL Cốt lết xốt tiêu đen gói 500g | B262: 2 | C262: 0 | D262: 0 | E262: 20 | F262: 1160000 | G262: 20 | H262: 1160000 | I262: 0 | J262: 0
A263: VS ĐL Dồi sụn giòn gói 250g | B263: 2 | C263: 1 | D263: 134195 | E263: 31 | F263: 4160045 | G263: 32 | H263: 4294240 | I263: 0 | J263: 0
A264: VS ĐL Dồi sụn giòn gói 500g | B264: 2 | C264: 0 | D264: 0 | E264: 0 | F264: 0 | G264: 0 | H264: 0 | I264: 0 | J264: 0
A265: VS ĐL Há Cảo gói 250g | B265: 2 | C265: 0 | D265: 0 | E265: 0 | F265: 0 | H265: 0 | I265: 0 | J265: 0
A266: VS ĐL Há Cảo Thanh Long gói 300g | B266: 2 | C266: 0 | D266: 0 | E266: 21 | F266: 745500 | G266: 21 | H266: 745500 | I266: 0 | J266: 0
A267: VS ĐL Há Cảo Thịt gói 300g | B267: 2 | C267: 0 | D267: 0 | E267: 53 | F267: 1325000 | G267: 53 | H267: 1325000 | I267: 0 | J267: 0
A268: VS ĐL Há Cảo Tôm gói 300g | B268: 2 | C268: 1 | D268: 75576 | E268: 65 | F268: 2457000 | G268: 66 | H268: 2532576 | I268: 0 | J268: 0
...

Sheet Tháng 3
C1: Tồn Đầu Kỳ | E1: Nhập | G1: Xuất | I1: Tồn cuối kỳ
A2: Tên Hàng | B2: Tháng | C2: Số Lượng | D2: T,Tiền | E2: Số Lượng | F2: T.Tiền | G2: Số Lượng | H2: T. Tiền | I2: Số Lượng | J2: T.Tiền
A3: Cá viên Funny 500g | B3: 3 | C3: 365 | D3: 9957363 | E3: 130 | F3: 3531580 | G3: 240 | H3: 6540094 | I3: 255 | J3: 6948849
A4: AL Anlene Concentrate Choco 4x125ml | B4: 3 | C4: 0 | D4: 0 | E4: 0 | F4: 0 | G4: 0 | H4: 0 | I4: 0 | J4: 0
A5: AL Anlene Concentrate Vanilla 4x125ml | B5: 3 | C5: 995 | D5: 32652055 | E5: 0 | F5: 0 | G5: 72 | H5: 2362762 | I5: 923 | J5: 30289293
A6: AL Anlene Gold Vanilla Movepro 1Kg | B6: 3 | C6: 120 | D6: 35752144 | E6: 0 | F6: 0 | G6: 0 | H6: 0 | I6: 120 | J6: 35752144
A7: AL Anlene Gold Vanilla Movepro 400g | B7: 3 | C7: 510 | D7: 69373706 | E7: 0 | F7: 0 | G7: 0 | H7: 0 | I7: 510 | J7: 69373706
A8: AL Anlene Gold Vanilla Movepro 440g | B8: 3 | C8: 344 | D8: 53839916 | E8: 0 | F8: 0 | G8: 0 | H8: 0 | I8: 344 | J8: 53839916
A9: AL Anlene Gold Vanilla Movepro 800g | B9: 3 | C9: 159 | D9: 38049584 | E9: 0 | F9: 0 | G9: 0 | H9: 0 | I9: 159 | J9: 38049584
A10: AL Anlene Movepro UHT 180ml - Có đường | B10: 3 | C10: 814 | D10: 17725779 | E10: 0 | F10: 0 | G10: 80 | H10: 1742091 | I10: 734 | J10: 15983688
A11: AL Anlene Movepro UHT 180ml - Không béo | B11: 3 | C11: 180 | D11: 3904035 | E11: 0 | F11: 0 | G11: 0 | H11: 0 | I11: 180 | J11: 3904035
A12: AL Anlene Vanilla Movepro 440g | B12: 3 | C12: 307 | D12: 32682234 | E12: 0 | F12: 0 | G12: 12 | H12: 1277481 | I12: 295 | J12: 31404753
A13: AL Anlene Vanilla Movepro 800g | B13: 3 | C13: 182 | D13: 43553612 | E13: 0 | F13: 0 | G13: 12 | H13: 2871667 | I13: 170 | J13: 40681945
A14: AL Anlene Vanilla Movepro Sachet 20gx3 | B14: 3 | C14: 18 | D14: 407934 | E14: 0 | F14: 0 | G14: 0 | H14: 0 | I14: 18 | J14: 407934
... A284: XXTT Heo 18g gói (T-3.6KG) | B284: 3 | C284: 666 | D284: 51254784 | E284: 341 | F284: 25627392 | G284: 0 | H284: 0 | I284: 1007 | J284: 76882176
D285: 16022965628 | F285: 9550427560 | H285: 8812324506 | J285: 16761068682

Sheet Tháng 4
C1: Tồn Đầu Kỳ | E1: Nhập | G1: Xuất | I1: Tồn cuối kỳ
A2: Tên Hàng | B2: Tháng | C2: Số Lượng | D2: T,Tiền | E2: Số Lượng | F2: T.Tiền | G2: Số Lượng | H2: T. Tiền | I2: Số Lượng | J2: T.Tiền
A3: Cá viên Funny 500g | B3: 4 | C3: 255 | D3: 6948849 | E3: 160 | F3: 4410140 | G3: 184 | H3: 5036275 | I3: 231 | J3: 6322714
A4: AL Anlene Concentrate Choco 4x125ml | B4: 4 | C4: 0 | D4: 0 | E4: 0 | F4: 0 | G4: 0 | H4: 0 | I4: 0 | J4: 0
A5: AL Anlene Concentrate Vanilla 4x125ml | B5: 4 | C5: 923 | D5: 30274687 | E5: 0 | F5: 0 | G5: 24 | H5: 787587 | I5: 899 | J5: 29487100
A6: AL Anlene Gold Vanilla Movepro 1Kg | B6: 4 | C6: 120 | D6: 35752144 | E6: 0 | F6: 0 | G6: 0 | H6: 0 | I6: 120 | J6: 35752144
A7: AL Anlene Gold Vanilla Movepro 400g | B7: 4 | C7: 510 | D7: 69373706 | E7: 0 | F7: 0 | G7: 0 | H7: 0 | I7: 510 | J7: 69373706
A8: AL Anlene Gold Vanilla Movepro 440g | B8: 4 | C8: 344 | D8: 53839916 | E8: 0 | F8: 0 | G8: 0 | H8: 0 | I8: 344 | J8: 53839916
A9: AL Anlene Gold Vanilla Movepro 800g | B9: 4 | C9: 159 | D9: 38049584 | E9: 0 | F9: 0 | G9: 0 | H9: 0 | I9: 159 | J9: 38049584
A10: AL Anlene Movepro UHT 180ml - Có đường | B10: 4 | C10: 734 | D10: 15983688 | E10: 0 | F10: 0 | G10: 0 | H10: 0 | I10: 734 | J10: 15983688
A11: AL Anlene Movepro UHT 180ml - Không béo | B11: 4 | C11: 180 | D11: 3904035 | E11: 0 | F11: 0 | G11: 0 | H11: 0 | I11: 180 | J11: 3904035
A12: AL Anlene Vanilla Movepro 440g | B12: 4 | C12: 295 | D12: 31404753 | E12: 0 | F12: 0 | G12: 0 | H12: 0 | I12: 295 | J12: 31404753
A13: AL Anlene Vanilla Movepro 800g | B13: 4 | C13: 170 | D13: 40681945 | E13: 0 | F13: 0 | G13: 0 | H13: 0 | I13: 170 | J13: 40681945
A14: AL Anlene Vanilla Movepro Sachet 20gx3 | B14: 4 | C14: 18 | D14: 407934 | E14: 0 | F14: 0 | G14: 0 | H14: 0 | I14: 18 | J14: 407934
... A284: XXTT Heo 18g gói (T-3.6KG) | B284: 4 | C284: 1007 | D284: 76882176 | E284: 184 | F284: 9610272 | G284: 0 | H284: 0 | I284: 1191 | J284: 86492448
D285: 16761054076 | F285: 9316351365 | H285: 8659651285 | J285: 17417754156

Sheet Tháng 5
C1: Tồn Đầu Kỳ | E1: Nhập | G1: Xuất | I1: Tồn cuối kỳ
A2: Tên Hàng | B2: Tháng | C2: Số Lượng | D2: T,Tiền | E2: Số Lượng | F2: T.Tiền | G2: Số Lượng | H2: T. Tiền | I2: Số Lượng | J2: T.Tiền
A3: Cá viên Funny 500g | B3: 5 | C3: 231 | D3: 6322714 | E3: 120 | F3: 3329280 | G3: 140 | H3: 3849798 | I3: 211 | J3: 5802196
A4: AL Anlene Concentrate Choco 4x125ml | B4: 5 | C4: 0 | D4: 0 | E4: 0 | F4: 0 | G4: 0 | H4: 0 | I4: 0 | J4: 0
A5: AL Anlene Concentrate Vanilla 4x125ml | B5: 5 | C5: 899 | D5: 29487100 | E5: 0 | F5: 0 | G5: 36 | H5: 1181381 | I5: 863 | J5: 28305719
A6: AL Anlene Gold Vanilla Movepro 1Kg | B6: 5 | C6: 120 | D6: 35752144 | E6: 0 | F6: 0 | G6: 0 | H6: 0 | I6: 120 | J6: 35752144
A7: AL Anlene Gold Vanilla Movepro 400g | B7: 5 | C7: 510 | D7: 69373706 | E7: 0 | F7: 0 | G7: 0 | H7: 0 | I7: 510 | J7: 69373706
A8: AL Anlene Gold Vanilla Movepro 440g | B8: 5 | C8: 344 | D8: 53839916 | E8: 0 | F8: 0 | G8: 0 | H8: 0 | I8: 344 | J8: 53839916
A9: AL Anlene Gold Vanilla Movepro 800g | B9: 5 | C9: 159 | D9: 38049584 | E9: 0 | F9: 0 | G9: 0 | H9: 0 | I9: 159 | J9: 38049584
A10: AL Anlene Movepro UHT 180ml - Có đường | B10: 5 | C10: 734 | D10: 15983688 | E10: 0 | F10: 0 | G10: 0 | H10: 0 | I10: 734 | J10: 15983688
A11: AL Anlene Movepro UHT 180ml - Không béo | B11: 5 | C11: 180 | D11: 3904035 | E11: 0 | F11: 0 | G11: 0 | H11: 0 | I11: 180 | J11: 3904035
A12: AL Anlene Vanilla Movepro 440g | B12: 5 | C12: 295 | D12: 31404753 | E12: 0 | F12: 0 | G12: 0 | H12: 0 | I12: 295 | J12: 31404753
A13: AL Anlene Vanilla Movepro 800g | B13: 5 | C13: 170 | D13: 40681945 | E13: 0 | F13: 0 | G13: 0 | H13: 0 | I13: 170 | J13: 40681945
A14: AL Anlene Vanilla Movepro Sachet 20gx3 | B14: 5 | C14: 18 | D14: 407934 | E14: 0 | F14: 0 | G14: 0 | H14: 0 | I14: 18 | J14: 407934
... A284: XXTT Heo 18g gói (T-3.6KG) | B284: 5 | C284: 1191 | D284: 86492448 | E284: 241 | F284: 12813696 | G284: 0 | H284: 0 | I284: 1432 | J284: 99306144
C285: 1130577 | D285: 17417754156 | E285: 410719 | F285: 7856754302 | G285: 436661 | H285: 9002504084 | I285: 1104635 | J285: 16272004374

Sheet Tháng 6
C1: Tồn Đầu Kỳ | E1: Nhập | G1: Xuất | I1: Tồn cuối kỳ
A2: Tên Hàng | B2: Tháng | C2: Số Lượng | D2: T,Tiền | E2: Số Lượng | F2: T.Tiền | G2: Số Lượng | H2: T. Tiền | I2: Số Lượng | J2: T.Tiền
A3: Cá viên Funny 500g | B3: 6 | C3: 211 | D3: 5802196 | E3: 70 | F3: 1942080 | G3: 80 | H3: 2204776 | I3: 201 | J3: 5539500
A4: AL Anlene Concentrate Choco 4x125ml | B4: 6 | C4: 0 | D4: 0 | E4: 0 | F4: 0 | G4: 0 | H4: 0 | I4: 0 | J4: 0
A5: AL Anlene Concentrate Vanilla 4x125ml | B5: 6 | C5: 863 | D5: 28305719 | E5: 0 | F5: 0 | G5: 0 | H5: 0 | I5: 863 | J5: 28305719
A6: AL Anlene Gold Vanilla Movepro 1Kg | B6: 6 | C6: 120 | D6: 35752144 | E6: 0 | F6: 0 | G6: 0 | H6: 0 | I6: 120 | J6: 35752144
A7: AL Anlene Gold Vanilla Movepro 400g | B7: 6 | C7: 510 | D7: 69373706 | E7: 0 | F7: 0 | G7: 0 | H7: 0 | I7: 510 | J7: 69373706
A8: AL Anlene Gold Vanilla Movepro 440g | B8: 6 | C8: 344 | D8: 53839916 | E8: 0 | F8: 0 | G8: 0 | H8: 0 | I8: 344 | J8: 53839916
A9: AL Anlene Gold Vanilla Movepro 800g | B9: 6 | C9: 159 | D9: 38049584 | E9: 0 | F9: 0 | G9: 0 | H9: 0 | I9: 159 | J9: 38049584
A10: AL Anlene Movepro UHT 180ml - Có đường | B10: 6 | C10: 734 | D10: 15983688 | E10: 0 | F10: 0 | G10: 0 | H10: 0 | I10: 734 | J10: 15983688
A11: AL Anlene Movepro UHT 180ml - Không béo | B11: 6 | C11: 180 | D11: 3904035 | E11: 0 | F11: 0 | G11: 0 | H11: 0 | I11: 180 | J11: 3904035
A12: AL Anlene Vanilla Movepro 440g | B12: 6 | C12: 295 | D12: 31404753 | E12: 0 | F12: 0 | G12: 0 | H12: 0 | I12: 295 | J12: 31404753
A13: AL Anlene Vanilla Movepro 800g | B13: 6 | C13: 170 | D13: 40681945 | E13: 0 | F13: 0 | G13: 0 | H13: 0 | I13: 170 | J13: 40681945
A14: AL Anlene Vanilla Movepro Sachet 20gx3 | B14: 6 | C14: 18 | D14: 407934 | E14: 0 | F14: 0 | G14: 0 | H14: 0 | I14: 18 | J14: 407934
... A284: XXTT Heo 18g gói (T-3.6KG) | B284: 6 | C284: 1432 | D284: 99306144 | E284: 198 | F284: 17618832 | G284: 36 | H284: 2582392 | I284: 1594 | J284: 114342584
D285: 16272004374 | F285: 6671492500 | H285: 6167307223 | J285: 16776189651

Sheet Tháng 7
C1: Tồn Đầu Kỳ | E1: Nhập | G1: Xuất | I1: Tồn cuối kỳ
A2: Tên Hàng | B2: Tháng | C2: Số Lượng | D2: T,Tiền | E2: Số Lượng | F2: T.Tiền | G2: Số Lượng | H2: T. Tiền | I2: Số Lượng | J2: T.Tiền
A3: Cá viên Funny 500g | B3: 7 | C3: 201 | D3: 5539500 | E3: 70 | F3: 1914336 | G3: 125 | H3: 3438116 | I3: 146 | J3: 4015720
A4: AL Anlene Concentrate Choco 4x125ml | B4: 7 | C4: 0 | D4: 0 | E4: 0 | F4: 0 | G4: 0 | H4: 0 | I4: 0 | J4: 0
A5: AL Anlene Concentrate Vanilla 4x125ml | B5: 7 | C5: 863 | D5: 28305719 | E5: 0 | F5: 0 | G5: 60 | H5: 1968968 | I5: 803 | J5: 26336751
A6: AL Anlene Gold Vanilla Movepro 1Kg | B6: 7 | C6: 120 | D6: 35752144 | E6: 0 | F6: 0 | G6: 0 | H6: 0 | I6: 120 | J6: 35752144
A7: AL Anlene Gold Vanilla Movepro 400g | B7: 7 | C7: 510 | D7: 69373706 | E7: 0 | F7: 0 | G7: 0 | H7: 0 | I7: 510 | J7: 69373706
A8: AL Anlene Gold Vanilla Movepro 440g | B8: 7 | C8: 344 | D8: 53839916 | E8: 0 | F8: 0 | G8: 0 | H8: 0 | I8: 344 | J8: 53839916
A9: AL Anlene Gold Vanilla Movepro 800g | B9: 7 | C9: 159 | D9: 38049584 | E9: 0 | F9: 0 | G9: 0 | H9: 0 | I9: 159 | J9: 38049584
A10: AL Anlene Movepro UHT 180ml - Có đường | B10: 7 | C10: 734 | D10: 15983688 | E10: 0 | F10: 0 | G10: 0 | H10: 0 | I10: 734 | J10: 15983688
A11: AL Anlene Movepro UHT 180ml - Không béo | B11: 7 | C11: 180 | D11: 3904035 | E11: 0 | F11: 0 | G11: 0 | H11: 0 | I11: 180 | J11: 3904035
A12: AL Anlene Vanilla Movepro 440g | B12: 7 | C12: 295 | D12: 31404753 | E12: 0 | F12: 0 | G12: 0 | H12: 0 | I12: 295 | J12: 31404753
A13: AL Anlene Vanilla Movepro 800g | B13: 7 | C13: 170 | D13: 40681945 | E13: 0 | F13: 0 | G13: 0 | H13: 0 | I13: 170 | J13: 40681945
A14: AL Anlene Vanilla Movepro Sachet 20gx3 | B14: 7 | C14: 18 | D14: 407934 | E14: 0 | F14: 0 | G14: 0 | H14: 0 | I14: 18 | J14: 407934
... A284: XXTT Heo 18g gói (T-3.6KG) | B284: 7 | C284: 1594 | D284: 114342584 | E284: 436 | F284: 32034240 | G284: 108 | H284: 7787535 | I284: 1922 | J284: 138589289
D285: 16776189651 | F285: 9695173526 | H285: 11337158824 | I285: 1128743 | J285: 15134204353

Sheet Tháng 8
C1: Tồn Đầu Kỳ | E1: Nhập | G1: Xuất | I1: Tồn cuối kỳ
A2: Tên Hàng | B2: Tháng | C2: Số Lượng | D2: T,Tiền | E2: Số Lượng | F2: T.Tiền | G2: Số Lượng | H2: T. Tiền | I2: Số Lượng | J2: T.Tiền
A3: Cá viên Funny 500g | B3: 8 | C3: 146 | D3: 4015720 | E3: 100 | F3: 2774400 | G3: 0 | H3: 0 | I3: 246 | J3: 6790120
A4: AL Anlene Concentrate Choco 4x125ml | B4: 8 | C4: 0 | D4: 0 | E4: 0 | F4: 0 | G4: 0 | H4: 0 | I4: 0 | J4: 0
A5: AL Anlene Concentrate Vanilla 4x125ml | B5: 8 | C5: 803 | D5: 26336751 | E5: 0 | F5: 0 | G5: 0 | H5: 0 | I5: 803 | J5: 26336751
A6: AL Anlene Gold Vanilla Movepro 1Kg | B6: 8 | C6: 120 | D6: 35752144 | E6: 0 | F6: 0 | G6: 0 | H6: 0 | I6: 120 | J6: 35752144
A7: AL Anlene Gold Vanilla Movepro 400g | B7: 8 | C7: 510 | D7: 69373706 | E7: 0 | F7: 0 | G7: 0 | H7: 0 | I7: 510 | J7: 69373706
A8: AL Anlene Gold Vanilla Movepro 440g | B8: 8 | C8: 344 | D8: 53839916 | E8: 0 | F8: 0 | G8: 0 | H8: 0 | I8: 344 | J8: 53839916
A9: AL Anlene Gold Vanilla Movepro 800g | B9: 8 | C9: 159 | D9: 38049584 | E9: 0 | F9: 0 | G9: 0 | H9: 0 | I9: 159 | J9: 38049584
A10: AL Anlene Movepro UHT 180ml - Có đường | B10: 8 | C10: 734 | D10: 15983688 | E10: 0 | F10: 0 | G10: 60 | H10: 1306569 | I10: 674 | J10: 14677119
A11: AL Anlene Movepro UHT 180ml - Không béo | B11: 8 | C11: 180 | D11: 3904035 | E11: 0 | F11: 0 | G11: 0 | H11: 0 | I11: 180 | J11: 3904035
A12: AL Anlene Vanilla Movepro 440g | B12: 8 | C12: 295 | D12: 31404753 | E12: 0 | F12: 0 | G12: 0 | H12: 0 | I12: 295 | J12: 31404753
A13: AL Anlene Vanilla Movepro 800g | B13: 8 | C13: 170 | D13: 40681945 | E13: 0 | F13: 0 | G13: 0 | H13: 0 | I13: 170 | J13: 40681945
A14: AL Anlene Vanilla Movepro Sachet 20gx3 | B14: 8 | C14: 18 | D14: 407934 | E14: 0 | F14: 0 | G14: 0 | H14: 0 | I14: 18 | J14: 407934
... A284: XXTT Heo 18g gói (T-3.6KG) | B284: 8 | C284: 1922 | D284: 138589289 | E284: 270 | F284: 24025680 | G284: 0 | H284: 0 | I284: 2192 | J284: 162614969
C285: =SUM(C2:C284) -> 1128743 | D285: =SUM(D2:D284) -> 15134204353 | E285: =SUM(E2:E284) -> 385682 | F285: =SUM(F2:F284) -> 9410289184 | G285: =SUM(G2:G284) -> 525627 | H285: =SUM(H2:H284) -> 9872002163 | I285: =SUM(I2:I284) -> 988798 | J285: =SUM(J2:J284) -> 14672491374

Sheet Tháng 9
C1: Tồn Đầu Kỳ | E1: Nhập | G1: Xuất | I1: Tồn cuối kỳ
A2: Tên Hàng | B2: Tháng | C2: Số Lượng | D2: T,Tiền | E2: Số Lượng | F2: T.Tiền | G2: Số Lượng | H2: T. Tiền | I2: Số Lượng | J2: T.Tiền
A3: Cá viên Funny 500g | B3: 9 | C3: 246 | D3: 6790120 | E3: 70 | F3: 1942080 | G3: 110 | H3: 3039690 | I3: 206 | J3: 5692510
A4: AL Anlene Concentrate Choco 4x125ml | B4: 9 | C4: 0 | D4: 0 | E4: 0 | F4: 0 | G4: 0 | H4: 0 | I4: 0 | J4: 0
A5: AL Anlene Concentrate Vanilla 4x125ml | B5: 9 | C5: 803 | D5: 26336751 | E5: 0 | F5: 0 | G5: 60 | H5: 1968968 | I5: 743 | J5: 24367783
A6: AL Anlene Gold Vanilla Movepro 1Kg | B6: 9 | C6: 120 | D6: 35752144 | E6: 0 | F6: 0 | G6: 0 | H6: 0 | I6: 120 | J6: 35752144
A7: AL Anlene Gold Vanilla Movepro 400g | B7: 9 | C7: 510 | D7: 69373706 | E7: 0 | F7: 0 | G7: 6 | H7: 816161 | I7: 504 | J7: 68557545
A8: AL Anlene Gold Vanilla Movepro 440g | B8: 9 | C8: 344 | D8: 53839916 | E8: 0 | F8: 0 | G8: 0 | H8: 0 | I8: 344 | J8: 53839916
A9: AL Anlene Gold Vanilla Movepro 800g | B9: 9 | C9: 159 | D9: 38049584 | E9: 0 | F9: 0 | G9: 6 | H9: 1435833 | I9: 153 | J9: 36613751
A10: AL Anlene Movepro UHT 180ml - Có đường | B10: 9 | C10: 674 | D10: 14677119 | E10: 0 | F10: 0 | G10: 0 | H10: 0 | I10: 674 | J10: 14677119
A11: AL Anlene Movepro UHT 180ml - Không béo | B11: 9 | C11: 180 | D11: 3904035 | E11: 0 | F11: 0 | G11: 0 | H11: 0 | I11: 180 | J11: 3904035
A12: AL Anlene Vanilla Movepro 440g | B12: 9 | C12: 295 | D12: 31404753 | E12: 0 | F12: 0 | G12: 0 | H12: 0 | I12: 295 | J12: 31404753
A13: AL Anlene Vanilla Movepro 800g | B13: 9 | C13: 170 | D13: 40681945 | E13: 0 | F13: 0 | G13: 0 | H13: 0 | I13: 170 | J13: 40681945
A14: AL Anlene Vanilla Movepro Sachet 20gx3 | B14: 9 | C14: 18 | D14: 407934 | E14: 0 | F14: 0 | G14: 0 | H14: 0 | I14: 18 | J14: 407934
... A284: XXTT Heo 18g gói (T-3.6KG) | B284: 9 | C284: 2192 | D284: 162614969 | E284: 270 | F284: 24025680 | G284: 1530 | H284: 115987081 | I284: 932 | J284: 70653568
D285: 14672491374 | F285: 8134206560 | H285: 7256403764 | J285: 15550294170

Sheet Tháng 10
C1: Tồn Đầu Kỳ | E1: Nhập | G1: Xuất | I1: Tồn cuối kỳ
A2: Tên Hàng | B2: Tháng | C2: Số Lượng | D2: T,Tiền | E2: Số Lượng | F2: T.Tiền | G2: Số Lượng | H2: T. Tiền | I2: Số Lượng | J2: T.Tiền
A3: Cá viên Funny 500g | B3: 10 | C3: 206 | D3: 5692510 | E3: 80 | F3: 2219520 | G3: 80 | H3: 2213155 | I3: 206 | J3: 5698875
A4: AL Anlene Concentrate Choco 4x125ml | B4: 10 | C4: 0 | D4: 0 | E4: 0 | F4: 0 | G4: 0 | H4: 0 | I4: 0 | J4: 0
A5: AL Anlene Concentrate Vanilla 4x125ml | B5: 10 | C5: 743 | D5: 24367783 | E5: 0 | F5: 0 | G5: 156 | H5: 5119317 | I5: 587 | J5: 19248466
A6: AL Anlene Gold Vanilla Movepro 1Kg | B6: 10 | C6: 120 | D6: 35752144 | E6: 0 | F6: 0 | G6: 0 | H6: 0 | I6: 120 | J6: 35752144
A7: AL Anlene Gold Vanilla Movepro 400g | B7: 10 | C7: 504 | D7: 68557545 | E7: 0 | F7: 0 | G7: 0 | H7: 0 | I7: 504 | J7: 68557545
A8: AL Anlene Gold Vanilla Movepro 440g | B8: 10 | C8: 344 | D8: 53839916 | E8: 0 | F8: 0 | G8: 0 | H8: 0 | I8: 344 | J8: 53839916
A9: AL Anlene Gold Vanilla Movepro 800g | B9: 10 | C9: 153 | D9: 36613751 | E9: 0 | F9: 0 | G9: 0 | H9: 0 | I9: 153 | J9: 36613751
A10: AL Anlene Movepro UHT 180ml - Có đường | B10: 10 | C10: 674 | D10: 14677119 | E10: 0 | F10: 0 | G10: 120 | H10: 2613137 | I10: 554 | J10: 12063982
A11: AL Anlene Movepro UHT 180ml - Không béo | B11: 10 | C11: 180 | D11: 3904035 | E11: 0 | F11: 0 | G11: 0 | H11: 0 | I11: 180 | J11: 3904035
A12: AL Anlene Vanilla Movepro 440g | B12: 10 | C12: 295 | D12: 31404753 | E12: 0 | F12: 0 | G12: 0 | H12: 0 | I12: 295 | J12: 31404753
A13: AL Anlene Vanilla Movepro 800g | B13: 10 | C13: 170 | D13: 40681945 | E13: 0 | F13: 0 | G13: 0 | H13: 0 | I13: 170 | J13: 40681945
A14: AL Anlene Vanilla Movepro Sachet 20gx3 | B14: 10 | C14: 18 | D14: 407934 | E14: 0 | F14: 0 | G14: 0 | H14: 0 | I14: 18 | J14: 407934
... A278: VS ĐL Xúc xích sụn giòn 500g | B278: 10 | C278: 8 | D278: 847410 | E278: 0 | F278: 0 | G278: 0 | H278: 0 | I278: 8 | J278: 847410
A279: VS ĐL Xúc xích sụn giòn- gói 250g ĐL | B279: 10 | C279: 8 | D279: 888480 | E279: 0 | G279: 0 | H279: 0 | I279: 8 | J279: 888480
A280: Xốt tiêu đen TT 190g | B280: 10 | C280: 72 | D280: 1717560 | E280: 0 | F280: 0 | G280: 0 | H280: 0 | I280: 72 | J280: 1717560
A281: Xốt ướp thịt HQ vị cay 90g | B281: 10 | C281: 5445 | D281: 18544800 | E281: 8 | F281: 0 | G281: 0 | H281: 0 | I281: 5453 | J281: 18544800
A282: XXTT Bò 18g gói (T-3.6kg) | B282: 10 | C282: 1489 | D282: 132500193 | E282: 432 | F282: 38441088 | G282: 1170 | H282: 104113118 | I282: 751 | J282: 66828163
A283: XXTT Dinh dưỡng heo gói 175g | B283: 10 | C283: 2558 | D283: 238790929 | E283: 910 | F283: 85077720 | G283: 2426 | H283: 226558634 | I283: 1042 | J283: 97310015
A284: XXTT Heo 18g gói (T-3.6KG) | B284: 10 | C284: 932 | D284: 70653568 | E284: 306 | F284: 27229104 | G284: 1026 | H284: 81120857 | I284: 212 | J284: 16761815
D285: 15550294170 | F285: 9205815555 | H285: 9489921705 | J285: 15266188020

Sheet Tháng 11
C1: Tồn Đầu Kỳ | E1: Nhập | G1: Xuất | I1: Tồn cuối kỳ
A2: Tên Hàng | B2: Tháng | C2: Số Lượng | D2: T,Tiền | E2: Số Lượng | F2: T.Tiền | G2: Số Lượng | H2: T. Tiền | I2: Số Lượng | J2: T.Tiền
A3: Cá viên Funny 500g | B3: 11 | C3: 206 | D3: 5698875 | E3: 50 | F3: 1387200 | G3: 30 | H3: 830399 | I3: 226 | J3: 6255676
A4: AL Anlene Concentrate Choco 4x125ml | B4: 11 | C4: 0 | D4: 0 | E4: 0 | F4: 0 | G4: 0 | H4: 0 | I4: 0 | J4: 0
A5: AL Anlene Concentrate Vanilla 4x125ml | B5: 11 | C5: 587 | D5: 19248466 | E5: 0 | F5: 0 | G5: 0 | H5: 0 | I5: 587 | J5: 19248466
A6: AL Anlene Gold Vanilla Movepro 1Kg | B6: 11 | C6: 120 | D6: 35752144 | E6: 0 | F6: 0 | G6: 0 | H6: 0 | I6: 120 | J6: 35752144
A7: AL Anlene Gold Vanilla Movepro 400g | B7: 11 | C7: 504 | D7: 68557545 | E7: 0 | F7: 0 | G7: 0 | H7: 0 | I7: 504 | J7: 68557545
A8: AL Anlene Gold Vanilla Movepro 440g | B8: 11 | C8: 344 | D8: 53839916 | E8: 0 | F8: 0 | G8: 0 | H8: 0 | I8: 344 | J8: 53839916
A9: AL Anlene Gold Vanilla Movepro 800g | B9: 11 | C9: 153 | D9: 36613751 | E9: 0 | F9: 0 | G9: 0 | H9: 0 | I9: 153 | J9: 36613751
A10: AL Anlene Movepro UHT 180ml - Có đường | B10: 11 | C10: 554 | D10: 12063982 | E10: 0 | F10: 0 | G10: 0 | H10: 0 | I10: 554 | J10: 12063982
A11: AL Anlene Movepro UHT 180ml - Không béo | B11: 11 | C11: 180 | D11: 3904035 | E11: 0 | F11: 0 | G11: 0 | H11: 0 | I11: 180 | J11: 3904035
A12: AL Anlene Vanilla Movepro 440g | B12: 11 | C12: 295 | D12: 31404753 | E12: 0 | F12: 0 | G12: 0 | H12: 0 | I12: 295 | J12: 31404753
A13: AL Anlene Vanilla Movepro 800g | B13: 11 | C13: 170 | D13: 40681945 | E13: 0 | F13: 0 | G13: 0 | H13: 0 | I13: 170 | J13: 40681945
A14: AL Anlene Vanilla Movepro Sachet 20gx3 | B14: 11 | C14: 18 | D14: 407934 | E14: 0 | F14: 0 | G14: 0 | H14: 0 | I14: 18 | J14: 407934
... A284: XXTT Heo 18g gói (T-3.6KG) | B284: 11 | C284: 212 | D284: 16761815 | E284: 332 | F284: 28432224 | G284: 544 | H284: 45194039 | I284: 0 | J284: 0
D285: 15266188020 | F285: 7821004404 | H285: 7330307950 | J285: 15756884474

Sheet T12 CHÍNH
A1: HÀNG TỒN KHO 31/12/2023 ĐÃ ĐIỀU CHỈNH GIÁ
C2: Tồn Đầu Kỳ | E2: Nhập | G2: Xuất | I2: Tồn cuối kỳ
A3: Tên Hàng | B3: Tháng | C3: Số Lượng | D3: T,Tiền | E3: Số Lượng | F3: T.Tiền | G3: Số Lượng | H3: T. Tiền | I3: Số Lượng | J3: T.Tiền
A4: Cá viên Funny 500g | B4: 12 | C4: 226 | D4: 6255676 | E4: 100 | F4: 2774400 | G4: 100 | H4: =D4+F4-J4 -> 2769962 | I4: 226 | J4: 6260114
A5: AL Anlene Concentrate Choco 4x125ml | B5: 12 | C5: 0 | D5: 0 | E5: 60 | F5: 1188660 | G5: 60 | H5: =D5+F5-J5 -> 1188660 | I5: 0 | J5: 0
A6: AL Anlene Concentrate Vanilla 4x125ml | B6: 12 | C6: 587 | D6: 19248466 | E6: 0 | F6: 0 | G6: 338 | H6: =D6+F6-J6 -> 14931342 | I6: 249 | J6: 4317124
A7: AL Anlene Gold Vanilla Movepro 1Kg | B7: 12 | C7: 120 | D7: 35752144 | E7: 0 | F7: 0 | G7: 120 | H7: =D7+F7-J7 -> 35752144 | I7: 0 | J7: 0
A8: AL Anlene Gold Vanilla Movepro 400g | B8: 12 | C8: 504 | D8: 68557545 | E8: 0 | F8: 0 | G8: 134 | H8: =D8+F8-J8 -> 37679444 | I8: 370 | J8: 30878101
A9: AL Anlene Gold Vanilla Movepro 440g | B9: 12 | C9: 344 | D9: 53839916 | E9: 0 | F9: 0 | G9: 34 | H9: =D9+F9-J9 -> 30363208 | I9: 310 | J9: 23476708
A10: AL Anlene Gold Vanilla Movepro 800g | B10: 12 | C10: 153 | D10: 36613751 | E10: 0 | F10: 0 | G10: 153 | H10: =D10+F10-J10 -> 36613751 | I10: 0 | J10: 0
A11: AL Anlene Movepro UHT 180ml - Có đường | B11: 12 | C11: 554 | D11: 12063982 | E11: 0 | F11: 0 | G11: 344 | H11: =D11+F11-J11 -> 9537950 | I11: 210 | J11: 2526032
A12: AL Anlene Movepro UHT 180ml - Không béo | B12: 12 | C12: 180 | D12: 3904035 | E12: 0 | F12: 0 | G12: 40 | H12: =D12+F12-J12 -> 2212287 | I12: 140 | J12: 1691748
A13: AL Anlene Vanilla Movepro 440g | B13: 12 | C13: 295 | D13: 31404753 | E13: 0 | F13: 0 | G13: 277 | H13: =D13+F13-J13 -> 29488531 | I13: 18 | J13: 1916222
A14: AL Anlene Vanilla Movepro 800g | B14: 12 | C14: 170 | D14: 40681945 | E14: 0 | F14: 0 | G14: 88 | H14: =D14+F14-J14 -> 29195278 | I14: 82 | J14: 11486667
A15: AL Anlene Vanilla Movepro Sachet 20gx3 | B15: 12 | C15: 18 | D15: 407934 | E15: 0 | F15: 0 | G15: 18 | H15: =D15+F15-J15 -> 407934 | I15: 0 | J15: 0
... A60: CLM Nước mắm cao đạm 150ml | B60: 12 | C60: 170 | D60: 1385264 | E60: 24 | F60: 400008 | G60: 81 | H60: =D60+F60-J60 -> 27607 | I60: 113 | J60: 1757665
A61: CLM Nước mắm cao đạm 500ml | B61: 12 | C61: 384 | D61: 17725913 | E61: 0 | F61: 0 | H61: =D61+F61-J61 -> 923225 | I61: 384 | J61: 16802688
A62: CLM Nước mắm cao đạm 500ml (Xuân) | B62: 12 | C62: 156 | D62: 16177824 | E62: 0 | F62: 0 | H62: =D62+F62-J62 -> 622224 | I62: 156 | J62: 15555600
A63: CLM Nước mắm cao đạm 750ml (Xuân) | B63: 12 | C63: 84 | D63: 12133296 | F63: 0 | H63: =D63+F63-J63 -> 0 | I63: 84 | J63: 12133296
A64: CLM Nước mắm chay tt 245ml | B64: 12 | C64: 1608 | D64: 25016122 | E64: 552 | F64: 8689032 | G64: 1294 | H64: =D64+F64-J64 -> 20956492 | I64: 866 | J64: 12748662
A65: CLM Nước Mắm Hương Việt 500ml hàng onpack chén | B65: 12 | C65: 3852 | D65: 90280472 | E65: 648 | F65: 15599952 | G65: 2687 | H65: =D65+F65-J65 -> 65081167 | I65: 1813 | J65: 40799257
A66: CLM Nước Mắm Hương Việt pet 750ml Hàng onpack chén | B66: 12 | C66: 4218 | D66: 143970514 | E66: 1800 | F66: 61666200 | G66: 4874 | H66: =D66+F66-J66 -> 169006179 | I66: 1144 | J66: 36630535
A67: CLM Nước tương Hảo Vị 500ml | B67: 12 | C67: 5136 | D67: 75745997 | E67: 1752 | F67: 25955880 | G67: 6059 | H67: =D67+F67-J67 -> 90214644 | I67: 829 | J67: 11487233
A68: CLM Nước tương Hảo Vị gói 7ml | B68: 12 | C68: 10400 | D68: 3813333 | E68: 0 | F68: 0 | G68: 9600 | H68: =D68+F68-J68 -> 3520000 | I68: 800 | J68: 293333
A69: CLM Nước tương Hương Việt 4.9 lít(3 bình/T) | B69: 12 | C69: 168 | D69: 9544198 | E69: 279 | F69: 4275018 | G69: 171 | H69: =D69+F69-J69 -> 221995 | I69: 276 | J69: 13597221
A70: CLM Nước tương đậu nành pet 150ml | B70: 12 | C70: 1092 | D70: 6735333 | E70: 0 | F70: 0 | G70: 206 | H70: =D70+F70-J70 -> 1517300 | I70: 886 | J70: 5218033
A71: CLM Nước tương đậu nành pet 300ml | B71: 12 | C71: 7371 | D71: 66190155 | E71: 1920 | F71: 21333120 | G71: 4938 | H71: =D71+F71-J71 -> 42296793 | I71: 4353 | J71: 45226482
A72: CLM Nước tương đậu nành pet 700ml | B72: 12 | C72: 1912 | D72: 38449684 | E72: 1560 | F72: 33221760 | G72: 3121 | H72: =D72+F72-J72 -> 64673570 | I72: 351 | J72: 6997874
A73: CLM Ớt khô sa tế hũ TT 100g | B73: 12 | C73: 180 | D73: 2602954 | E73: 85 | F73: 1177052.4 | G73: 0 | H73: =D73+F73-J73 -> 110372.42 | I73: 265 | J73: 3669634
A74: CLM Ớt Sate hũ TT 150g | B74: 12 | C74: 2052 | D74: 31426776 | E74: 504 | F74: 7933464 | G74: 2016 | H74: =D74+F74-J74 -> 31414276 | I74: 540 | J74: 7945964
A75: CLM Sa tế chay pet 90gr | B75: 12 | C75: 5760 | D75: 42106565 | E75: 1368 | F75: 10132776 | G75: 4986 | H75: =D75+F75-J75 -> 37405948 | I75: 2142 | J75: 14833393
... A101: CLM Tương đen phở 230g | B101: 12 | C101: 46476 | D101: 335124139 | E101: 977 | F101: 44416165 | G101: 45413 | H101: =D101+F101-J101 -> 2.8679826e+08 | I101: 2040 | J101: 92742043
A102: CLM Tương đen phở 520g | B102: 12 | C102: 48 | D102: 2333328 | E102: 202 | F102: 1458330 | H102: =D102+F102-J102 -> 0 | I102: 250 | J102: 3791658
A103: CLM Xốt ướp xá xíu TT 200G | B103: 12 | C103: 864 | D103: 15351650 | E103: 684 | F103: 12350304 | G103: 1103 | H103: =D103+F103-J103 -> 20185920 | I103: 445 | J103: 7516034
A104: CLM Xốt bò kho gói 90g | B104: 12 | C104: 7094 | D104: 57800393 | E104: 7800 | F104: 63554400 | G104: 13333 | H104: =D104+F104-J104 -> 109458862 | I104: 1561 | J104: 11895931
A105: CLM Xốt bún bò gói 90g | B105: 12 | C105: 2500 | D105: 20355350 | E105: 1320 | F105: 10755360 | G105: 2890 | H105: =D105+F105-J105 -> 24025287 | I105: 930 | J105: 7085423
A106: CLM Xốt cá chiên PET 280g | B106: 12 | C106: 240 | D106: 3935440 | E106: 90 | F106: 1200024 | H106: =D106+F106-J106 -> 0 | I106: 330 | J106: 5135464
A107: CLM Xốt cà chua KetChup TT 330g | B107: 12 | C107: 192 | D107: 3650221 | E107: 83 | F107: 1342579 | G107: 0 | H107: =D107+F107-J107 -> 0 | I107: 275 | J107: 4992800
A108: CLM Xốt gà chiên nước mắm 90g | B108: 12 | C108: 4325 | D108: 27997920 | E108: 2412 | F108: 15554400 | G108: 4660 | H108: =D108+F108-J108 -> 30965654 | I108: 2077 | J108: 12586666
A109: CLM Xốt lẩu kim chi pet 280g | B109: 12 | C109: 4565 | D109: 92887200 | E109: 0 | F109: 0 | G109: 2461 | H109: =D109+F109-J109 -> 52822600 | I109: 2104 | J109: 40064600
...
